2019-01-08 19:57:57,475 INFO org.apache.hadoop.yarn.server.resourcemanager.ResourceManager: STARTUP_MSG: 
/************************************************************
STARTUP_MSG: Starting ResourceManager
STARTUP_MSG:   host = master/132.72.109.20
STARTUP_MSG:   args = []
STARTUP_MSG:   version = 2.9.1
STARTUP_MSG:   build = https://github.com/razo7/hadoop-2.9.1-OR2.git -r ef46505203318032151d4f27c5bbb6d9e7cda417; compiled by 'hadoop2' on 2019-01-08T16:41Z
STARTUP_MSG:   java = 1.8.0_181
************************************************************/
2019-01-08 19:57:57,508 INFO org.apache.hadoop.yarn.server.resourcemanager.ResourceManager: registered UNIX signal handlers for [TERM, HUP, INT]
2019-01-08 19:57:57,947 INFO org.apache.hadoop.conf.Configuration: found resource core-site.xml at file:/usr/local/hadoop/etc/hadoop/core-site.xml
2019-01-08 19:57:58,350 INFO org.apache.hadoop.security.Groups: clearing userToGroupsMap cache
2019-01-08 19:57:58,437 INFO org.apache.hadoop.conf.Configuration: found resource yarn-site.xml at file:/usr/local/hadoop/etc/hadoop/yarn-site.xml
2019-01-08 19:57:58,480 INFO org.apache.hadoop.yarn.event.AsyncDispatcher: Registering class org.apache.hadoop.yarn.server.resourcemanager.RMFatalEventType for class org.apache.hadoop.yarn.server.resourcemanager.ResourceManager$RMFatalEventDispatcher
2019-01-08 19:57:59,090 INFO org.apache.hadoop.yarn.server.resourcemanager.security.NMTokenSecretManagerInRM: NMTokenKeyRollingInterval: 86400000ms and NMTokenKeyActivationDelay: 900000ms
2019-01-08 19:57:59,116 INFO org.apache.hadoop.yarn.server.resourcemanager.security.RMContainerTokenSecretManager: ContainerTokenKeyRollingInterval: 86400000ms and ContainerTokenKeyActivationDelay: 900000ms
2019-01-08 19:57:59,132 INFO org.apache.hadoop.yarn.server.resourcemanager.security.AMRMTokenSecretManager: AMRMTokenKeyRollingInterval: 86400000ms and AMRMTokenKeyActivationDelay: 900000 ms
2019-01-08 19:57:59,251 INFO org.apache.hadoop.yarn.event.AsyncDispatcher: Registering class org.apache.hadoop.yarn.server.resourcemanager.recovery.RMStateStoreEventType for class org.apache.hadoop.yarn.server.resourcemanager.recovery.RMStateStore$ForwardingEventHandler
2019-01-08 19:57:59,257 INFO org.apache.hadoop.yarn.event.AsyncDispatcher: Registering class org.apache.hadoop.yarn.server.resourcemanager.NodesListManagerEventType for class org.apache.hadoop.yarn.server.resourcemanager.NodesListManager
2019-01-08 19:57:59,257 INFO org.apache.hadoop.yarn.server.resourcemanager.ResourceManager: Using Scheduler: org.apache.hadoop.yarn.server.resourcemanager.scheduler.capacity.CapacityScheduler
2019-01-08 19:57:59,336 INFO org.apache.hadoop.yarn.event.AsyncDispatcher: Registering class org.apache.hadoop.yarn.server.resourcemanager.scheduler.event.SchedulerEventType for class org.apache.hadoop.yarn.event.EventDispatcher
2019-01-08 19:57:59,338 INFO org.apache.hadoop.yarn.event.AsyncDispatcher: Registering class org.apache.hadoop.yarn.server.resourcemanager.rmapp.RMAppEventType for class org.apache.hadoop.yarn.server.resourcemanager.ResourceManager$ApplicationEventDispatcher
2019-01-08 19:57:59,339 INFO org.apache.hadoop.yarn.event.AsyncDispatcher: Registering class org.apache.hadoop.yarn.server.resourcemanager.rmapp.attempt.RMAppAttemptEventType for class org.apache.hadoop.yarn.server.resourcemanager.ResourceManager$ApplicationAttemptEventDispatcher
2019-01-08 19:57:59,340 INFO org.apache.hadoop.yarn.event.AsyncDispatcher: Registering class org.apache.hadoop.yarn.server.resourcemanager.rmnode.RMNodeEventType for class org.apache.hadoop.yarn.server.resourcemanager.ResourceManager$NodeEventDispatcher
2019-01-08 19:57:59,427 INFO org.apache.hadoop.metrics2.impl.MetricsConfig: loaded properties from hadoop-metrics2.properties
2019-01-08 19:57:59,646 INFO org.apache.hadoop.metrics2.impl.MetricsSystemImpl: Scheduled Metric snapshot period at 10 second(s).
2019-01-08 19:57:59,646 INFO org.apache.hadoop.metrics2.impl.MetricsSystemImpl: ResourceManager metrics system started
2019-01-08 19:57:59,667 INFO org.apache.hadoop.yarn.security.YarnAuthorizationProvider: org.apache.hadoop.yarn.security.ConfiguredYarnAuthorizer is instantiated.
2019-01-08 19:57:59,678 INFO org.apache.hadoop.yarn.event.AsyncDispatcher: Registering class org.apache.hadoop.yarn.server.resourcemanager.RMAppManagerEventType for class org.apache.hadoop.yarn.server.resourcemanager.RMAppManager
2019-01-08 19:57:59,722 INFO org.apache.hadoop.yarn.event.AsyncDispatcher: Registering class org.apache.hadoop.yarn.server.resourcemanager.amlauncher.AMLauncherEventType for class org.apache.hadoop.yarn.server.resourcemanager.amlauncher.ApplicationMasterLauncher
2019-01-08 19:57:59,744 INFO org.apache.hadoop.yarn.server.resourcemanager.RMNMInfo: Registered RMNMInfo MBean
2019-01-08 19:57:59,745 INFO org.apache.hadoop.yarn.server.resourcemanager.rmapp.monitor.RMAppLifetimeMonitor: Application lifelime monitor interval set to 3000 ms.
2019-01-08 19:57:59,761 INFO org.apache.hadoop.util.HostsFileReader: Refreshing hosts (include/exclude) list
2019-01-08 19:57:59,778 INFO org.apache.hadoop.conf.Configuration: found resource capacity-scheduler.xml at file:/usr/local/hadoop/etc/hadoop/capacity-scheduler.xml
2019-01-08 19:57:59,890 INFO org.apache.hadoop.yarn.server.resourcemanager.scheduler.capacity.CapacitySchedulerConfiguration: max alloc mb per queue for root is undefined
2019-01-08 19:57:59,891 INFO org.apache.hadoop.yarn.server.resourcemanager.scheduler.capacity.CapacitySchedulerConfiguration: max alloc vcore per queue for root is undefined
2019-01-08 19:57:59,922 INFO org.apache.hadoop.yarn.server.resourcemanager.scheduler.capacity.ParentQueue: root, capacity=1.0, absoluteCapacity=1.0, maxCapacity=1.0, absoluteMaxCapacity=1.0, state=RUNNING, acls=ADMINISTER_QUEUE:*SUBMIT_APP:*, labels=*,
, reservationsContinueLooking=true, orderingPolicy=utilization, priority=0
2019-01-08 19:57:59,922 INFO org.apache.hadoop.yarn.server.resourcemanager.scheduler.capacity.ParentQueue: Initialized parent-queue root name=root, fullname=root
2019-01-08 19:57:59,968 INFO org.apache.hadoop.yarn.server.resourcemanager.scheduler.capacity.CapacitySchedulerConfiguration: max alloc mb per queue for root.default is undefined
2019-01-08 19:57:59,968 INFO org.apache.hadoop.yarn.server.resourcemanager.scheduler.capacity.CapacitySchedulerConfiguration: max alloc vcore per queue for root.default is undefined
2019-01-08 19:57:59,983 INFO org.apache.hadoop.yarn.server.resourcemanager.scheduler.capacity.LeafQueue: Initializing default
capacity = 1.0 [= (float) configuredCapacity / 100 ]
absoluteCapacity = 1.0 [= parentAbsoluteCapacity * capacity ]
maxCapacity = 1.0 [= configuredMaxCapacity ]
absoluteMaxCapacity = 1.0 [= 1.0 maximumCapacity undefined, (parentAbsoluteMaxCapacity * maximumCapacity) / 100 otherwise ]
userLimit = 100 [= configuredUserLimit ]
userLimitFactor = 1.0 [= configuredUserLimitFactor ]
maxApplications = 10000 [= configuredMaximumSystemApplicationsPerQueue or (int)(configuredMaximumSystemApplications * absoluteCapacity)]
maxApplicationsPerUser = 10000 [= (int)(maxApplications * (userLimit / 100.0f) * userLimitFactor) ]
usedCapacity = 0.0 [= usedResourcesMemory / (clusterResourceMemory * absoluteCapacity)]
absoluteUsedCapacity = 0.0 [= usedResourcesMemory / clusterResourceMemory]
maxAMResourcePerQueuePercent = 0.1 [= configuredMaximumAMResourcePercent ]
minimumAllocationFactor = 0.9717813 [= (float)(maximumAllocationMemory - minimumAllocationMemory) / maximumAllocationMemory ]
maximumAllocation = <memory:4536, vCores:4> [= configuredMaxAllocation ]
numContainers = 0 [= currentNumContainers ]
state = RUNNING [= configuredState ]
acls = ADMINISTER_QUEUE:*SUBMIT_APP:* [= configuredAcls ]
nodeLocalityDelay = 40
rackLocalityAdditionalDelay = -1
labels=*,
reservationsContinueLooking = true
preemptionDisabled = true
defaultAppPriorityPerQueue = 0
priority = 0
maxLifetime = -1 seconds
defaultLifetime = -1 seconds
2019-01-08 19:57:59,983 INFO org.apache.hadoop.yarn.server.resourcemanager.scheduler.capacity.CapacitySchedulerQueueManager: Initialized queue: default: capacity=1.0, absoluteCapacity=1.0, usedResources=<memory:0, vCores:0>, usedCapacity=0.0, absoluteUsedCapacity=0.0, numApps=0, numContainers=0
2019-01-08 19:57:59,984 INFO org.apache.hadoop.yarn.server.resourcemanager.scheduler.capacity.CapacitySchedulerQueueManager: Initialized queue: root: numChildQueue= 1, capacity=1.0, absoluteCapacity=1.0, usedResources=<memory:0, vCores:0>usedCapacity=0.0, numApps=0, numContainers=0
2019-01-08 19:57:59,990 INFO org.apache.hadoop.yarn.server.resourcemanager.scheduler.capacity.CapacitySchedulerQueueManager: Initialized root queue root: numChildQueue= 1, capacity=1.0, absoluteCapacity=1.0, usedResources=<memory:0, vCores:0>usedCapacity=0.0, numApps=0, numContainers=0
2019-01-08 19:57:59,990 INFO org.apache.hadoop.yarn.server.resourcemanager.scheduler.capacity.CapacityScheduler: Initialized queue mappings, override: false
2019-01-08 19:57:59,996 INFO org.apache.hadoop.yarn.server.resourcemanager.scheduler.capacity.CapacityScheduler: Initialized CapacityScheduler with calculator=class org.apache.hadoop.yarn.util.resource.DefaultResourceCalculator, minimumAllocation=<<memory:128, vCores:1>>, maximumAllocation=<<memory:4536, vCores:4>>, asynchronousScheduling=false, asyncScheduleInterval=5ms
2019-01-08 19:58:00,003 INFO org.apache.hadoop.conf.Configuration: dynamic-resources.xml not found
2019-01-08 19:58:00,006 INFO org.apache.hadoop.yarn.server.resourcemanager.AMSProcessingChain: Initializing AMS Processing chain. Root Processor=[org.apache.hadoop.yarn.server.resourcemanager.DefaultAMSProcessor].
2019-01-08 19:58:00,022 INFO org.apache.hadoop.yarn.server.resourcemanager.ResourceManager: TimelineServicePublisher is not configured
2019-01-08 19:58:00,024 INFO org.apache.hadoop.yarn.server.resourcemanager.ResourceManager: Transitioning to active state
2019-01-08 19:58:00,090 INFO org.apache.hadoop.yarn.server.resourcemanager.recovery.RMStateStore: Updating AMRMToken
2019-01-08 19:58:00,090 INFO org.apache.hadoop.yarn.server.resourcemanager.security.RMContainerTokenSecretManager: Rolling master-key for container-tokens
2019-01-08 19:58:00,091 INFO org.apache.hadoop.yarn.server.resourcemanager.security.NMTokenSecretManagerInRM: Rolling master-key for nm-tokens
2019-01-08 19:58:00,093 INFO org.apache.hadoop.security.token.delegation.AbstractDelegationTokenSecretManager: Updating the current master key for generating delegation tokens
2019-01-08 19:58:00,094 INFO org.apache.hadoop.yarn.server.resourcemanager.security.RMDelegationTokenSecretManager: storing master key with keyID 1
2019-01-08 19:58:00,095 INFO org.apache.hadoop.yarn.server.resourcemanager.recovery.RMStateStore: Storing RMDTMasterKey.
2019-01-08 19:58:00,098 INFO org.apache.hadoop.security.token.delegation.AbstractDelegationTokenSecretManager: Starting expired delegation token remover thread, tokenRemoverScanInterval=60 min(s)
2019-01-08 19:58:00,098 INFO org.apache.hadoop.security.token.delegation.AbstractDelegationTokenSecretManager: Updating the current master key for generating delegation tokens
2019-01-08 19:58:00,098 INFO org.apache.hadoop.yarn.server.resourcemanager.security.RMDelegationTokenSecretManager: storing master key with keyID 2
2019-01-08 19:58:00,098 INFO org.apache.hadoop.yarn.server.resourcemanager.recovery.RMStateStore: Storing RMDTMasterKey.
2019-01-08 19:58:00,100 INFO org.apache.hadoop.yarn.event.AsyncDispatcher: Registering class org.apache.hadoop.yarn.nodelabels.event.NodeLabelsStoreEventType for class org.apache.hadoop.yarn.nodelabels.CommonNodeLabelsManager$ForwardingEventHandler
2019-01-08 19:58:00,179 INFO org.apache.hadoop.ipc.CallQueueManager: Using callQueue: class java.util.concurrent.LinkedBlockingQueue queueCapacity: 5000 scheduler: class org.apache.hadoop.ipc.DefaultRpcScheduler
2019-01-08 19:58:00,199 INFO org.apache.hadoop.ipc.Server: Starting Socket Reader #1 for port 8031
2019-01-08 19:58:00,660 INFO org.apache.hadoop.yarn.factories.impl.pb.RpcServerFactoryPBImpl: Adding protocol org.apache.hadoop.yarn.server.api.ResourceTrackerPB to the server
2019-01-08 19:58:00,668 INFO org.apache.hadoop.ipc.Server: IPC Server Responder: starting
2019-01-08 19:58:00,669 INFO org.apache.hadoop.ipc.Server: IPC Server listener on 8031: starting
2019-01-08 19:58:00,950 INFO org.apache.hadoop.util.JvmPauseMonitor: Starting JVM pause monitor
2019-01-08 19:58:00,959 INFO org.apache.hadoop.ipc.CallQueueManager: Using callQueue: class java.util.concurrent.LinkedBlockingQueue queueCapacity: 5000 scheduler: class org.apache.hadoop.ipc.DefaultRpcScheduler
2019-01-08 19:58:00,999 INFO org.apache.hadoop.ipc.Server: Starting Socket Reader #1 for port 8030
2019-01-08 19:58:01,050 INFO org.apache.hadoop.yarn.factories.impl.pb.RpcServerFactoryPBImpl: Adding protocol org.apache.hadoop.yarn.api.ApplicationMasterProtocolPB to the server
2019-01-08 19:58:01,050 INFO org.apache.hadoop.ipc.Server: IPC Server Responder: starting
2019-01-08 19:58:01,051 INFO org.apache.hadoop.ipc.Server: IPC Server listener on 8030: starting
2019-01-08 19:58:01,326 INFO org.apache.hadoop.ipc.CallQueueManager: Using callQueue: class java.util.concurrent.LinkedBlockingQueue queueCapacity: 5000 scheduler: class org.apache.hadoop.ipc.DefaultRpcScheduler
2019-01-08 19:58:01,333 INFO org.apache.hadoop.ipc.Server: Starting Socket Reader #1 for port 8032
2019-01-08 19:58:01,349 INFO org.apache.hadoop.yarn.factories.impl.pb.RpcServerFactoryPBImpl: Adding protocol org.apache.hadoop.yarn.api.ApplicationClientProtocolPB to the server
2019-01-08 19:58:01,363 INFO org.apache.hadoop.ipc.Server: IPC Server Responder: starting
2019-01-08 19:58:01,371 INFO org.apache.hadoop.ipc.Server: IPC Server listener on 8032: starting
2019-01-08 19:58:01,577 INFO org.apache.hadoop.yarn.server.resourcemanager.ResourceManager: Transitioned to active state
2019-01-08 19:58:01,941 INFO org.mortbay.log: Logging to org.slf4j.impl.Log4jLoggerAdapter(org.mortbay.log) via org.mortbay.log.Slf4jLog
2019-01-08 19:58:01,996 INFO org.apache.hadoop.security.authentication.server.AuthenticationFilter: Unable to initialize FileSignerSecretProvider, falling back to use random secrets.
2019-01-08 19:58:02,025 INFO org.apache.hadoop.http.HttpRequestLog: Http request log for http.requests.resourcemanager is not defined
2019-01-08 19:58:02,033 INFO org.apache.hadoop.http.HttpServer2: Added global filter 'safety' (class=org.apache.hadoop.http.HttpServer2$QuotingInputFilter)
2019-01-08 19:58:02,040 INFO org.apache.hadoop.http.HttpServer2: Added filter RMAuthenticationFilter (class=org.apache.hadoop.yarn.server.security.http.RMAuthenticationFilter) to context cluster
2019-01-08 19:58:02,040 INFO org.apache.hadoop.http.HttpServer2: Added filter RMAuthenticationFilter (class=org.apache.hadoop.yarn.server.security.http.RMAuthenticationFilter) to context static
2019-01-08 19:58:02,040 INFO org.apache.hadoop.http.HttpServer2: Added filter RMAuthenticationFilter (class=org.apache.hadoop.yarn.server.security.http.RMAuthenticationFilter) to context logs
2019-01-08 19:58:02,041 INFO org.apache.hadoop.http.HttpServer2: Added filter static_user_filter (class=org.apache.hadoop.http.lib.StaticUserWebFilter$StaticUserFilter) to context cluster
2019-01-08 19:58:02,041 INFO org.apache.hadoop.http.HttpServer2: Added filter static_user_filter (class=org.apache.hadoop.http.lib.StaticUserWebFilter$StaticUserFilter) to context static
2019-01-08 19:58:02,041 INFO org.apache.hadoop.http.HttpServer2: Added filter static_user_filter (class=org.apache.hadoop.http.lib.StaticUserWebFilter$StaticUserFilter) to context logs
2019-01-08 19:58:02,046 INFO org.apache.hadoop.http.HttpServer2: adding path spec: /cluster/*
2019-01-08 19:58:02,047 INFO org.apache.hadoop.http.HttpServer2: adding path spec: /ws/*
2019-01-08 19:58:03,280 INFO org.apache.hadoop.yarn.webapp.WebApps: Registered webapp guice modules
2019-01-08 19:58:03,286 INFO org.apache.hadoop.http.HttpServer2: Jetty bound to port 8088
2019-01-08 19:58:03,287 INFO org.mortbay.log: jetty-6.1.26
2019-01-08 19:58:03,692 INFO org.mortbay.log: Extract jar:file:/usr/local/hadoop/share/hadoop/yarn/hadoop-yarn-common-2.9.1.jar!/webapps/cluster to /tmp/Jetty_master_8088_cluster____i4ls4w/webapp
2019-01-08 19:58:04,207 INFO org.apache.hadoop.security.token.delegation.AbstractDelegationTokenSecretManager: Updating the current master key for generating delegation tokens
2019-01-08 19:58:04,216 INFO org.apache.hadoop.security.token.delegation.AbstractDelegationTokenSecretManager: Starting expired delegation token remover thread, tokenRemoverScanInterval=60 min(s)
2019-01-08 19:58:04,221 INFO org.apache.hadoop.security.token.delegation.AbstractDelegationTokenSecretManager: Updating the current master key for generating delegation tokens
2019-01-08 19:58:07,938 INFO org.mortbay.log: Started HttpServer2$SelectChannelConnectorWithSafeStartup@master:8088
2019-01-08 19:58:07,940 INFO org.apache.hadoop.yarn.webapp.WebApps: Web app cluster started at 8088
2019-01-08 19:58:08,076 INFO org.apache.hadoop.ipc.CallQueueManager: Using callQueue: class java.util.concurrent.LinkedBlockingQueue queueCapacity: 100 scheduler: class org.apache.hadoop.ipc.DefaultRpcScheduler
2019-01-08 19:58:08,082 INFO org.apache.hadoop.ipc.Server: Starting Socket Reader #1 for port 8033
2019-01-08 19:58:08,093 INFO org.apache.hadoop.yarn.factories.impl.pb.RpcServerFactoryPBImpl: Adding protocol org.apache.hadoop.yarn.server.api.ResourceManagerAdministrationProtocolPB to the server
2019-01-08 19:58:08,100 INFO org.apache.hadoop.ipc.Server: IPC Server Responder: starting
2019-01-08 19:58:08,100 INFO org.apache.hadoop.ipc.Server: IPC Server listener on 8033: starting
2019-01-08 19:58:10,199 INFO org.apache.hadoop.yarn.server.resourcemanager.ResourceTrackerService: NodeManager from node master(cmPort: 39349 httpPort: 8042) registered with capability: <memory:4536, vCores:2>, assigned nodeId master:39349
2019-01-08 19:58:10,208 INFO org.apache.hadoop.yarn.server.resourcemanager.rmnode.RMNodeImpl: master:39349 Node Transitioned from NEW to RUNNING
2019-01-08 19:58:10,237 INFO org.apache.hadoop.yarn.server.resourcemanager.scheduler.capacity.CapacityScheduler: Added node master:39349 clusterResource: <memory:4536, vCores:2>
2019-01-08 20:07:59,777 INFO org.apache.hadoop.yarn.server.resourcemanager.scheduler.AbstractYarnScheduler: Release request cache is cleaned up
2019-01-08 20:09:18,026 INFO org.apache.hadoop.yarn.server.resourcemanager.ResourceTrackerService: NodeManager from node razoldslave2(cmPort: 40557 httpPort: 8042) registered with capability: <memory:4536, vCores:2>, assigned nodeId razoldslave2:40557
2019-01-08 20:09:18,027 INFO org.apache.hadoop.yarn.server.resourcemanager.rmnode.RMNodeImpl: razoldslave2:40557 Node Transitioned from NEW to RUNNING
2019-01-08 20:09:18,028 INFO org.apache.hadoop.yarn.server.resourcemanager.scheduler.capacity.CapacityScheduler: Added node razoldslave2:40557 clusterResource: <memory:9072, vCores:4>
2019-01-08 20:14:59,966 INFO org.apache.hadoop.yarn.server.resourcemanager.ClientRMService: Allocated new applicationId: 1
2019-01-08 20:15:06,111 INFO org.apache.hadoop.yarn.server.resourcemanager.scheduler.capacity.CapacityScheduler: Application 'application_1546970280036_0001' is submitted without priority hence considering default queue/cluster priority: 0
2019-01-08 20:15:06,112 INFO org.apache.hadoop.yarn.server.resourcemanager.scheduler.capacity.CapacityScheduler: Priority '0' is acceptable in queue : default for application: application_1546970280036_0001
2019-01-08 20:15:06,151 INFO org.apache.hadoop.yarn.server.resourcemanager.rmapp.RMAppImpl: Storing application with id application_1546970280036_0001
2019-01-08 20:15:06,153 INFO org.apache.hadoop.yarn.server.resourcemanager.ClientRMService: Application with id 1 submitted by user hadoop2
2019-01-08 20:15:06,180 INFO org.apache.hadoop.yarn.server.resourcemanager.RMAuditLogger: USER=hadoop2	IP=132.72.109.20	OPERATION=Submit Application Request	TARGET=ClientRMService	RESULT=SUCCESS	APPID=application_1546970280036_0001	CALLERCONTEXT=CLI
2019-01-08 20:15:06,185 INFO org.apache.hadoop.yarn.server.resourcemanager.recovery.RMStateStore: Storing info for app: application_1546970280036_0001
2019-01-08 20:15:06,196 INFO org.apache.hadoop.yarn.server.resourcemanager.rmapp.RMAppImpl: application_1546970280036_0001 State change from NEW to NEW_SAVING on event = START
2019-01-08 20:15:06,198 INFO org.apache.hadoop.yarn.server.resourcemanager.rmapp.RMAppImpl: application_1546970280036_0001 State change from NEW_SAVING to SUBMITTED on event = APP_NEW_SAVED
2019-01-08 20:15:06,207 INFO org.apache.hadoop.yarn.server.resourcemanager.scheduler.capacity.ParentQueue: Application added - appId: application_1546970280036_0001 user: hadoop2 leaf-queue of parent: root #applications: 1
2019-01-08 20:15:06,207 INFO org.apache.hadoop.yarn.server.resourcemanager.scheduler.capacity.CapacityScheduler: Accepted application application_1546970280036_0001 from user: hadoop2, in queue: default
2019-01-08 20:15:06,281 INFO org.apache.hadoop.yarn.server.resourcemanager.rmapp.RMAppImpl: application_1546970280036_0001 State change from SUBMITTED to ACCEPTED on event = APP_ACCEPTED
2019-01-08 20:15:06,380 INFO org.apache.hadoop.yarn.server.resourcemanager.ApplicationMasterService: Registering app attempt : appattempt_1546970280036_0001_000001
2019-01-08 20:15:06,382 INFO org.apache.hadoop.yarn.server.resourcemanager.rmapp.attempt.RMAppAttemptImpl: appattempt_1546970280036_0001_000001 State change from NEW to SUBMITTED on event = START
2019-01-08 20:15:06,449 INFO org.apache.hadoop.yarn.server.resourcemanager.scheduler.capacity.LeafQueue: Application application_1546970280036_0001 from user: hadoop2 activated in queue: default
2019-01-08 20:15:06,449 INFO org.apache.hadoop.yarn.server.resourcemanager.scheduler.capacity.LeafQueue: Application added - appId: application_1546970280036_0001 user: hadoop2, leaf-queue: default #user-pending-applications: 0 #user-active-applications: 1 #queue-pending-applications: 0 #queue-active-applications: 1
2019-01-08 20:15:06,450 INFO org.apache.hadoop.yarn.server.resourcemanager.scheduler.capacity.CapacityScheduler: Added Application Attempt appattempt_1546970280036_0001_000001 to scheduler from user hadoop2 in queue default
2019-01-08 20:15:06,473 INFO org.apache.hadoop.yarn.server.resourcemanager.rmapp.attempt.RMAppAttemptImpl: appattempt_1546970280036_0001_000001 State change from SUBMITTED to SCHEDULED on event = ATTEMPT_ADDED
2019-01-08 20:15:06,934 INFO org.apache.hadoop.yarn.server.resourcemanager.scheduler.capacity.allocator.AbstractContainerAllocator: assignedContainer application attempt=appattempt_1546970280036_0001_000001 container=null queue=org.apache.hadoop.yarn.server.resourcemanager.scheduler.capacity.allocator.RegularContainerAllocator@4caad69f clusterResource=<memory:9072, vCores:4> type=OFF_SWITCH requestedPartition=
2019-01-08 20:15:06,935 INFO org.apache.hadoop.yarn.server.resourcemanager.scheduler.capacity.ParentQueue: assignedContainer queue=root usedCapacity=0.0 absoluteUsedCapacity=0.0 used=<memory:0, vCores:0> cluster=<memory:9072, vCores:4>
2019-01-08 20:15:06,939 INFO org.apache.hadoop.yarn.server.resourcemanager.rmcontainer.RMContainerImpl: container_1546970280036_0001_01_000001 Container Transitioned from NEW to ALLOCATED
2019-01-08 20:15:06,940 INFO org.apache.hadoop.yarn.server.resourcemanager.RMAuditLogger: USER=hadoop2	OPERATION=AM Allocated Container	TARGET=SchedulerApp	RESULT=SUCCESS	APPID=application_1546970280036_0001	CONTAINERID=container_1546970280036_0001_01_000001	RESOURCE=<memory:512, vCores:1>
2019-01-08 20:15:06,981 INFO org.apache.hadoop.yarn.server.resourcemanager.security.NMTokenSecretManagerInRM: Sending NMToken for nodeId : razoldslave2:40557 for container : container_1546970280036_0001_01_000001
2019-01-08 20:15:07,012 INFO org.apache.hadoop.yarn.server.resourcemanager.rmcontainer.RMContainerImpl: container_1546970280036_0001_01_000001 Container Transitioned from ALLOCATED to ACQUIRED
2019-01-08 20:15:07,013 INFO org.apache.hadoop.yarn.server.resourcemanager.scheduler.capacity.ParentQueue: assignedContainer queue=root usedCapacity=0.056437388 absoluteUsedCapacity=0.056437388 used=<memory:512, vCores:1> cluster=<memory:9072, vCores:4>
2019-01-08 20:15:07,013 INFO org.apache.hadoop.yarn.server.resourcemanager.scheduler.capacity.CapacityScheduler: Allocation proposal accepted
2019-01-08 20:15:07,014 INFO org.apache.hadoop.yarn.server.resourcemanager.security.NMTokenSecretManagerInRM: Clear node set for appattempt_1546970280036_0001_000001
2019-01-08 20:15:07,014 INFO org.apache.hadoop.yarn.server.resourcemanager.rmapp.attempt.RMAppAttemptImpl: Storing attempt: AppId: application_1546970280036_0001 AttemptId: appattempt_1546970280036_0001_000001 MasterContainer: Container: [ContainerId: container_1546970280036_0001_01_000001, AllocationRequestId: 0, Version: 0, NodeId: razoldslave2:40557, NodeHttpAddress: razoldslave2:8042, Resource: <memory:512, vCores:1>, Priority: 0, Token: Token { kind: ContainerToken, service: 132.72.109.41:40557 }, ExecutionType: GUARANTEED, ]
2019-01-08 20:15:07,031 INFO org.apache.hadoop.yarn.server.resourcemanager.rmapp.attempt.RMAppAttemptImpl: appattempt_1546970280036_0001_000001 State change from SCHEDULED to ALLOCATED_SAVING on event = CONTAINER_ALLOCATED
2019-01-08 20:15:07,038 INFO org.apache.hadoop.yarn.server.resourcemanager.rmapp.attempt.RMAppAttemptImpl: appattempt_1546970280036_0001_000001 State change from ALLOCATED_SAVING to ALLOCATED on event = ATTEMPT_NEW_SAVED
2019-01-08 20:15:07,048 INFO org.apache.hadoop.yarn.server.resourcemanager.amlauncher.AMLauncher: Launching masterappattempt_1546970280036_0001_000001
2019-01-08 20:15:07,131 INFO org.apache.hadoop.yarn.server.resourcemanager.amlauncher.AMLauncher: Setting up container Container: [ContainerId: container_1546970280036_0001_01_000001, AllocationRequestId: 0, Version: 0, NodeId: razoldslave2:40557, NodeHttpAddress: razoldslave2:8042, Resource: <memory:512, vCores:1>, Priority: 0, Token: Token { kind: ContainerToken, service: 132.72.109.41:40557 }, ExecutionType: GUARANTEED, ] for AM appattempt_1546970280036_0001_000001
2019-01-08 20:15:07,138 INFO org.apache.hadoop.yarn.server.resourcemanager.security.AMRMTokenSecretManager: Create AMRMToken for ApplicationAttempt: appattempt_1546970280036_0001_000001
2019-01-08 20:15:07,142 INFO org.apache.hadoop.yarn.server.resourcemanager.security.AMRMTokenSecretManager: Creating password for appattempt_1546970280036_0001_000001
2019-01-08 20:15:07,742 INFO org.apache.hadoop.yarn.server.resourcemanager.amlauncher.AMLauncher: Done launching container Container: [ContainerId: container_1546970280036_0001_01_000001, AllocationRequestId: 0, Version: 0, NodeId: razoldslave2:40557, NodeHttpAddress: razoldslave2:8042, Resource: <memory:512, vCores:1>, Priority: 0, Token: Token { kind: ContainerToken, service: 132.72.109.41:40557 }, ExecutionType: GUARANTEED, ] for AM appattempt_1546970280036_0001_000001
2019-01-08 20:15:07,742 INFO org.apache.hadoop.yarn.server.resourcemanager.rmapp.attempt.RMAppAttemptImpl: appattempt_1546970280036_0001_000001 State change from ALLOCATED to LAUNCHED on event = LAUNCHED
2019-01-08 20:15:07,932 INFO org.apache.hadoop.yarn.server.resourcemanager.rmcontainer.RMContainerImpl: container_1546970280036_0001_01_000001 Container Transitioned from ACQUIRED to RUNNING
2019-01-08 20:15:16,183 INFO SecurityLogger.org.apache.hadoop.ipc.Server: Auth successful for appattempt_1546970280036_0001_000001 (auth:SIMPLE)
2019-01-08 20:15:16,219 INFO org.apache.hadoop.yarn.server.resourcemanager.DefaultAMSProcessor: AM registration appattempt_1546970280036_0001_000001
2019-01-08 20:15:16,220 INFO org.apache.hadoop.yarn.server.resourcemanager.RMAuditLogger: USER=hadoop2	IP=132.72.109.41	OPERATION=Register App Master	TARGET=ApplicationMasterService	RESULT=SUCCESS	APPID=application_1546970280036_0001	APPATTEMPTID=appattempt_1546970280036_0001_000001
2019-01-08 20:15:16,220 INFO org.apache.hadoop.yarn.server.resourcemanager.rmapp.attempt.RMAppAttemptImpl: appattempt_1546970280036_0001_000001 State change from LAUNCHED to RUNNING on event = REGISTERED
2019-01-08 20:15:16,221 INFO org.apache.hadoop.yarn.server.resourcemanager.rmapp.RMAppImpl: application_1546970280036_0001 State change from ACCEPTED to RUNNING on event = ATTEMPT_REGISTERED
2019-01-08 20:15:17,383 INFO org.apache.hadoop.yarn.server.resourcemanager.scheduler.capacity.allocator.AbstractContainerAllocator: assignedContainer application attempt=appattempt_1546970280036_0001_000001 container=null queue=org.apache.hadoop.yarn.server.resourcemanager.scheduler.capacity.allocator.RegularContainerAllocator@4caad69f clusterResource=<memory:9072, vCores:4> type=NODE_LOCAL requestedPartition=
2019-01-08 20:15:17,383 INFO org.apache.hadoop.yarn.server.resourcemanager.scheduler.capacity.ParentQueue: assignedContainer queue=root usedCapacity=0.056437388 absoluteUsedCapacity=0.056437388 used=<memory:512, vCores:1> cluster=<memory:9072, vCores:4>
2019-01-08 20:15:17,384 INFO org.apache.hadoop.yarn.server.resourcemanager.rmcontainer.RMContainerImpl: container_1546970280036_0001_01_000002 Container Transitioned from NEW to ALLOCATED
2019-01-08 20:15:17,384 INFO org.apache.hadoop.yarn.server.resourcemanager.RMAuditLogger: USER=hadoop2	OPERATION=AM Allocated Container	TARGET=SchedulerApp	RESULT=SUCCESS	APPID=application_1546970280036_0001	CONTAINERID=container_1546970280036_0001_01_000002	RESOURCE=<memory:512, vCores:1>
2019-01-08 20:15:17,385 INFO org.apache.hadoop.yarn.server.resourcemanager.scheduler.capacity.ParentQueue: assignedContainer queue=root usedCapacity=0.112874776 absoluteUsedCapacity=0.112874776 used=<memory:1024, vCores:2> cluster=<memory:9072, vCores:4>
2019-01-08 20:15:17,385 INFO org.apache.hadoop.yarn.server.resourcemanager.scheduler.capacity.CapacityScheduler: Allocation proposal accepted
2019-01-08 20:15:18,311 INFO org.apache.hadoop.yarn.server.resourcemanager.security.NMTokenSecretManagerInRM: Sending NMToken for nodeId : master:39349 for container : container_1546970280036_0001_01_000002
2019-01-08 20:15:18,313 INFO org.apache.hadoop.yarn.server.resourcemanager.rmcontainer.RMContainerImpl: container_1546970280036_0001_01_000002 Container Transitioned from ALLOCATED to ACQUIRED
2019-01-08 20:15:18,384 INFO org.apache.hadoop.yarn.server.resourcemanager.scheduler.capacity.allocator.AbstractContainerAllocator: assignedContainer application attempt=appattempt_1546970280036_0001_000001 container=null queue=org.apache.hadoop.yarn.server.resourcemanager.scheduler.capacity.allocator.RegularContainerAllocator@4caad69f clusterResource=<memory:9072, vCores:4> type=OFF_SWITCH requestedPartition=
2019-01-08 20:15:18,385 INFO org.apache.hadoop.yarn.server.resourcemanager.scheduler.capacity.ParentQueue: assignedContainer queue=root usedCapacity=0.112874776 absoluteUsedCapacity=0.112874776 used=<memory:1024, vCores:2> cluster=<memory:9072, vCores:4>
2019-01-08 20:15:18,385 INFO org.apache.hadoop.yarn.server.resourcemanager.rmcontainer.RMContainerImpl: container_1546970280036_0001_01_000003 Container Transitioned from NEW to ALLOCATED
2019-01-08 20:15:18,385 INFO org.apache.hadoop.yarn.server.resourcemanager.RMAuditLogger: USER=hadoop2	OPERATION=AM Allocated Container	TARGET=SchedulerApp	RESULT=SUCCESS	APPID=application_1546970280036_0001	CONTAINERID=container_1546970280036_0001_01_000003	RESOURCE=<memory:512, vCores:1>
2019-01-08 20:15:18,385 INFO org.apache.hadoop.yarn.server.resourcemanager.scheduler.capacity.ParentQueue: assignedContainer queue=root usedCapacity=0.16931216 absoluteUsedCapacity=0.16931216 used=<memory:1536, vCores:3> cluster=<memory:9072, vCores:4>
2019-01-08 20:15:18,385 INFO org.apache.hadoop.yarn.server.resourcemanager.scheduler.capacity.CapacityScheduler: Allocation proposal accepted
2019-01-08 20:15:18,991 INFO org.apache.hadoop.yarn.server.resourcemanager.scheduler.capacity.allocator.AbstractContainerAllocator: assignedContainer application attempt=appattempt_1546970280036_0001_000001 container=null queue=org.apache.hadoop.yarn.server.resourcemanager.scheduler.capacity.allocator.RegularContainerAllocator@4caad69f clusterResource=<memory:9072, vCores:4> type=OFF_SWITCH requestedPartition=
2019-01-08 20:15:18,991 INFO org.apache.hadoop.yarn.server.resourcemanager.scheduler.capacity.ParentQueue: assignedContainer queue=root usedCapacity=0.16931216 absoluteUsedCapacity=0.16931216 used=<memory:1536, vCores:3> cluster=<memory:9072, vCores:4>
2019-01-08 20:15:18,991 INFO org.apache.hadoop.yarn.server.resourcemanager.rmcontainer.RMContainerImpl: container_1546970280036_0001_01_000004 Container Transitioned from NEW to ALLOCATED
2019-01-08 20:15:18,992 INFO org.apache.hadoop.yarn.server.resourcemanager.RMAuditLogger: USER=hadoop2	OPERATION=AM Allocated Container	TARGET=SchedulerApp	RESULT=SUCCESS	APPID=application_1546970280036_0001	CONTAINERID=container_1546970280036_0001_01_000004	RESOURCE=<memory:512, vCores:1>
2019-01-08 20:15:18,992 INFO org.apache.hadoop.yarn.server.resourcemanager.scheduler.capacity.ParentQueue: assignedContainer queue=root usedCapacity=0.22574955 absoluteUsedCapacity=0.22574955 used=<memory:2048, vCores:4> cluster=<memory:9072, vCores:4>
2019-01-08 20:15:18,992 INFO org.apache.hadoop.yarn.server.resourcemanager.scheduler.capacity.CapacityScheduler: Allocation proposal accepted
2019-01-08 20:15:19,334 INFO org.apache.hadoop.yarn.server.resourcemanager.scheduler.AppSchedulingInfo: checking for deactivate of application :application_1546970280036_0001
2019-01-08 20:15:19,338 INFO org.apache.hadoop.yarn.server.resourcemanager.rmcontainer.RMContainerImpl: container_1546970280036_0001_01_000003 Container Transitioned from ALLOCATED to ACQUIRED
2019-01-08 20:15:19,340 INFO org.apache.hadoop.yarn.server.resourcemanager.security.NMTokenSecretManagerInRM: Sending NMToken for nodeId : razoldslave2:40557 for container : container_1546970280036_0001_01_000004
2019-01-08 20:15:19,347 INFO org.apache.hadoop.yarn.server.resourcemanager.rmcontainer.RMContainerImpl: container_1546970280036_0001_01_000004 Container Transitioned from ALLOCATED to ACQUIRED
2019-01-08 20:15:19,431 INFO org.apache.hadoop.yarn.server.resourcemanager.rmcontainer.RMContainerImpl: container_1546970280036_0001_01_000002 Container Transitioned from ACQUIRED to RUNNING
2019-01-08 20:15:19,431 INFO org.apache.hadoop.yarn.server.resourcemanager.scheduler.capacity.allocator.AbstractContainerAllocator: assignedContainer application attempt=appattempt_1546970280036_0001_000001 container=null queue=org.apache.hadoop.yarn.server.resourcemanager.scheduler.capacity.allocator.RegularContainerAllocator@4caad69f clusterResource=<memory:9072, vCores:4> type=OFF_SWITCH requestedPartition=
2019-01-08 20:15:19,431 INFO org.apache.hadoop.yarn.server.resourcemanager.scheduler.capacity.ParentQueue: assignedContainer queue=root usedCapacity=0.22574955 absoluteUsedCapacity=0.22574955 used=<memory:2048, vCores:4> cluster=<memory:9072, vCores:4>
2019-01-08 20:15:19,432 INFO org.apache.hadoop.yarn.server.resourcemanager.rmcontainer.RMContainerImpl: container_1546970280036_0001_01_000005 Container Transitioned from NEW to ALLOCATED
2019-01-08 20:15:19,432 INFO org.apache.hadoop.yarn.server.resourcemanager.RMAuditLogger: USER=hadoop2	OPERATION=AM Allocated Container	TARGET=SchedulerApp	RESULT=SUCCESS	APPID=application_1546970280036_0001	CONTAINERID=container_1546970280036_0001_01_000005	RESOURCE=<memory:512, vCores:1>
2019-01-08 20:15:19,432 INFO org.apache.hadoop.yarn.server.resourcemanager.scheduler.capacity.ParentQueue: assignedContainer queue=root usedCapacity=0.28218696 absoluteUsedCapacity=0.28218696 used=<memory:2560, vCores:5> cluster=<memory:9072, vCores:4>
2019-01-08 20:15:19,432 INFO org.apache.hadoop.yarn.server.resourcemanager.scheduler.capacity.CapacityScheduler: Allocation proposal accepted
2019-01-08 20:15:19,958 INFO org.apache.hadoop.yarn.server.resourcemanager.rmcontainer.RMContainerImpl: container_1546970280036_0001_01_000004 Container Transitioned from ACQUIRED to RUNNING
2019-01-08 20:15:19,958 INFO org.apache.hadoop.yarn.server.resourcemanager.scheduler.capacity.allocator.AbstractContainerAllocator: assignedContainer application attempt=appattempt_1546970280036_0001_000001 container=null queue=org.apache.hadoop.yarn.server.resourcemanager.scheduler.capacity.allocator.RegularContainerAllocator@4caad69f clusterResource=<memory:9072, vCores:4> type=OFF_SWITCH requestedPartition=
2019-01-08 20:15:19,958 INFO org.apache.hadoop.yarn.server.resourcemanager.scheduler.capacity.ParentQueue: assignedContainer queue=root usedCapacity=0.28218696 absoluteUsedCapacity=0.28218696 used=<memory:2560, vCores:5> cluster=<memory:9072, vCores:4>
2019-01-08 20:15:19,958 INFO org.apache.hadoop.yarn.server.resourcemanager.rmcontainer.RMContainerImpl: container_1546970280036_0001_01_000006 Container Transitioned from NEW to ALLOCATED
2019-01-08 20:15:19,958 INFO org.apache.hadoop.yarn.server.resourcemanager.RMAuditLogger: USER=hadoop2	OPERATION=AM Allocated Container	TARGET=SchedulerApp	RESULT=SUCCESS	APPID=application_1546970280036_0001	CONTAINERID=container_1546970280036_0001_01_000006	RESOURCE=<memory:512, vCores:1>
2019-01-08 20:15:19,959 INFO org.apache.hadoop.yarn.server.resourcemanager.scheduler.capacity.ParentQueue: assignedContainer queue=root usedCapacity=0.33862433 absoluteUsedCapacity=0.33862433 used=<memory:3072, vCores:6> cluster=<memory:9072, vCores:4>
2019-01-08 20:15:19,959 INFO org.apache.hadoop.yarn.server.resourcemanager.scheduler.capacity.CapacityScheduler: Allocation proposal accepted
2019-01-08 20:15:20,354 INFO org.apache.hadoop.yarn.server.resourcemanager.rmcontainer.RMContainerImpl: container_1546970280036_0001_01_000005 Container Transitioned from ALLOCATED to ACQUIRED
2019-01-08 20:15:20,355 INFO org.apache.hadoop.yarn.server.resourcemanager.rmcontainer.RMContainerImpl: container_1546970280036_0001_01_000006 Container Transitioned from ALLOCATED to ACQUIRED
2019-01-08 20:15:20,444 INFO org.apache.hadoop.yarn.server.resourcemanager.rmcontainer.RMContainerImpl: container_1546970280036_0001_01_000003 Container Transitioned from ACQUIRED to RUNNING
2019-01-08 20:15:20,445 INFO org.apache.hadoop.yarn.server.resourcemanager.scheduler.capacity.allocator.AbstractContainerAllocator: assignedContainer application attempt=appattempt_1546970280036_0001_000001 container=null queue=org.apache.hadoop.yarn.server.resourcemanager.scheduler.capacity.allocator.RegularContainerAllocator@4caad69f clusterResource=<memory:9072, vCores:4> type=OFF_SWITCH requestedPartition=
2019-01-08 20:15:20,445 INFO org.apache.hadoop.yarn.server.resourcemanager.scheduler.capacity.ParentQueue: assignedContainer queue=root usedCapacity=0.33862433 absoluteUsedCapacity=0.33862433 used=<memory:3072, vCores:6> cluster=<memory:9072, vCores:4>
2019-01-08 20:15:20,446 INFO org.apache.hadoop.yarn.server.resourcemanager.rmcontainer.RMContainerImpl: container_1546970280036_0001_01_000007 Container Transitioned from NEW to ALLOCATED
2019-01-08 20:15:20,446 INFO org.apache.hadoop.yarn.server.resourcemanager.RMAuditLogger: USER=hadoop2	OPERATION=AM Allocated Container	TARGET=SchedulerApp	RESULT=SUCCESS	APPID=application_1546970280036_0001	CONTAINERID=container_1546970280036_0001_01_000007	RESOURCE=<memory:512, vCores:1>
2019-01-08 20:15:20,446 INFO org.apache.hadoop.yarn.server.resourcemanager.scheduler.capacity.ParentQueue: assignedContainer queue=root usedCapacity=0.39506173 absoluteUsedCapacity=0.39506173 used=<memory:3584, vCores:7> cluster=<memory:9072, vCores:4>
2019-01-08 20:15:20,446 INFO org.apache.hadoop.yarn.server.resourcemanager.scheduler.capacity.CapacityScheduler: Allocation proposal accepted
2019-01-08 20:15:20,964 INFO org.apache.hadoop.yarn.server.resourcemanager.rmcontainer.RMContainerImpl: container_1546970280036_0001_01_000006 Container Transitioned from ACQUIRED to RUNNING
2019-01-08 20:15:20,964 INFO org.apache.hadoop.yarn.server.resourcemanager.scheduler.capacity.allocator.AbstractContainerAllocator: assignedContainer application attempt=appattempt_1546970280036_0001_000001 container=null queue=org.apache.hadoop.yarn.server.resourcemanager.scheduler.capacity.allocator.RegularContainerAllocator@4caad69f clusterResource=<memory:9072, vCores:4> type=OFF_SWITCH requestedPartition=
2019-01-08 20:15:20,964 INFO org.apache.hadoop.yarn.server.resourcemanager.scheduler.capacity.ParentQueue: assignedContainer queue=root usedCapacity=0.39506173 absoluteUsedCapacity=0.39506173 used=<memory:3584, vCores:7> cluster=<memory:9072, vCores:4>
2019-01-08 20:15:20,965 INFO org.apache.hadoop.yarn.server.resourcemanager.rmcontainer.RMContainerImpl: container_1546970280036_0001_01_000008 Container Transitioned from NEW to ALLOCATED
2019-01-08 20:15:20,965 INFO org.apache.hadoop.yarn.server.resourcemanager.RMAuditLogger: USER=hadoop2	OPERATION=AM Allocated Container	TARGET=SchedulerApp	RESULT=SUCCESS	APPID=application_1546970280036_0001	CONTAINERID=container_1546970280036_0001_01_000008	RESOURCE=<memory:512, vCores:1>
2019-01-08 20:15:20,965 INFO org.apache.hadoop.yarn.server.resourcemanager.scheduler.capacity.ParentQueue: assignedContainer queue=root usedCapacity=0.4514991 absoluteUsedCapacity=0.4514991 used=<memory:4096, vCores:8> cluster=<memory:9072, vCores:4>
2019-01-08 20:15:20,965 INFO org.apache.hadoop.yarn.server.resourcemanager.scheduler.capacity.CapacityScheduler: Allocation proposal accepted
2019-01-08 20:15:21,362 INFO org.apache.hadoop.yarn.server.resourcemanager.rmcontainer.RMContainerImpl: container_1546970280036_0001_01_000007 Container Transitioned from ALLOCATED to ACQUIRED
2019-01-08 20:15:21,382 INFO org.apache.hadoop.yarn.server.resourcemanager.rmcontainer.RMContainerImpl: container_1546970280036_0001_01_000008 Container Transitioned from ALLOCATED to ACQUIRED
2019-01-08 20:15:21,453 INFO org.apache.hadoop.yarn.server.resourcemanager.rmcontainer.RMContainerImpl: container_1546970280036_0001_01_000005 Container Transitioned from ACQUIRED to RUNNING
2019-01-08 20:15:21,454 INFO org.apache.hadoop.yarn.server.resourcemanager.scheduler.capacity.allocator.AbstractContainerAllocator: assignedContainer application attempt=appattempt_1546970280036_0001_000001 container=null queue=org.apache.hadoop.yarn.server.resourcemanager.scheduler.capacity.allocator.RegularContainerAllocator@4caad69f clusterResource=<memory:9072, vCores:4> type=OFF_SWITCH requestedPartition=
2019-01-08 20:15:21,454 INFO org.apache.hadoop.yarn.server.resourcemanager.scheduler.capacity.ParentQueue: assignedContainer queue=root usedCapacity=0.4514991 absoluteUsedCapacity=0.4514991 used=<memory:4096, vCores:8> cluster=<memory:9072, vCores:4>
2019-01-08 20:15:21,454 INFO org.apache.hadoop.yarn.server.resourcemanager.rmcontainer.RMContainerImpl: container_1546970280036_0001_01_000009 Container Transitioned from NEW to ALLOCATED
2019-01-08 20:15:21,454 INFO org.apache.hadoop.yarn.server.resourcemanager.RMAuditLogger: USER=hadoop2	OPERATION=AM Allocated Container	TARGET=SchedulerApp	RESULT=SUCCESS	APPID=application_1546970280036_0001	CONTAINERID=container_1546970280036_0001_01_000009	RESOURCE=<memory:512, vCores:1>
2019-01-08 20:15:21,455 INFO org.apache.hadoop.yarn.server.resourcemanager.scheduler.capacity.ParentQueue: assignedContainer queue=root usedCapacity=0.50793654 absoluteUsedCapacity=0.50793654 used=<memory:4608, vCores:9> cluster=<memory:9072, vCores:4>
2019-01-08 20:15:21,455 INFO org.apache.hadoop.yarn.server.resourcemanager.scheduler.capacity.CapacityScheduler: Allocation proposal accepted
2019-01-08 20:15:21,982 INFO org.apache.hadoop.yarn.server.resourcemanager.rmcontainer.RMContainerImpl: container_1546970280036_0001_01_000008 Container Transitioned from ACQUIRED to RUNNING
2019-01-08 20:15:21,983 INFO org.apache.hadoop.yarn.server.resourcemanager.scheduler.capacity.allocator.AbstractContainerAllocator: assignedContainer application attempt=appattempt_1546970280036_0001_000001 container=null queue=org.apache.hadoop.yarn.server.resourcemanager.scheduler.capacity.allocator.RegularContainerAllocator@4caad69f clusterResource=<memory:9072, vCores:4> type=OFF_SWITCH requestedPartition=
2019-01-08 20:15:21,983 INFO org.apache.hadoop.yarn.server.resourcemanager.scheduler.capacity.ParentQueue: assignedContainer queue=root usedCapacity=0.50793654 absoluteUsedCapacity=0.50793654 used=<memory:4608, vCores:9> cluster=<memory:9072, vCores:4>
2019-01-08 20:15:21,983 INFO org.apache.hadoop.yarn.server.resourcemanager.rmcontainer.RMContainerImpl: container_1546970280036_0001_01_000010 Container Transitioned from NEW to ALLOCATED
2019-01-08 20:15:21,983 INFO org.apache.hadoop.yarn.server.resourcemanager.RMAuditLogger: USER=hadoop2	OPERATION=AM Allocated Container	TARGET=SchedulerApp	RESULT=SUCCESS	APPID=application_1546970280036_0001	CONTAINERID=container_1546970280036_0001_01_000010	RESOURCE=<memory:512, vCores:1>
2019-01-08 20:15:21,983 INFO org.apache.hadoop.yarn.server.resourcemanager.scheduler.capacity.ParentQueue: assignedContainer queue=root usedCapacity=0.5643739 absoluteUsedCapacity=0.5643739 used=<memory:5120, vCores:10> cluster=<memory:9072, vCores:4>
2019-01-08 20:15:21,983 INFO org.apache.hadoop.yarn.server.resourcemanager.scheduler.capacity.CapacityScheduler: Allocation proposal accepted
2019-01-08 20:15:22,392 INFO org.apache.hadoop.yarn.server.resourcemanager.rmcontainer.RMContainerImpl: container_1546970280036_0001_01_000009 Container Transitioned from ALLOCATED to ACQUIRED
2019-01-08 20:15:22,395 INFO org.apache.hadoop.yarn.server.resourcemanager.rmcontainer.RMContainerImpl: container_1546970280036_0001_01_000010 Container Transitioned from ALLOCATED to ACQUIRED
2019-01-08 20:15:22,463 INFO org.apache.hadoop.yarn.server.resourcemanager.rmcontainer.RMContainerImpl: container_1546970280036_0001_01_000007 Container Transitioned from ACQUIRED to RUNNING
2019-01-08 20:15:22,464 INFO org.apache.hadoop.yarn.server.resourcemanager.rmcontainer.RMContainerImpl: container_1546970280036_0001_01_000009 Container Transitioned from ACQUIRED to RUNNING
2019-01-08 20:15:22,464 INFO org.apache.hadoop.yarn.server.resourcemanager.scheduler.capacity.allocator.AbstractContainerAllocator: assignedContainer application attempt=appattempt_1546970280036_0001_000001 container=null queue=org.apache.hadoop.yarn.server.resourcemanager.scheduler.capacity.allocator.RegularContainerAllocator@4caad69f clusterResource=<memory:9072, vCores:4> type=OFF_SWITCH requestedPartition=
2019-01-08 20:15:22,464 INFO org.apache.hadoop.yarn.server.resourcemanager.scheduler.capacity.ParentQueue: assignedContainer queue=root usedCapacity=0.5643739 absoluteUsedCapacity=0.5643739 used=<memory:5120, vCores:10> cluster=<memory:9072, vCores:4>
2019-01-08 20:15:22,465 INFO org.apache.hadoop.yarn.server.resourcemanager.rmcontainer.RMContainerImpl: container_1546970280036_0001_01_000011 Container Transitioned from NEW to ALLOCATED
2019-01-08 20:15:22,465 INFO org.apache.hadoop.yarn.server.resourcemanager.RMAuditLogger: USER=hadoop2	OPERATION=AM Allocated Container	TARGET=SchedulerApp	RESULT=SUCCESS	APPID=application_1546970280036_0001	CONTAINERID=container_1546970280036_0001_01_000011	RESOURCE=<memory:512, vCores:1>
2019-01-08 20:15:22,465 INFO org.apache.hadoop.yarn.server.resourcemanager.scheduler.capacity.ParentQueue: assignedContainer queue=root usedCapacity=0.6208113 absoluteUsedCapacity=0.6208113 used=<memory:5632, vCores:11> cluster=<memory:9072, vCores:4>
2019-01-08 20:15:22,465 INFO org.apache.hadoop.yarn.server.resourcemanager.scheduler.capacity.CapacityScheduler: Allocation proposal accepted
2019-01-08 20:15:22,985 INFO org.apache.hadoop.yarn.server.resourcemanager.rmcontainer.RMContainerImpl: container_1546970280036_0001_01_000010 Container Transitioned from ACQUIRED to RUNNING
2019-01-08 20:15:22,986 INFO org.apache.hadoop.yarn.server.resourcemanager.scheduler.capacity.allocator.AbstractContainerAllocator: assignedContainer application attempt=appattempt_1546970280036_0001_000001 container=null queue=org.apache.hadoop.yarn.server.resourcemanager.scheduler.capacity.allocator.RegularContainerAllocator@4caad69f clusterResource=<memory:9072, vCores:4> type=OFF_SWITCH requestedPartition=
2019-01-08 20:15:22,986 INFO org.apache.hadoop.yarn.server.resourcemanager.scheduler.capacity.ParentQueue: assignedContainer queue=root usedCapacity=0.6208113 absoluteUsedCapacity=0.6208113 used=<memory:5632, vCores:11> cluster=<memory:9072, vCores:4>
2019-01-08 20:15:22,986 INFO org.apache.hadoop.yarn.server.resourcemanager.rmcontainer.RMContainerImpl: container_1546970280036_0001_01_000012 Container Transitioned from NEW to ALLOCATED
2019-01-08 20:15:22,986 INFO org.apache.hadoop.yarn.server.resourcemanager.RMAuditLogger: USER=hadoop2	OPERATION=AM Allocated Container	TARGET=SchedulerApp	RESULT=SUCCESS	APPID=application_1546970280036_0001	CONTAINERID=container_1546970280036_0001_01_000012	RESOURCE=<memory:512, vCores:1>
2019-01-08 20:15:22,986 INFO org.apache.hadoop.yarn.server.resourcemanager.scheduler.capacity.ParentQueue: assignedContainer queue=root usedCapacity=0.67724866 absoluteUsedCapacity=0.67724866 used=<memory:6144, vCores:12> cluster=<memory:9072, vCores:4>
2019-01-08 20:15:22,986 INFO org.apache.hadoop.yarn.server.resourcemanager.scheduler.capacity.CapacityScheduler: Allocation proposal accepted
2019-01-08 20:15:23,401 INFO org.apache.hadoop.yarn.server.resourcemanager.rmcontainer.RMContainerImpl: container_1546970280036_0001_01_000011 Container Transitioned from ALLOCATED to ACQUIRED
2019-01-08 20:15:23,403 INFO org.apache.hadoop.yarn.server.resourcemanager.rmcontainer.RMContainerImpl: container_1546970280036_0001_01_000012 Container Transitioned from ALLOCATED to ACQUIRED
2019-01-08 20:15:23,483 INFO org.apache.hadoop.yarn.server.resourcemanager.rmcontainer.RMContainerImpl: container_1546970280036_0001_01_000011 Container Transitioned from ACQUIRED to RUNNING
2019-01-08 20:15:23,484 INFO org.apache.hadoop.yarn.server.resourcemanager.scheduler.capacity.allocator.AbstractContainerAllocator: assignedContainer application attempt=appattempt_1546970280036_0001_000001 container=null queue=org.apache.hadoop.yarn.server.resourcemanager.scheduler.capacity.allocator.RegularContainerAllocator@4caad69f clusterResource=<memory:9072, vCores:4> type=OFF_SWITCH requestedPartition=
2019-01-08 20:15:23,484 INFO org.apache.hadoop.yarn.server.resourcemanager.scheduler.capacity.ParentQueue: assignedContainer queue=root usedCapacity=0.67724866 absoluteUsedCapacity=0.67724866 used=<memory:6144, vCores:12> cluster=<memory:9072, vCores:4>
2019-01-08 20:15:23,484 INFO org.apache.hadoop.yarn.server.resourcemanager.rmcontainer.RMContainerImpl: container_1546970280036_0001_01_000013 Container Transitioned from NEW to ALLOCATED
2019-01-08 20:15:23,484 INFO org.apache.hadoop.yarn.server.resourcemanager.RMAuditLogger: USER=hadoop2	OPERATION=AM Allocated Container	TARGET=SchedulerApp	RESULT=SUCCESS	APPID=application_1546970280036_0001	CONTAINERID=container_1546970280036_0001_01_000013	RESOURCE=<memory:512, vCores:1>
2019-01-08 20:15:23,485 INFO org.apache.hadoop.yarn.server.resourcemanager.scheduler.capacity.ParentQueue: assignedContainer queue=root usedCapacity=0.7336861 absoluteUsedCapacity=0.7336861 used=<memory:6656, vCores:13> cluster=<memory:9072, vCores:4>
2019-01-08 20:15:23,485 INFO org.apache.hadoop.yarn.server.resourcemanager.scheduler.capacity.CapacityScheduler: Allocation proposal accepted
2019-01-08 20:15:24,958 INFO org.apache.hadoop.yarn.server.resourcemanager.rmcontainer.RMContainerImpl: container_1546970280036_0001_01_000012 Container Transitioned from ACQUIRED to RELEASED
2019-01-08 20:15:24,958 INFO org.apache.hadoop.yarn.server.resourcemanager.RMAuditLogger: USER=hadoop2	IP=132.72.109.41	OPERATION=AM Released Container	TARGET=SchedulerApp	RESULT=SUCCESS	APPID=application_1546970280036_0001	CONTAINERID=container_1546970280036_0001_01_000012	RESOURCE=<memory:512, vCores:1>
2019-01-08 20:15:24,960 INFO org.apache.hadoop.yarn.server.resourcemanager.scheduler.AppSchedulingInfo: checking for deactivate of application :application_1546970280036_0001
2019-01-08 20:15:24,972 INFO org.apache.hadoop.yarn.server.resourcemanager.rmcontainer.RMContainerImpl: container_1546970280036_0001_01_000013 Container Transitioned from ALLOCATED to ACQUIRED
2019-01-08 20:15:25,992 INFO org.apache.hadoop.yarn.server.resourcemanager.rmcontainer.RMContainerImpl: container_1546970280036_0001_01_000013 Container Transitioned from ACQUIRED to RELEASED
2019-01-08 20:15:25,992 INFO org.apache.hadoop.yarn.server.resourcemanager.RMAuditLogger: USER=hadoop2	IP=132.72.109.41	OPERATION=AM Released Container	TARGET=SchedulerApp	RESULT=SUCCESS	APPID=application_1546970280036_0001	CONTAINERID=container_1546970280036_0001_01_000013	RESOURCE=<memory:512, vCores:1>
2019-01-08 20:16:15,359 INFO org.apache.hadoop.yarn.server.resourcemanager.rmcontainer.RMContainerImpl: container_1546970280036_0001_01_000002 Container Transitioned from RUNNING to COMPLETED
2019-01-08 20:16:15,376 INFO org.apache.hadoop.yarn.server.resourcemanager.RMAuditLogger: USER=hadoop2	OPERATION=AM Released Container	TARGET=SchedulerApp	RESULT=SUCCESS	APPID=application_1546970280036_0001	CONTAINERID=container_1546970280036_0001_01_000002	RESOURCE=<memory:512, vCores:1>
2019-01-08 20:16:16,453 INFO org.apache.hadoop.yarn.server.resourcemanager.rmcontainer.RMContainerImpl: container_1546970280036_0001_01_000008 Container Transitioned from RUNNING to COMPLETED
2019-01-08 20:16:16,453 INFO org.apache.hadoop.yarn.server.resourcemanager.RMAuditLogger: USER=hadoop2	OPERATION=AM Released Container	TARGET=SchedulerApp	RESULT=SUCCESS	APPID=application_1546970280036_0001	CONTAINERID=container_1546970280036_0001_01_000008	RESOURCE=<memory:512, vCores:1>
2019-01-08 20:16:16,822 INFO org.apache.hadoop.yarn.server.resourcemanager.rmcontainer.RMContainerImpl: container_1546970280036_0001_01_000004 Container Transitioned from RUNNING to COMPLETED
2019-01-08 20:16:16,822 INFO org.apache.hadoop.yarn.server.resourcemanager.RMAuditLogger: USER=hadoop2	OPERATION=AM Released Container	TARGET=SchedulerApp	RESULT=SUCCESS	APPID=application_1546970280036_0001	CONTAINERID=container_1546970280036_0001_01_000004	RESOURCE=<memory:512, vCores:1>
2019-01-08 20:16:16,870 INFO org.apache.hadoop.yarn.server.resourcemanager.rmcontainer.RMContainerImpl: container_1546970280036_0001_01_000006 Container Transitioned from RUNNING to COMPLETED
2019-01-08 20:16:16,871 INFO org.apache.hadoop.yarn.server.resourcemanager.RMAuditLogger: USER=hadoop2	OPERATION=AM Released Container	TARGET=SchedulerApp	RESULT=SUCCESS	APPID=application_1546970280036_0001	CONTAINERID=container_1546970280036_0001_01_000006	RESOURCE=<memory:512, vCores:1>
2019-01-08 20:16:16,871 INFO org.apache.hadoop.yarn.server.resourcemanager.rmcontainer.RMContainerImpl: container_1546970280036_0001_01_000010 Container Transitioned from RUNNING to COMPLETED
2019-01-08 20:16:16,871 INFO org.apache.hadoop.yarn.server.resourcemanager.RMAuditLogger: USER=hadoop2	OPERATION=AM Released Container	TARGET=SchedulerApp	RESULT=SUCCESS	APPID=application_1546970280036_0001	CONTAINERID=container_1546970280036_0001_01_000010	RESOURCE=<memory:512, vCores:1>
2019-01-08 20:16:17,873 INFO org.apache.hadoop.yarn.server.resourcemanager.scheduler.capacity.allocator.AbstractContainerAllocator: assignedContainer application attempt=appattempt_1546970280036_0001_000001 container=null queue=org.apache.hadoop.yarn.server.resourcemanager.scheduler.capacity.allocator.RegularContainerAllocator@4caad69f clusterResource=<memory:9072, vCores:4> type=OFF_SWITCH requestedPartition=
2019-01-08 20:16:17,874 INFO org.apache.hadoop.yarn.server.resourcemanager.scheduler.capacity.ParentQueue: assignedContainer queue=root usedCapacity=0.33862433 absoluteUsedCapacity=0.33862433 used=<memory:3072, vCores:6> cluster=<memory:9072, vCores:4>
2019-01-08 20:16:17,874 INFO org.apache.hadoop.yarn.server.resourcemanager.rmcontainer.RMContainerImpl: container_1546970280036_0001_01_000014 Container Transitioned from NEW to ALLOCATED
2019-01-08 20:16:17,874 INFO org.apache.hadoop.yarn.server.resourcemanager.RMAuditLogger: USER=hadoop2	OPERATION=AM Allocated Container	TARGET=SchedulerApp	RESULT=SUCCESS	APPID=application_1546970280036_0001	CONTAINERID=container_1546970280036_0001_01_000014	RESOURCE=<memory:512, vCores:1>
2019-01-08 20:16:17,874 INFO org.apache.hadoop.yarn.server.resourcemanager.scheduler.capacity.ParentQueue: assignedContainer queue=root usedCapacity=0.39506173 absoluteUsedCapacity=0.39506173 used=<memory:3584, vCores:7> cluster=<memory:9072, vCores:4>
2019-01-08 20:16:17,874 INFO org.apache.hadoop.yarn.server.resourcemanager.scheduler.capacity.CapacityScheduler: Allocation proposal accepted
2019-01-08 20:16:18,526 INFO org.apache.hadoop.yarn.server.resourcemanager.rmcontainer.RMContainerImpl: container_1546970280036_0001_01_000014 Container Transitioned from ALLOCATED to ACQUIRED
2019-01-08 20:16:19,533 INFO org.apache.hadoop.yarn.server.resourcemanager.scheduler.AppSchedulingInfo: checking for deactivate of application :application_1546970280036_0001
2019-01-08 20:16:19,655 INFO org.apache.hadoop.yarn.server.resourcemanager.rmcontainer.RMContainerImpl: container_1546970280036_0001_01_000005 Container Transitioned from RUNNING to COMPLETED
2019-01-08 20:16:19,655 INFO org.apache.hadoop.yarn.server.resourcemanager.RMAuditLogger: USER=hadoop2	OPERATION=AM Released Container	TARGET=SchedulerApp	RESULT=SUCCESS	APPID=application_1546970280036_0001	CONTAINERID=container_1546970280036_0001_01_000005	RESOURCE=<memory:512, vCores:1>
2019-01-08 20:16:19,824 INFO org.apache.hadoop.yarn.server.resourcemanager.rmcontainer.RMContainerImpl: container_1546970280036_0001_01_000007 Container Transitioned from RUNNING to COMPLETED
2019-01-08 20:16:19,824 INFO org.apache.hadoop.yarn.server.resourcemanager.RMAuditLogger: USER=hadoop2	OPERATION=AM Released Container	TARGET=SchedulerApp	RESULT=SUCCESS	APPID=application_1546970280036_0001	CONTAINERID=container_1546970280036_0001_01_000007	RESOURCE=<memory:512, vCores:1>
2019-01-08 20:16:19,824 INFO org.apache.hadoop.yarn.server.resourcemanager.rmcontainer.RMContainerImpl: container_1546970280036_0001_01_000011 Container Transitioned from RUNNING to COMPLETED
2019-01-08 20:16:19,824 INFO org.apache.hadoop.yarn.server.resourcemanager.RMAuditLogger: USER=hadoop2	OPERATION=AM Released Container	TARGET=SchedulerApp	RESULT=SUCCESS	APPID=application_1546970280036_0001	CONTAINERID=container_1546970280036_0001_01_000011	RESOURCE=<memory:512, vCores:1>
2019-01-08 20:16:20,163 INFO org.apache.hadoop.yarn.server.resourcemanager.rmapp.attempt.RMAppAttemptImpl: Updating application attempt appattempt_1546970280036_0001_000001 with final state: FINISHING, and exit status: -1000
2019-01-08 20:16:20,170 INFO org.apache.hadoop.yarn.server.resourcemanager.rmapp.attempt.RMAppAttemptImpl: appattempt_1546970280036_0001_000001 State change from RUNNING to FINAL_SAVING on event = UNREGISTERED
2019-01-08 20:16:20,170 INFO org.apache.hadoop.yarn.server.resourcemanager.rmapp.attempt.RMAppAttemptImpl: appattempt_1546970280036_0001_000001 State change from FINAL_SAVING to FINISHING on event = ATTEMPT_UPDATE_SAVED
2019-01-08 20:16:20,170 INFO org.apache.hadoop.yarn.server.resourcemanager.rmapp.RMAppImpl: Updating application application_1546970280036_0001 with final state: FINISHING
2019-01-08 20:16:20,170 INFO org.apache.hadoop.yarn.server.resourcemanager.recovery.RMStateStore: Updating info for app: application_1546970280036_0001
2019-01-08 20:16:20,171 INFO org.apache.hadoop.yarn.server.resourcemanager.rmapp.RMAppImpl: application_1546970280036_0001 State change from RUNNING to FINAL_SAVING on event = ATTEMPT_UNREGISTERED
2019-01-08 20:16:20,171 INFO org.apache.hadoop.yarn.server.resourcemanager.rmapp.RMAppImpl: application_1546970280036_0001 State change from FINAL_SAVING to FINISHING on event = APP_UPDATE_SAVED
2019-01-08 20:16:20,826 INFO org.apache.hadoop.yarn.server.resourcemanager.rmcontainer.RMContainerImpl: container_1546970280036_0001_01_000003 Container Transitioned from RUNNING to COMPLETED
2019-01-08 20:16:20,826 INFO org.apache.hadoop.yarn.server.resourcemanager.RMAuditLogger: USER=hadoop2	OPERATION=AM Released Container	TARGET=SchedulerApp	RESULT=SUCCESS	APPID=application_1546970280036_0001	CONTAINERID=container_1546970280036_0001_01_000003	RESOURCE=<memory:512, vCores:1>
2019-01-08 20:16:20,827 INFO org.apache.hadoop.yarn.server.resourcemanager.rmcontainer.RMContainerImpl: container_1546970280036_0001_01_000009 Container Transitioned from RUNNING to COMPLETED
2019-01-08 20:16:20,827 INFO org.apache.hadoop.yarn.server.resourcemanager.RMAuditLogger: USER=hadoop2	OPERATION=AM Released Container	TARGET=SchedulerApp	RESULT=SUCCESS	APPID=application_1546970280036_0001	CONTAINERID=container_1546970280036_0001_01_000009	RESOURCE=<memory:512, vCores:1>
2019-01-08 20:16:21,168 INFO org.apache.hadoop.yarn.server.resourcemanager.ApplicationMasterService: application_1546970280036_0001 unregistered successfully. 
2019-01-08 20:16:21,658 INFO org.apache.hadoop.yarn.server.resourcemanager.ClientRMService: Allocated new applicationId: 2
2019-01-08 20:16:26,405 INFO org.apache.hadoop.yarn.server.resourcemanager.scheduler.capacity.CapacityScheduler: Application 'application_1546970280036_0002' is submitted without priority hence considering default queue/cluster priority: 0
2019-01-08 20:16:26,405 INFO org.apache.hadoop.yarn.server.resourcemanager.scheduler.capacity.CapacityScheduler: Priority '0' is acceptable in queue : default for application: application_1546970280036_0002
2019-01-08 20:16:26,405 INFO org.apache.hadoop.yarn.server.resourcemanager.ClientRMService: Application with id 2 submitted by user hadoop2
2019-01-08 20:16:26,405 INFO org.apache.hadoop.yarn.server.resourcemanager.RMAuditLogger: USER=hadoop2	IP=132.72.109.20	OPERATION=Submit Application Request	TARGET=ClientRMService	RESULT=SUCCESS	APPID=application_1546970280036_0002	CALLERCONTEXT=CLI
2019-01-08 20:16:26,406 INFO org.apache.hadoop.yarn.server.resourcemanager.rmapp.RMAppImpl: Storing application with id application_1546970280036_0002
2019-01-08 20:16:26,406 INFO org.apache.hadoop.yarn.server.resourcemanager.rmapp.RMAppImpl: application_1546970280036_0002 State change from NEW to NEW_SAVING on event = START
2019-01-08 20:16:26,406 INFO org.apache.hadoop.yarn.server.resourcemanager.recovery.RMStateStore: Storing info for app: application_1546970280036_0002
2019-01-08 20:16:26,409 INFO org.apache.hadoop.yarn.server.resourcemanager.rmapp.RMAppImpl: application_1546970280036_0002 State change from NEW_SAVING to SUBMITTED on event = APP_NEW_SAVED
2019-01-08 20:16:26,409 INFO org.apache.hadoop.yarn.server.resourcemanager.scheduler.capacity.ParentQueue: Application added - appId: application_1546970280036_0002 user: hadoop2 leaf-queue of parent: root #applications: 2
2019-01-08 20:16:26,410 INFO org.apache.hadoop.yarn.server.resourcemanager.scheduler.capacity.CapacityScheduler: Accepted application application_1546970280036_0002 from user: hadoop2, in queue: default
2019-01-08 20:16:26,413 INFO org.apache.hadoop.yarn.server.resourcemanager.rmapp.RMAppImpl: application_1546970280036_0002 State change from SUBMITTED to ACCEPTED on event = APP_ACCEPTED
2019-01-08 20:16:26,413 INFO org.apache.hadoop.yarn.server.resourcemanager.ApplicationMasterService: Registering app attempt : appattempt_1546970280036_0002_000001
2019-01-08 20:16:26,413 INFO org.apache.hadoop.yarn.server.resourcemanager.rmapp.attempt.RMAppAttemptImpl: appattempt_1546970280036_0002_000001 State change from NEW to SUBMITTED on event = START
2019-01-08 20:16:26,414 INFO org.apache.hadoop.yarn.server.resourcemanager.scheduler.capacity.LeafQueue: Application application_1546970280036_0002 from user: hadoop2 activated in queue: default
2019-01-08 20:16:26,414 INFO org.apache.hadoop.yarn.server.resourcemanager.scheduler.capacity.LeafQueue: Application added - appId: application_1546970280036_0002 user: hadoop2, leaf-queue: default #user-pending-applications: 0 #user-active-applications: 2 #queue-pending-applications: 0 #queue-active-applications: 2
2019-01-08 20:16:26,414 INFO org.apache.hadoop.yarn.server.resourcemanager.scheduler.capacity.CapacityScheduler: Added Application Attempt appattempt_1546970280036_0002_000001 to scheduler from user hadoop2 in queue default
2019-01-08 20:16:26,415 INFO org.apache.hadoop.yarn.server.resourcemanager.rmapp.attempt.RMAppAttemptImpl: appattempt_1546970280036_0002_000001 State change from SUBMITTED to SCHEDULED on event = ATTEMPT_ADDED
2019-01-08 20:16:26,587 INFO org.apache.hadoop.yarn.server.resourcemanager.rmcontainer.RMContainerImpl: container_1546970280036_0001_01_000001 Container Transitioned from RUNNING to COMPLETED
2019-01-08 20:16:26,587 INFO org.apache.hadoop.yarn.server.resourcemanager.ApplicationMasterService: Unregistering app attempt : appattempt_1546970280036_0001_000001
2019-01-08 20:16:26,587 INFO org.apache.hadoop.yarn.server.resourcemanager.RMAuditLogger: USER=hadoop2	OPERATION=AM Released Container	TARGET=SchedulerApp	RESULT=SUCCESS	APPID=application_1546970280036_0001	CONTAINERID=container_1546970280036_0001_01_000001	RESOURCE=<memory:512, vCores:1>
2019-01-08 20:16:26,589 INFO org.apache.hadoop.yarn.server.resourcemanager.scheduler.capacity.allocator.AbstractContainerAllocator: assignedContainer application attempt=appattempt_1546970280036_0002_000001 container=null queue=org.apache.hadoop.yarn.server.resourcemanager.scheduler.capacity.allocator.RegularContainerAllocator@14bd88be clusterResource=<memory:9072, vCores:4> type=OFF_SWITCH requestedPartition=
2019-01-08 20:16:26,589 INFO org.apache.hadoop.yarn.server.resourcemanager.scheduler.capacity.ParentQueue: assignedContainer queue=root usedCapacity=0.056437388 absoluteUsedCapacity=0.056437388 used=<memory:512, vCores:1> cluster=<memory:9072, vCores:4>
2019-01-08 20:16:26,589 INFO org.apache.hadoop.yarn.server.resourcemanager.rmcontainer.RMContainerImpl: container_1546970280036_0002_01_000001 Container Transitioned from NEW to ALLOCATED
2019-01-08 20:16:26,589 INFO org.apache.hadoop.yarn.server.resourcemanager.RMAuditLogger: USER=hadoop2	OPERATION=AM Allocated Container	TARGET=SchedulerApp	RESULT=SUCCESS	APPID=application_1546970280036_0002	CONTAINERID=container_1546970280036_0002_01_000001	RESOURCE=<memory:512, vCores:1>
2019-01-08 20:16:26,590 INFO org.apache.hadoop.yarn.server.resourcemanager.scheduler.capacity.ParentQueue: assignedContainer queue=root usedCapacity=0.112874776 absoluteUsedCapacity=0.112874776 used=<memory:1024, vCores:2> cluster=<memory:9072, vCores:4>
2019-01-08 20:16:26,590 INFO org.apache.hadoop.yarn.server.resourcemanager.scheduler.capacity.CapacityScheduler: Allocation proposal accepted
2019-01-08 20:16:26,622 INFO org.apache.hadoop.yarn.server.resourcemanager.security.AMRMTokenSecretManager: Application finished, removing password for appattempt_1546970280036_0001_000001
2019-01-08 20:16:26,622 INFO org.apache.hadoop.yarn.server.resourcemanager.rmapp.attempt.RMAppAttemptImpl: appattempt_1546970280036_0001_000001 State change from FINISHING to FINISHED on event = CONTAINER_FINISHED
2019-01-08 20:16:26,633 INFO org.apache.hadoop.yarn.server.resourcemanager.rmapp.RMAppImpl: application_1546970280036_0001 State change from FINISHING to FINISHED on event = ATTEMPT_FINISHED
2019-01-08 20:16:26,633 INFO org.apache.hadoop.yarn.server.resourcemanager.security.NMTokenSecretManagerInRM: Sending NMToken for nodeId : razoldslave2:40557 for container : container_1546970280036_0002_01_000001
2019-01-08 20:16:26,634 INFO org.apache.hadoop.yarn.server.resourcemanager.rmcontainer.RMContainerImpl: container_1546970280036_0002_01_000001 Container Transitioned from ALLOCATED to ACQUIRED
2019-01-08 20:16:26,634 INFO org.apache.hadoop.yarn.server.resourcemanager.security.NMTokenSecretManagerInRM: Clear node set for appattempt_1546970280036_0002_000001
2019-01-08 20:16:26,634 INFO org.apache.hadoop.yarn.server.resourcemanager.rmapp.attempt.RMAppAttemptImpl: Storing attempt: AppId: application_1546970280036_0002 AttemptId: appattempt_1546970280036_0002_000001 MasterContainer: Container: [ContainerId: container_1546970280036_0002_01_000001, AllocationRequestId: 0, Version: 0, NodeId: razoldslave2:40557, NodeHttpAddress: razoldslave2:8042, Resource: <memory:512, vCores:1>, Priority: 0, Token: Token { kind: ContainerToken, service: 132.72.109.41:40557 }, ExecutionType: GUARANTEED, ]
2019-01-08 20:16:26,634 INFO org.apache.hadoop.yarn.server.resourcemanager.rmapp.attempt.RMAppAttemptImpl: appattempt_1546970280036_0002_000001 State change from SCHEDULED to ALLOCATED_SAVING on event = CONTAINER_ALLOCATED
2019-01-08 20:16:26,634 INFO org.apache.hadoop.yarn.server.resourcemanager.scheduler.capacity.CapacityScheduler: Application Attempt appattempt_1546970280036_0001_000001 is done. finalState=FINISHED
2019-01-08 20:16:26,635 INFO org.apache.hadoop.yarn.server.resourcemanager.rmcontainer.RMContainerImpl: container_1546970280036_0001_01_000014 Container Transitioned from ACQUIRED to KILLED
2019-01-08 20:16:26,635 INFO org.apache.hadoop.yarn.server.resourcemanager.RMAuditLogger: USER=hadoop2	OPERATION=AM Released Container	TARGET=SchedulerApp	RESULT=SUCCESS	APPID=application_1546970280036_0001	CONTAINERID=container_1546970280036_0001_01_000014	RESOURCE=<memory:512, vCores:1>
2019-01-08 20:16:26,635 INFO org.apache.hadoop.yarn.server.resourcemanager.scheduler.AppSchedulingInfo: Application application_1546970280036_0001 requests cleared
2019-01-08 20:16:26,636 INFO org.apache.hadoop.yarn.server.resourcemanager.scheduler.capacity.LeafQueue: Application removed - appId: application_1546970280036_0001 user: hadoop2 queue: default #user-pending-applications: 0 #user-active-applications: 1 #queue-pending-applications: 0 #queue-active-applications: 1
2019-01-08 20:16:26,636 INFO org.apache.hadoop.yarn.server.resourcemanager.scheduler.capacity.ParentQueue: Application removed - appId: application_1546970280036_0001 user: hadoop2 leaf-queue of parent: root #applications: 1
2019-01-08 20:16:26,637 INFO org.apache.hadoop.yarn.server.resourcemanager.amlauncher.AMLauncher: Cleaning master appattempt_1546970280036_0001_000001
2019-01-08 20:16:26,639 INFO org.apache.hadoop.yarn.server.resourcemanager.RMAuditLogger: USER=hadoop2	OPERATION=Application Finished - Succeeded	TARGET=RMAppManager	RESULT=SUCCESS	APPID=application_1546970280036_0001
2019-01-08 20:16:26,687 INFO org.apache.hadoop.yarn.server.resourcemanager.RMAppManager$ApplicationSummary: appId=application_1546970280036_0001,name=input_105_104-000,user=hadoop2,queue=default,state=FINISHED,trackingUrl=http://master:8088/proxy/application_1546970280036_0001/,appMasterHost=razoldslave2,submitTime=1546971306012,startTime=1546971306150,finishTime=1546971380170,finalStatus=SUCCEEDED,memorySeconds=345478,vcoreSeconds=666,preemptedMemorySeconds=0,preemptedVcoreSeconds=0,preemptedAMContainers=0,preemptedNonAMContainers=0,preemptedResources=<memory:0\, vCores:0>,applicationType=MAPREDUCE
2019-01-08 20:16:26,688 INFO org.apache.hadoop.yarn.server.resourcemanager.rmapp.attempt.RMAppAttemptImpl: appattempt_1546970280036_0002_000001 State change from ALLOCATED_SAVING to ALLOCATED on event = ATTEMPT_NEW_SAVED
2019-01-08 20:16:26,689 INFO org.apache.hadoop.yarn.server.resourcemanager.amlauncher.AMLauncher: Launching masterappattempt_1546970280036_0002_000001
2019-01-08 20:16:26,692 INFO org.apache.hadoop.yarn.server.resourcemanager.amlauncher.AMLauncher: Setting up container Container: [ContainerId: container_1546970280036_0002_01_000001, AllocationRequestId: 0, Version: 0, NodeId: razoldslave2:40557, NodeHttpAddress: razoldslave2:8042, Resource: <memory:512, vCores:1>, Priority: 0, Token: Token { kind: ContainerToken, service: 132.72.109.41:40557 }, ExecutionType: GUARANTEED, ] for AM appattempt_1546970280036_0002_000001
2019-01-08 20:16:26,692 INFO org.apache.hadoop.yarn.server.resourcemanager.security.AMRMTokenSecretManager: Create AMRMToken for ApplicationAttempt: appattempt_1546970280036_0002_000001
2019-01-08 20:16:26,692 INFO org.apache.hadoop.yarn.server.resourcemanager.security.AMRMTokenSecretManager: Creating password for appattempt_1546970280036_0002_000001
2019-01-08 20:16:26,708 INFO org.apache.hadoop.yarn.server.resourcemanager.amlauncher.AMLauncher: Done launching container Container: [ContainerId: container_1546970280036_0002_01_000001, AllocationRequestId: 0, Version: 0, NodeId: razoldslave2:40557, NodeHttpAddress: razoldslave2:8042, Resource: <memory:512, vCores:1>, Priority: 0, Token: Token { kind: ContainerToken, service: 132.72.109.41:40557 }, ExecutionType: GUARANTEED, ] for AM appattempt_1546970280036_0002_000001
2019-01-08 20:16:26,709 INFO org.apache.hadoop.yarn.server.resourcemanager.rmapp.attempt.RMAppAttemptImpl: appattempt_1546970280036_0002_000001 State change from ALLOCATED to LAUNCHED on event = LAUNCHED
2019-01-08 20:16:27,590 INFO org.apache.hadoop.yarn.server.resourcemanager.rmcontainer.RMContainerImpl: container_1546970280036_0002_01_000001 Container Transitioned from ACQUIRED to RUNNING
2019-01-08 20:16:33,706 INFO SecurityLogger.org.apache.hadoop.ipc.Server: Auth successful for appattempt_1546970280036_0002_000001 (auth:SIMPLE)
2019-01-08 20:16:33,712 INFO org.apache.hadoop.yarn.server.resourcemanager.DefaultAMSProcessor: AM registration appattempt_1546970280036_0002_000001
2019-01-08 20:16:33,712 INFO org.apache.hadoop.yarn.server.resourcemanager.rmapp.attempt.RMAppAttemptImpl: appattempt_1546970280036_0002_000001 State change from LAUNCHED to RUNNING on event = REGISTERED
2019-01-08 20:16:33,712 INFO org.apache.hadoop.yarn.server.resourcemanager.RMAuditLogger: USER=hadoop2	IP=132.72.109.41	OPERATION=Register App Master	TARGET=ApplicationMasterService	RESULT=SUCCESS	APPID=application_1546970280036_0002	APPATTEMPTID=appattempt_1546970280036_0002_000001
2019-01-08 20:16:33,713 INFO org.apache.hadoop.yarn.server.resourcemanager.rmapp.RMAppImpl: application_1546970280036_0002 State change from ACCEPTED to RUNNING on event = ATTEMPT_REGISTERED
2019-01-08 20:16:34,882 INFO org.apache.hadoop.yarn.server.resourcemanager.scheduler.capacity.allocator.AbstractContainerAllocator: assignedContainer application attempt=appattempt_1546970280036_0002_000001 container=null queue=org.apache.hadoop.yarn.server.resourcemanager.scheduler.capacity.allocator.RegularContainerAllocator@14bd88be clusterResource=<memory:9072, vCores:4> type=NODE_LOCAL requestedPartition=
2019-01-08 20:16:34,882 INFO org.apache.hadoop.yarn.server.resourcemanager.scheduler.capacity.ParentQueue: assignedContainer queue=root usedCapacity=0.056437388 absoluteUsedCapacity=0.056437388 used=<memory:512, vCores:1> cluster=<memory:9072, vCores:4>
2019-01-08 20:16:34,882 INFO org.apache.hadoop.yarn.server.resourcemanager.rmcontainer.RMContainerImpl: container_1546970280036_0002_01_000002 Container Transitioned from NEW to ALLOCATED
2019-01-08 20:16:34,882 INFO org.apache.hadoop.yarn.server.resourcemanager.RMAuditLogger: USER=hadoop2	OPERATION=AM Allocated Container	TARGET=SchedulerApp	RESULT=SUCCESS	APPID=application_1546970280036_0002	CONTAINERID=container_1546970280036_0002_01_000002	RESOURCE=<memory:512, vCores:1>
2019-01-08 20:16:34,883 INFO org.apache.hadoop.yarn.server.resourcemanager.scheduler.capacity.ParentQueue: assignedContainer queue=root usedCapacity=0.112874776 absoluteUsedCapacity=0.112874776 used=<memory:1024, vCores:2> cluster=<memory:9072, vCores:4>
2019-01-08 20:16:34,883 INFO org.apache.hadoop.yarn.server.resourcemanager.scheduler.capacity.CapacityScheduler: Allocation proposal accepted
2019-01-08 20:16:35,810 INFO org.apache.hadoop.yarn.server.resourcemanager.security.NMTokenSecretManagerInRM: Sending NMToken for nodeId : master:39349 for container : container_1546970280036_0002_01_000002
2019-01-08 20:16:35,814 INFO org.apache.hadoop.yarn.server.resourcemanager.rmcontainer.RMContainerImpl: container_1546970280036_0002_01_000002 Container Transitioned from ALLOCATED to ACQUIRED
2019-01-08 20:16:35,882 INFO org.apache.hadoop.yarn.server.resourcemanager.scheduler.capacity.allocator.AbstractContainerAllocator: assignedContainer application attempt=appattempt_1546970280036_0002_000001 container=null queue=org.apache.hadoop.yarn.server.resourcemanager.scheduler.capacity.allocator.RegularContainerAllocator@14bd88be clusterResource=<memory:9072, vCores:4> type=OFF_SWITCH requestedPartition=
2019-01-08 20:16:35,882 INFO org.apache.hadoop.yarn.server.resourcemanager.scheduler.capacity.ParentQueue: assignedContainer queue=root usedCapacity=0.112874776 absoluteUsedCapacity=0.112874776 used=<memory:1024, vCores:2> cluster=<memory:9072, vCores:4>
2019-01-08 20:16:35,882 INFO org.apache.hadoop.yarn.server.resourcemanager.rmcontainer.RMContainerImpl: container_1546970280036_0002_01_000003 Container Transitioned from NEW to ALLOCATED
2019-01-08 20:16:35,882 INFO org.apache.hadoop.yarn.server.resourcemanager.RMAuditLogger: USER=hadoop2	OPERATION=AM Allocated Container	TARGET=SchedulerApp	RESULT=SUCCESS	APPID=application_1546970280036_0002	CONTAINERID=container_1546970280036_0002_01_000003	RESOURCE=<memory:512, vCores:1>
2019-01-08 20:16:35,883 INFO org.apache.hadoop.yarn.server.resourcemanager.scheduler.capacity.ParentQueue: assignedContainer queue=root usedCapacity=0.16931216 absoluteUsedCapacity=0.16931216 used=<memory:1536, vCores:3> cluster=<memory:9072, vCores:4>
2019-01-08 20:16:35,883 INFO org.apache.hadoop.yarn.server.resourcemanager.scheduler.capacity.CapacityScheduler: Allocation proposal accepted
2019-01-08 20:16:36,615 INFO org.apache.hadoop.yarn.server.resourcemanager.scheduler.capacity.allocator.AbstractContainerAllocator: assignedContainer application attempt=appattempt_1546970280036_0002_000001 container=null queue=org.apache.hadoop.yarn.server.resourcemanager.scheduler.capacity.allocator.RegularContainerAllocator@14bd88be clusterResource=<memory:9072, vCores:4> type=OFF_SWITCH requestedPartition=
2019-01-08 20:16:36,616 INFO org.apache.hadoop.yarn.server.resourcemanager.scheduler.capacity.ParentQueue: assignedContainer queue=root usedCapacity=0.16931216 absoluteUsedCapacity=0.16931216 used=<memory:1536, vCores:3> cluster=<memory:9072, vCores:4>
2019-01-08 20:16:36,616 INFO org.apache.hadoop.yarn.server.resourcemanager.rmcontainer.RMContainerImpl: container_1546970280036_0002_01_000004 Container Transitioned from NEW to ALLOCATED
2019-01-08 20:16:36,616 INFO org.apache.hadoop.yarn.server.resourcemanager.RMAuditLogger: USER=hadoop2	OPERATION=AM Allocated Container	TARGET=SchedulerApp	RESULT=SUCCESS	APPID=application_1546970280036_0002	CONTAINERID=container_1546970280036_0002_01_000004	RESOURCE=<memory:512, vCores:1>
2019-01-08 20:16:36,616 INFO org.apache.hadoop.yarn.server.resourcemanager.scheduler.capacity.ParentQueue: assignedContainer queue=root usedCapacity=0.22574955 absoluteUsedCapacity=0.22574955 used=<memory:2048, vCores:4> cluster=<memory:9072, vCores:4>
2019-01-08 20:16:36,616 INFO org.apache.hadoop.yarn.server.resourcemanager.scheduler.capacity.CapacityScheduler: Allocation proposal accepted
2019-01-08 20:16:36,831 INFO org.apache.hadoop.yarn.server.resourcemanager.scheduler.AppSchedulingInfo: checking for deactivate of application :application_1546970280036_0002
2019-01-08 20:16:36,834 INFO org.apache.hadoop.yarn.server.resourcemanager.rmcontainer.RMContainerImpl: container_1546970280036_0002_01_000003 Container Transitioned from ALLOCATED to ACQUIRED
2019-01-08 20:16:36,835 INFO org.apache.hadoop.yarn.server.resourcemanager.security.NMTokenSecretManagerInRM: Sending NMToken for nodeId : razoldslave2:40557 for container : container_1546970280036_0002_01_000004
2019-01-08 20:16:36,839 INFO org.apache.hadoop.yarn.server.resourcemanager.rmcontainer.RMContainerImpl: container_1546970280036_0002_01_000004 Container Transitioned from ALLOCATED to ACQUIRED
2019-01-08 20:16:36,884 INFO org.apache.hadoop.yarn.server.resourcemanager.rmcontainer.RMContainerImpl: container_1546970280036_0002_01_000002 Container Transitioned from ACQUIRED to RUNNING
2019-01-08 20:16:36,884 INFO org.apache.hadoop.yarn.server.resourcemanager.scheduler.capacity.allocator.AbstractContainerAllocator: assignedContainer application attempt=appattempt_1546970280036_0002_000001 container=null queue=org.apache.hadoop.yarn.server.resourcemanager.scheduler.capacity.allocator.RegularContainerAllocator@14bd88be clusterResource=<memory:9072, vCores:4> type=OFF_SWITCH requestedPartition=
2019-01-08 20:16:36,884 INFO org.apache.hadoop.yarn.server.resourcemanager.scheduler.capacity.ParentQueue: assignedContainer queue=root usedCapacity=0.22574955 absoluteUsedCapacity=0.22574955 used=<memory:2048, vCores:4> cluster=<memory:9072, vCores:4>
2019-01-08 20:16:36,884 INFO org.apache.hadoop.yarn.server.resourcemanager.rmcontainer.RMContainerImpl: container_1546970280036_0002_01_000005 Container Transitioned from NEW to ALLOCATED
2019-01-08 20:16:36,884 INFO org.apache.hadoop.yarn.server.resourcemanager.RMAuditLogger: USER=hadoop2	OPERATION=AM Allocated Container	TARGET=SchedulerApp	RESULT=SUCCESS	APPID=application_1546970280036_0002	CONTAINERID=container_1546970280036_0002_01_000005	RESOURCE=<memory:512, vCores:1>
2019-01-08 20:16:36,885 INFO org.apache.hadoop.yarn.server.resourcemanager.scheduler.capacity.ParentQueue: assignedContainer queue=root usedCapacity=0.28218696 absoluteUsedCapacity=0.28218696 used=<memory:2560, vCores:5> cluster=<memory:9072, vCores:4>
2019-01-08 20:16:36,885 INFO org.apache.hadoop.yarn.server.resourcemanager.scheduler.capacity.CapacityScheduler: Allocation proposal accepted
2019-01-08 20:16:37,619 INFO org.apache.hadoop.yarn.server.resourcemanager.rmcontainer.RMContainerImpl: container_1546970280036_0002_01_000004 Container Transitioned from ACQUIRED to RUNNING
2019-01-08 20:16:37,619 INFO org.apache.hadoop.yarn.server.resourcemanager.scheduler.capacity.allocator.AbstractContainerAllocator: assignedContainer application attempt=appattempt_1546970280036_0002_000001 container=null queue=org.apache.hadoop.yarn.server.resourcemanager.scheduler.capacity.allocator.RegularContainerAllocator@14bd88be clusterResource=<memory:9072, vCores:4> type=OFF_SWITCH requestedPartition=
2019-01-08 20:16:37,620 INFO org.apache.hadoop.yarn.server.resourcemanager.scheduler.capacity.ParentQueue: assignedContainer queue=root usedCapacity=0.28218696 absoluteUsedCapacity=0.28218696 used=<memory:2560, vCores:5> cluster=<memory:9072, vCores:4>
2019-01-08 20:16:37,620 INFO org.apache.hadoop.yarn.server.resourcemanager.rmcontainer.RMContainerImpl: container_1546970280036_0002_01_000006 Container Transitioned from NEW to ALLOCATED
2019-01-08 20:16:37,620 INFO org.apache.hadoop.yarn.server.resourcemanager.RMAuditLogger: USER=hadoop2	OPERATION=AM Allocated Container	TARGET=SchedulerApp	RESULT=SUCCESS	APPID=application_1546970280036_0002	CONTAINERID=container_1546970280036_0002_01_000006	RESOURCE=<memory:512, vCores:1>
2019-01-08 20:16:37,620 INFO org.apache.hadoop.yarn.server.resourcemanager.scheduler.capacity.ParentQueue: assignedContainer queue=root usedCapacity=0.33862433 absoluteUsedCapacity=0.33862433 used=<memory:3072, vCores:6> cluster=<memory:9072, vCores:4>
2019-01-08 20:16:37,620 INFO org.apache.hadoop.yarn.server.resourcemanager.scheduler.capacity.CapacityScheduler: Allocation proposal accepted
2019-01-08 20:16:37,848 INFO org.apache.hadoop.yarn.server.resourcemanager.rmcontainer.RMContainerImpl: container_1546970280036_0002_01_000005 Container Transitioned from ALLOCATED to ACQUIRED
2019-01-08 20:16:37,848 INFO org.apache.hadoop.yarn.server.resourcemanager.rmcontainer.RMContainerImpl: container_1546970280036_0002_01_000006 Container Transitioned from ALLOCATED to ACQUIRED
2019-01-08 20:16:37,889 INFO org.apache.hadoop.yarn.server.resourcemanager.rmcontainer.RMContainerImpl: container_1546970280036_0002_01_000003 Container Transitioned from ACQUIRED to RUNNING
2019-01-08 20:16:37,889 INFO org.apache.hadoop.yarn.server.resourcemanager.scheduler.capacity.allocator.AbstractContainerAllocator: assignedContainer application attempt=appattempt_1546970280036_0002_000001 container=null queue=org.apache.hadoop.yarn.server.resourcemanager.scheduler.capacity.allocator.RegularContainerAllocator@14bd88be clusterResource=<memory:9072, vCores:4> type=OFF_SWITCH requestedPartition=
2019-01-08 20:16:37,890 INFO org.apache.hadoop.yarn.server.resourcemanager.scheduler.capacity.ParentQueue: assignedContainer queue=root usedCapacity=0.33862433 absoluteUsedCapacity=0.33862433 used=<memory:3072, vCores:6> cluster=<memory:9072, vCores:4>
2019-01-08 20:16:37,890 INFO org.apache.hadoop.yarn.server.resourcemanager.rmcontainer.RMContainerImpl: container_1546970280036_0002_01_000007 Container Transitioned from NEW to ALLOCATED
2019-01-08 20:16:37,890 INFO org.apache.hadoop.yarn.server.resourcemanager.RMAuditLogger: USER=hadoop2	OPERATION=AM Allocated Container	TARGET=SchedulerApp	RESULT=SUCCESS	APPID=application_1546970280036_0002	CONTAINERID=container_1546970280036_0002_01_000007	RESOURCE=<memory:512, vCores:1>
2019-01-08 20:16:37,890 INFO org.apache.hadoop.yarn.server.resourcemanager.scheduler.capacity.ParentQueue: assignedContainer queue=root usedCapacity=0.39506173 absoluteUsedCapacity=0.39506173 used=<memory:3584, vCores:7> cluster=<memory:9072, vCores:4>
2019-01-08 20:16:37,890 INFO org.apache.hadoop.yarn.server.resourcemanager.scheduler.capacity.CapacityScheduler: Allocation proposal accepted
2019-01-08 20:16:38,621 INFO org.apache.hadoop.yarn.server.resourcemanager.rmcontainer.RMContainerImpl: container_1546970280036_0002_01_000006 Container Transitioned from ACQUIRED to RUNNING
2019-01-08 20:16:38,622 INFO org.apache.hadoop.yarn.server.resourcemanager.scheduler.capacity.allocator.AbstractContainerAllocator: assignedContainer application attempt=appattempt_1546970280036_0002_000001 container=null queue=org.apache.hadoop.yarn.server.resourcemanager.scheduler.capacity.allocator.RegularContainerAllocator@14bd88be clusterResource=<memory:9072, vCores:4> type=OFF_SWITCH requestedPartition=
2019-01-08 20:16:38,622 INFO org.apache.hadoop.yarn.server.resourcemanager.scheduler.capacity.ParentQueue: assignedContainer queue=root usedCapacity=0.39506173 absoluteUsedCapacity=0.39506173 used=<memory:3584, vCores:7> cluster=<memory:9072, vCores:4>
2019-01-08 20:16:38,622 INFO org.apache.hadoop.yarn.server.resourcemanager.rmcontainer.RMContainerImpl: container_1546970280036_0002_01_000008 Container Transitioned from NEW to ALLOCATED
2019-01-08 20:16:38,622 INFO org.apache.hadoop.yarn.server.resourcemanager.RMAuditLogger: USER=hadoop2	OPERATION=AM Allocated Container	TARGET=SchedulerApp	RESULT=SUCCESS	APPID=application_1546970280036_0002	CONTAINERID=container_1546970280036_0002_01_000008	RESOURCE=<memory:512, vCores:1>
2019-01-08 20:16:38,622 INFO org.apache.hadoop.yarn.server.resourcemanager.scheduler.capacity.ParentQueue: assignedContainer queue=root usedCapacity=0.4514991 absoluteUsedCapacity=0.4514991 used=<memory:4096, vCores:8> cluster=<memory:9072, vCores:4>
2019-01-08 20:16:38,622 INFO org.apache.hadoop.yarn.server.resourcemanager.scheduler.capacity.CapacityScheduler: Allocation proposal accepted
2019-01-08 20:16:38,860 INFO org.apache.hadoop.yarn.server.resourcemanager.rmcontainer.RMContainerImpl: container_1546970280036_0002_01_000007 Container Transitioned from ALLOCATED to ACQUIRED
2019-01-08 20:16:38,861 INFO org.apache.hadoop.yarn.server.resourcemanager.rmcontainer.RMContainerImpl: container_1546970280036_0002_01_000008 Container Transitioned from ALLOCATED to ACQUIRED
2019-01-08 20:16:38,895 INFO org.apache.hadoop.yarn.server.resourcemanager.rmcontainer.RMContainerImpl: container_1546970280036_0002_01_000005 Container Transitioned from ACQUIRED to RUNNING
2019-01-08 20:16:38,903 INFO org.apache.hadoop.yarn.server.resourcemanager.scheduler.capacity.allocator.AbstractContainerAllocator: assignedContainer application attempt=appattempt_1546970280036_0002_000001 container=null queue=org.apache.hadoop.yarn.server.resourcemanager.scheduler.capacity.allocator.RegularContainerAllocator@14bd88be clusterResource=<memory:9072, vCores:4> type=OFF_SWITCH requestedPartition=
2019-01-08 20:16:38,904 INFO org.apache.hadoop.yarn.server.resourcemanager.scheduler.capacity.ParentQueue: assignedContainer queue=root usedCapacity=0.4514991 absoluteUsedCapacity=0.4514991 used=<memory:4096, vCores:8> cluster=<memory:9072, vCores:4>
2019-01-08 20:16:38,904 INFO org.apache.hadoop.yarn.server.resourcemanager.rmcontainer.RMContainerImpl: container_1546970280036_0002_01_000009 Container Transitioned from NEW to ALLOCATED
2019-01-08 20:16:38,904 INFO org.apache.hadoop.yarn.server.resourcemanager.RMAuditLogger: USER=hadoop2	OPERATION=AM Allocated Container	TARGET=SchedulerApp	RESULT=SUCCESS	APPID=application_1546970280036_0002	CONTAINERID=container_1546970280036_0002_01_000009	RESOURCE=<memory:512, vCores:1>
2019-01-08 20:16:38,904 INFO org.apache.hadoop.yarn.server.resourcemanager.scheduler.capacity.ParentQueue: assignedContainer queue=root usedCapacity=0.50793654 absoluteUsedCapacity=0.50793654 used=<memory:4608, vCores:9> cluster=<memory:9072, vCores:4>
2019-01-08 20:16:38,904 INFO org.apache.hadoop.yarn.server.resourcemanager.scheduler.capacity.CapacityScheduler: Allocation proposal accepted
2019-01-08 20:16:39,623 INFO org.apache.hadoop.yarn.server.resourcemanager.rmcontainer.RMContainerImpl: container_1546970280036_0002_01_000008 Container Transitioned from ACQUIRED to RUNNING
2019-01-08 20:16:39,624 INFO org.apache.hadoop.yarn.server.resourcemanager.scheduler.capacity.allocator.AbstractContainerAllocator: assignedContainer application attempt=appattempt_1546970280036_0002_000001 container=null queue=org.apache.hadoop.yarn.server.resourcemanager.scheduler.capacity.allocator.RegularContainerAllocator@14bd88be clusterResource=<memory:9072, vCores:4> type=OFF_SWITCH requestedPartition=
2019-01-08 20:16:39,624 INFO org.apache.hadoop.yarn.server.resourcemanager.scheduler.capacity.ParentQueue: assignedContainer queue=root usedCapacity=0.50793654 absoluteUsedCapacity=0.50793654 used=<memory:4608, vCores:9> cluster=<memory:9072, vCores:4>
2019-01-08 20:16:39,624 INFO org.apache.hadoop.yarn.server.resourcemanager.rmcontainer.RMContainerImpl: container_1546970280036_0002_01_000010 Container Transitioned from NEW to ALLOCATED
2019-01-08 20:16:39,624 INFO org.apache.hadoop.yarn.server.resourcemanager.RMAuditLogger: USER=hadoop2	OPERATION=AM Allocated Container	TARGET=SchedulerApp	RESULT=SUCCESS	APPID=application_1546970280036_0002	CONTAINERID=container_1546970280036_0002_01_000010	RESOURCE=<memory:512, vCores:1>
2019-01-08 20:16:39,624 INFO org.apache.hadoop.yarn.server.resourcemanager.scheduler.capacity.ParentQueue: assignedContainer queue=root usedCapacity=0.5643739 absoluteUsedCapacity=0.5643739 used=<memory:5120, vCores:10> cluster=<memory:9072, vCores:4>
2019-01-08 20:16:39,624 INFO org.apache.hadoop.yarn.server.resourcemanager.scheduler.capacity.CapacityScheduler: Allocation proposal accepted
2019-01-08 20:16:39,867 INFO org.apache.hadoop.yarn.server.resourcemanager.rmcontainer.RMContainerImpl: container_1546970280036_0002_01_000009 Container Transitioned from ALLOCATED to ACQUIRED
2019-01-08 20:16:39,868 INFO org.apache.hadoop.yarn.server.resourcemanager.rmcontainer.RMContainerImpl: container_1546970280036_0002_01_000010 Container Transitioned from ALLOCATED to ACQUIRED
2019-01-08 20:16:39,901 INFO org.apache.hadoop.yarn.server.resourcemanager.rmcontainer.RMContainerImpl: container_1546970280036_0002_01_000007 Container Transitioned from ACQUIRED to RUNNING
2019-01-08 20:16:39,901 INFO org.apache.hadoop.yarn.server.resourcemanager.scheduler.capacity.allocator.AbstractContainerAllocator: assignedContainer application attempt=appattempt_1546970280036_0002_000001 container=null queue=org.apache.hadoop.yarn.server.resourcemanager.scheduler.capacity.allocator.RegularContainerAllocator@14bd88be clusterResource=<memory:9072, vCores:4> type=OFF_SWITCH requestedPartition=
2019-01-08 20:16:39,901 INFO org.apache.hadoop.yarn.server.resourcemanager.scheduler.capacity.ParentQueue: assignedContainer queue=root usedCapacity=0.5643739 absoluteUsedCapacity=0.5643739 used=<memory:5120, vCores:10> cluster=<memory:9072, vCores:4>
2019-01-08 20:16:39,901 INFO org.apache.hadoop.yarn.server.resourcemanager.rmcontainer.RMContainerImpl: container_1546970280036_0002_01_000011 Container Transitioned from NEW to ALLOCATED
2019-01-08 20:16:39,902 INFO org.apache.hadoop.yarn.server.resourcemanager.RMAuditLogger: USER=hadoop2	OPERATION=AM Allocated Container	TARGET=SchedulerApp	RESULT=SUCCESS	APPID=application_1546970280036_0002	CONTAINERID=container_1546970280036_0002_01_000011	RESOURCE=<memory:512, vCores:1>
2019-01-08 20:16:39,902 INFO org.apache.hadoop.yarn.server.resourcemanager.scheduler.capacity.ParentQueue: assignedContainer queue=root usedCapacity=0.6208113 absoluteUsedCapacity=0.6208113 used=<memory:5632, vCores:11> cluster=<memory:9072, vCores:4>
2019-01-08 20:16:39,902 INFO org.apache.hadoop.yarn.server.resourcemanager.scheduler.capacity.CapacityScheduler: Allocation proposal accepted
2019-01-08 20:16:40,626 INFO org.apache.hadoop.yarn.server.resourcemanager.rmcontainer.RMContainerImpl: container_1546970280036_0002_01_000010 Container Transitioned from ACQUIRED to RUNNING
2019-01-08 20:16:40,626 INFO org.apache.hadoop.yarn.server.resourcemanager.scheduler.capacity.allocator.AbstractContainerAllocator: assignedContainer application attempt=appattempt_1546970280036_0002_000001 container=null queue=org.apache.hadoop.yarn.server.resourcemanager.scheduler.capacity.allocator.RegularContainerAllocator@14bd88be clusterResource=<memory:9072, vCores:4> type=OFF_SWITCH requestedPartition=
2019-01-08 20:16:40,626 INFO org.apache.hadoop.yarn.server.resourcemanager.scheduler.capacity.ParentQueue: assignedContainer queue=root usedCapacity=0.6208113 absoluteUsedCapacity=0.6208113 used=<memory:5632, vCores:11> cluster=<memory:9072, vCores:4>
2019-01-08 20:16:40,626 INFO org.apache.hadoop.yarn.server.resourcemanager.rmcontainer.RMContainerImpl: container_1546970280036_0002_01_000012 Container Transitioned from NEW to ALLOCATED
2019-01-08 20:16:40,626 INFO org.apache.hadoop.yarn.server.resourcemanager.RMAuditLogger: USER=hadoop2	OPERATION=AM Allocated Container	TARGET=SchedulerApp	RESULT=SUCCESS	APPID=application_1546970280036_0002	CONTAINERID=container_1546970280036_0002_01_000012	RESOURCE=<memory:512, vCores:1>
2019-01-08 20:16:40,627 INFO org.apache.hadoop.yarn.server.resourcemanager.scheduler.capacity.ParentQueue: assignedContainer queue=root usedCapacity=0.67724866 absoluteUsedCapacity=0.67724866 used=<memory:6144, vCores:12> cluster=<memory:9072, vCores:4>
2019-01-08 20:16:40,627 INFO org.apache.hadoop.yarn.server.resourcemanager.scheduler.capacity.CapacityScheduler: Allocation proposal accepted
2019-01-08 20:16:40,874 INFO org.apache.hadoop.yarn.server.resourcemanager.rmcontainer.RMContainerImpl: container_1546970280036_0002_01_000011 Container Transitioned from ALLOCATED to ACQUIRED
2019-01-08 20:16:40,874 INFO org.apache.hadoop.yarn.server.resourcemanager.rmcontainer.RMContainerImpl: container_1546970280036_0002_01_000012 Container Transitioned from ALLOCATED to ACQUIRED
2019-01-08 20:16:40,902 INFO org.apache.hadoop.yarn.server.resourcemanager.rmcontainer.RMContainerImpl: container_1546970280036_0002_01_000009 Container Transitioned from ACQUIRED to RUNNING
2019-01-08 20:16:40,903 INFO org.apache.hadoop.yarn.server.resourcemanager.scheduler.capacity.allocator.AbstractContainerAllocator: assignedContainer application attempt=appattempt_1546970280036_0002_000001 container=null queue=org.apache.hadoop.yarn.server.resourcemanager.scheduler.capacity.allocator.RegularContainerAllocator@14bd88be clusterResource=<memory:9072, vCores:4> type=OFF_SWITCH requestedPartition=
2019-01-08 20:16:40,903 INFO org.apache.hadoop.yarn.server.resourcemanager.scheduler.capacity.ParentQueue: assignedContainer queue=root usedCapacity=0.67724866 absoluteUsedCapacity=0.67724866 used=<memory:6144, vCores:12> cluster=<memory:9072, vCores:4>
2019-01-08 20:16:40,903 INFO org.apache.hadoop.yarn.server.resourcemanager.rmcontainer.RMContainerImpl: container_1546970280036_0002_01_000013 Container Transitioned from NEW to ALLOCATED
2019-01-08 20:16:40,903 INFO org.apache.hadoop.yarn.server.resourcemanager.RMAuditLogger: USER=hadoop2	OPERATION=AM Allocated Container	TARGET=SchedulerApp	RESULT=SUCCESS	APPID=application_1546970280036_0002	CONTAINERID=container_1546970280036_0002_01_000013	RESOURCE=<memory:512, vCores:1>
2019-01-08 20:16:40,903 INFO org.apache.hadoop.yarn.server.resourcemanager.scheduler.capacity.ParentQueue: assignedContainer queue=root usedCapacity=0.7336861 absoluteUsedCapacity=0.7336861 used=<memory:6656, vCores:13> cluster=<memory:9072, vCores:4>
2019-01-08 20:16:40,903 INFO org.apache.hadoop.yarn.server.resourcemanager.scheduler.capacity.CapacityScheduler: Allocation proposal accepted
2019-01-08 20:16:41,904 INFO org.apache.hadoop.yarn.server.resourcemanager.rmcontainer.RMContainerImpl: container_1546970280036_0002_01_000011 Container Transitioned from ACQUIRED to RUNNING
2019-01-08 20:16:42,462 INFO org.apache.hadoop.yarn.server.resourcemanager.rmcontainer.RMContainerImpl: container_1546970280036_0002_01_000012 Container Transitioned from ACQUIRED to RELEASED
2019-01-08 20:16:42,462 INFO org.apache.hadoop.yarn.server.resourcemanager.RMAuditLogger: USER=hadoop2	IP=132.72.109.41	OPERATION=AM Released Container	TARGET=SchedulerApp	RESULT=SUCCESS	APPID=application_1546970280036_0002	CONTAINERID=container_1546970280036_0002_01_000012	RESOURCE=<memory:512, vCores:1>
2019-01-08 20:16:42,462 INFO org.apache.hadoop.yarn.server.resourcemanager.scheduler.AppSchedulingInfo: checking for deactivate of application :application_1546970280036_0002
2019-01-08 20:16:42,464 INFO org.apache.hadoop.yarn.server.resourcemanager.rmcontainer.RMContainerImpl: container_1546970280036_0002_01_000013 Container Transitioned from ALLOCATED to ACQUIRED
2019-01-08 20:16:43,475 INFO org.apache.hadoop.yarn.server.resourcemanager.rmcontainer.RMContainerImpl: container_1546970280036_0002_01_000013 Container Transitioned from ACQUIRED to RELEASED
2019-01-08 20:16:43,475 INFO org.apache.hadoop.yarn.server.resourcemanager.RMAuditLogger: USER=hadoop2	IP=132.72.109.41	OPERATION=AM Released Container	TARGET=SchedulerApp	RESULT=SUCCESS	APPID=application_1546970280036_0002	CONTAINERID=container_1546970280036_0002_01_000013	RESOURCE=<memory:512, vCores:1>
2019-01-08 20:17:24,409 INFO org.apache.hadoop.yarn.server.resourcemanager.rmcontainer.RMContainerImpl: container_1546970280036_0002_01_000006 Container Transitioned from RUNNING to COMPLETED
2019-01-08 20:17:24,446 INFO org.apache.hadoop.yarn.server.resourcemanager.RMAuditLogger: USER=hadoop2	OPERATION=AM Released Container	TARGET=SchedulerApp	RESULT=SUCCESS	APPID=application_1546970280036_0002	CONTAINERID=container_1546970280036_0002_01_000006	RESOURCE=<memory:512, vCores:1>
2019-01-08 20:17:24,481 INFO org.apache.hadoop.yarn.server.resourcemanager.rmcontainer.RMContainerImpl: container_1546970280036_0002_01_000004 Container Transitioned from RUNNING to COMPLETED
2019-01-08 20:17:24,481 INFO org.apache.hadoop.yarn.server.resourcemanager.RMAuditLogger: USER=hadoop2	OPERATION=AM Released Container	TARGET=SchedulerApp	RESULT=SUCCESS	APPID=application_1546970280036_0002	CONTAINERID=container_1546970280036_0002_01_000004	RESOURCE=<memory:512, vCores:1>
2019-01-08 20:17:24,886 INFO org.apache.hadoop.yarn.server.resourcemanager.rmcontainer.RMContainerImpl: container_1546970280036_0002_01_000008 Container Transitioned from RUNNING to COMPLETED
2019-01-08 20:17:24,887 INFO org.apache.hadoop.yarn.server.resourcemanager.RMAuditLogger: USER=hadoop2	OPERATION=AM Released Container	TARGET=SchedulerApp	RESULT=SUCCESS	APPID=application_1546970280036_0002	CONTAINERID=container_1546970280036_0002_01_000008	RESOURCE=<memory:512, vCores:1>
2019-01-08 20:17:24,907 INFO org.apache.hadoop.yarn.server.resourcemanager.rmcontainer.RMContainerImpl: container_1546970280036_0002_01_000010 Container Transitioned from RUNNING to COMPLETED
2019-01-08 20:17:24,907 INFO org.apache.hadoop.yarn.server.resourcemanager.RMAuditLogger: USER=hadoop2	OPERATION=AM Released Container	TARGET=SchedulerApp	RESULT=SUCCESS	APPID=application_1546970280036_0002	CONTAINERID=container_1546970280036_0002_01_000010	RESOURCE=<memory:512, vCores:1>
2019-01-08 20:17:26,097 INFO org.apache.hadoop.yarn.server.resourcemanager.scheduler.capacity.allocator.AbstractContainerAllocator: assignedContainer application attempt=appattempt_1546970280036_0002_000001 container=null queue=org.apache.hadoop.yarn.server.resourcemanager.scheduler.capacity.allocator.RegularContainerAllocator@14bd88be clusterResource=<memory:9072, vCores:4> type=OFF_SWITCH requestedPartition=
2019-01-08 20:17:26,097 INFO org.apache.hadoop.yarn.server.resourcemanager.scheduler.capacity.ParentQueue: assignedContainer queue=root usedCapacity=0.39506173 absoluteUsedCapacity=0.39506173 used=<memory:3584, vCores:7> cluster=<memory:9072, vCores:4>
2019-01-08 20:17:26,097 INFO org.apache.hadoop.yarn.server.resourcemanager.rmcontainer.RMContainerImpl: container_1546970280036_0002_01_000014 Container Transitioned from NEW to ALLOCATED
2019-01-08 20:17:26,097 INFO org.apache.hadoop.yarn.server.resourcemanager.RMAuditLogger: USER=hadoop2	OPERATION=AM Allocated Container	TARGET=SchedulerApp	RESULT=SUCCESS	APPID=application_1546970280036_0002	CONTAINERID=container_1546970280036_0002_01_000014	RESOURCE=<memory:512, vCores:1>
2019-01-08 20:17:26,098 INFO org.apache.hadoop.yarn.server.resourcemanager.scheduler.capacity.ParentQueue: assignedContainer queue=root usedCapacity=0.4514991 absoluteUsedCapacity=0.4514991 used=<memory:4096, vCores:8> cluster=<memory:9072, vCores:4>
2019-01-08 20:17:26,098 INFO org.apache.hadoop.yarn.server.resourcemanager.scheduler.capacity.CapacityScheduler: Allocation proposal accepted
2019-01-08 20:17:26,966 INFO org.apache.hadoop.yarn.server.resourcemanager.rmcontainer.RMContainerImpl: container_1546970280036_0002_01_000014 Container Transitioned from ALLOCATED to ACQUIRED
2019-01-08 20:17:27,099 INFO org.apache.hadoop.yarn.server.resourcemanager.rmcontainer.RMContainerImpl: container_1546970280036_0002_01_000014 Container Transitioned from ACQUIRED to RUNNING
2019-01-08 20:17:27,274 INFO org.apache.hadoop.yarn.server.resourcemanager.rmcontainer.RMContainerImpl: container_1546970280036_0002_01_000002 Container Transitioned from RUNNING to COMPLETED
2019-01-08 20:17:27,274 INFO org.apache.hadoop.yarn.server.resourcemanager.RMAuditLogger: USER=hadoop2	OPERATION=AM Released Container	TARGET=SchedulerApp	RESULT=SUCCESS	APPID=application_1546970280036_0002	CONTAINERID=container_1546970280036_0002_01_000002	RESOURCE=<memory:512, vCores:1>
2019-01-08 20:17:27,969 INFO org.apache.hadoop.yarn.server.resourcemanager.scheduler.AppSchedulingInfo: checking for deactivate of application :application_1546970280036_0002
2019-01-08 20:17:43,834 INFO org.apache.hadoop.yarn.server.resourcemanager.rmcontainer.RMContainerImpl: container_1546970280036_0002_01_000014 Container Transitioned from RUNNING to COMPLETED
2019-01-08 20:17:43,834 INFO org.apache.hadoop.yarn.server.resourcemanager.RMAuditLogger: USER=hadoop2	OPERATION=AM Released Container	TARGET=SchedulerApp	RESULT=SUCCESS	APPID=application_1546970280036_0002	CONTAINERID=container_1546970280036_0002_01_000014	RESOURCE=<memory:512, vCores:1>
2019-01-08 20:17:44,573 INFO org.apache.hadoop.yarn.server.resourcemanager.rmcontainer.RMContainerImpl: container_1546970280036_0002_01_000005 Container Transitioned from RUNNING to COMPLETED
2019-01-08 20:17:44,573 INFO org.apache.hadoop.yarn.server.resourcemanager.RMAuditLogger: USER=hadoop2	OPERATION=AM Released Container	TARGET=SchedulerApp	RESULT=SUCCESS	APPID=application_1546970280036_0002	CONTAINERID=container_1546970280036_0002_01_000005	RESOURCE=<memory:512, vCores:1>
2019-01-08 20:17:44,993 INFO org.apache.hadoop.yarn.server.resourcemanager.rmcontainer.RMContainerImpl: container_1546970280036_0002_01_000003 Container Transitioned from RUNNING to COMPLETED
2019-01-08 20:17:44,993 INFO org.apache.hadoop.yarn.server.resourcemanager.RMAuditLogger: USER=hadoop2	OPERATION=AM Released Container	TARGET=SchedulerApp	RESULT=SUCCESS	APPID=application_1546970280036_0002	CONTAINERID=container_1546970280036_0002_01_000003	RESOURCE=<memory:512, vCores:1>
2019-01-08 20:17:44,996 INFO org.apache.hadoop.yarn.server.resourcemanager.rmcontainer.RMContainerImpl: container_1546970280036_0002_01_000007 Container Transitioned from RUNNING to COMPLETED
2019-01-08 20:17:44,996 INFO org.apache.hadoop.yarn.server.resourcemanager.RMAuditLogger: USER=hadoop2	OPERATION=AM Released Container	TARGET=SchedulerApp	RESULT=SUCCESS	APPID=application_1546970280036_0002	CONTAINERID=container_1546970280036_0002_01_000007	RESOURCE=<memory:512, vCores:1>
2019-01-08 20:17:45,002 INFO org.apache.hadoop.yarn.server.resourcemanager.rmcontainer.RMContainerImpl: container_1546970280036_0002_01_000011 Container Transitioned from RUNNING to COMPLETED
2019-01-08 20:17:45,002 INFO org.apache.hadoop.yarn.server.resourcemanager.RMAuditLogger: USER=hadoop2	OPERATION=AM Released Container	TARGET=SchedulerApp	RESULT=SUCCESS	APPID=application_1546970280036_0002	CONTAINERID=container_1546970280036_0002_01_000011	RESOURCE=<memory:512, vCores:1>
2019-01-08 20:17:45,005 INFO org.apache.hadoop.yarn.server.resourcemanager.rmcontainer.RMContainerImpl: container_1546970280036_0002_01_000009 Container Transitioned from RUNNING to COMPLETED
2019-01-08 20:17:45,005 INFO org.apache.hadoop.yarn.server.resourcemanager.RMAuditLogger: USER=hadoop2	OPERATION=AM Released Container	TARGET=SchedulerApp	RESULT=SUCCESS	APPID=application_1546970280036_0002	CONTAINERID=container_1546970280036_0002_01_000009	RESOURCE=<memory:512, vCores:1>
2019-01-08 20:17:45,972 INFO org.apache.hadoop.yarn.server.resourcemanager.rmapp.attempt.RMAppAttemptImpl: Updating application attempt appattempt_1546970280036_0002_000001 with final state: FINISHING, and exit status: -1000
2019-01-08 20:17:45,972 INFO org.apache.hadoop.yarn.server.resourcemanager.rmapp.attempt.RMAppAttemptImpl: appattempt_1546970280036_0002_000001 State change from RUNNING to FINAL_SAVING on event = UNREGISTERED
2019-01-08 20:17:45,972 INFO org.apache.hadoop.yarn.server.resourcemanager.rmapp.RMAppImpl: Updating application application_1546970280036_0002 with final state: FINISHING
2019-01-08 20:17:45,972 INFO org.apache.hadoop.yarn.server.resourcemanager.rmapp.RMAppImpl: application_1546970280036_0002 State change from RUNNING to FINAL_SAVING on event = ATTEMPT_UNREGISTERED
2019-01-08 20:17:45,972 INFO org.apache.hadoop.yarn.server.resourcemanager.recovery.RMStateStore: Updating info for app: application_1546970280036_0002
2019-01-08 20:17:45,972 INFO org.apache.hadoop.yarn.server.resourcemanager.rmapp.attempt.RMAppAttemptImpl: appattempt_1546970280036_0002_000001 State change from FINAL_SAVING to FINISHING on event = ATTEMPT_UPDATE_SAVED
2019-01-08 20:17:45,972 INFO org.apache.hadoop.yarn.server.resourcemanager.rmapp.RMAppImpl: application_1546970280036_0002 State change from FINAL_SAVING to FINISHING on event = APP_UPDATE_SAVED
2019-01-08 20:17:46,975 INFO org.apache.hadoop.yarn.server.resourcemanager.ApplicationMasterService: application_1546970280036_0002 unregistered successfully. 
2019-01-08 20:17:52,377 INFO org.apache.hadoop.yarn.server.resourcemanager.rmcontainer.RMContainerImpl: container_1546970280036_0002_01_000001 Container Transitioned from RUNNING to COMPLETED
2019-01-08 20:17:52,377 INFO org.apache.hadoop.yarn.server.resourcemanager.ApplicationMasterService: Unregistering app attempt : appattempt_1546970280036_0002_000001
2019-01-08 20:17:52,377 INFO org.apache.hadoop.yarn.server.resourcemanager.RMAuditLogger: USER=hadoop2	OPERATION=AM Released Container	TARGET=SchedulerApp	RESULT=SUCCESS	APPID=application_1546970280036_0002	CONTAINERID=container_1546970280036_0002_01_000001	RESOURCE=<memory:512, vCores:1>
2019-01-08 20:17:52,377 INFO org.apache.hadoop.yarn.server.resourcemanager.security.AMRMTokenSecretManager: Application finished, removing password for appattempt_1546970280036_0002_000001
2019-01-08 20:17:52,377 INFO org.apache.hadoop.yarn.server.resourcemanager.rmapp.attempt.RMAppAttemptImpl: appattempt_1546970280036_0002_000001 State change from FINISHING to FINISHED on event = CONTAINER_FINISHED
2019-01-08 20:17:52,378 INFO org.apache.hadoop.yarn.server.resourcemanager.rmapp.RMAppImpl: application_1546970280036_0002 State change from FINISHING to FINISHED on event = ATTEMPT_FINISHED
2019-01-08 20:17:52,378 INFO org.apache.hadoop.yarn.server.resourcemanager.scheduler.capacity.CapacityScheduler: Application Attempt appattempt_1546970280036_0002_000001 is done. finalState=FINISHED
2019-01-08 20:17:52,378 INFO org.apache.hadoop.yarn.server.resourcemanager.scheduler.AppSchedulingInfo: Application application_1546970280036_0002 requests cleared
2019-01-08 20:17:52,378 INFO org.apache.hadoop.yarn.server.resourcemanager.RMAuditLogger: USER=hadoop2	OPERATION=Application Finished - Succeeded	TARGET=RMAppManager	RESULT=SUCCESS	APPID=application_1546970280036_0002
2019-01-08 20:17:52,378 INFO org.apache.hadoop.yarn.server.resourcemanager.scheduler.capacity.LeafQueue: Application removed - appId: application_1546970280036_0002 user: hadoop2 queue: default #user-pending-applications: 0 #user-active-applications: 0 #queue-pending-applications: 0 #queue-active-applications: 0
2019-01-08 20:17:52,378 INFO org.apache.hadoop.yarn.server.resourcemanager.scheduler.capacity.ParentQueue: Application removed - appId: application_1546970280036_0002 user: hadoop2 leaf-queue of parent: root #applications: 0
2019-01-08 20:17:52,378 INFO org.apache.hadoop.yarn.server.resourcemanager.RMAppManager$ApplicationSummary: appId=application_1546970280036_0002,name=input_105_104-000,user=hadoop2,queue=default,state=FINISHED,trackingUrl=http://master:8088/proxy/application_1546970280036_0002/,appMasterHost=razoldslave2,submitTime=1546971386405,startTime=1546971386405,finishTime=1546971465972,finalStatus=SUCCEEDED,memorySeconds=348991,vcoreSeconds=675,preemptedMemorySeconds=0,preemptedVcoreSeconds=0,preemptedAMContainers=0,preemptedNonAMContainers=0,preemptedResources=<memory:0\, vCores:0>,applicationType=MAPREDUCE
2019-01-08 20:17:52,379 INFO org.apache.hadoop.yarn.server.resourcemanager.amlauncher.AMLauncher: Cleaning master appattempt_1546970280036_0002_000001
2019-01-08 21:01:30,706 INFO org.apache.hadoop.yarn.server.resourcemanager.ClientRMService: Allocated new applicationId: 3
2019-01-08 21:01:37,937 INFO org.apache.hadoop.yarn.server.resourcemanager.scheduler.capacity.CapacityScheduler: Application 'application_1546970280036_0003' is submitted without priority hence considering default queue/cluster priority: 0
2019-01-08 21:01:37,937 INFO org.apache.hadoop.yarn.server.resourcemanager.scheduler.capacity.CapacityScheduler: Priority '0' is acceptable in queue : default for application: application_1546970280036_0003
2019-01-08 21:01:37,937 INFO org.apache.hadoop.yarn.server.resourcemanager.ClientRMService: Application with id 3 submitted by user hadoop2
2019-01-08 21:01:37,937 INFO org.apache.hadoop.yarn.server.resourcemanager.RMAuditLogger: USER=hadoop2	IP=132.72.109.20	OPERATION=Submit Application Request	TARGET=ClientRMService	RESULT=SUCCESS	APPID=application_1546970280036_0003	CALLERCONTEXT=CLI
2019-01-08 21:01:37,937 INFO org.apache.hadoop.yarn.server.resourcemanager.rmapp.RMAppImpl: Storing application with id application_1546970280036_0003
2019-01-08 21:01:37,938 INFO org.apache.hadoop.yarn.server.resourcemanager.rmapp.RMAppImpl: application_1546970280036_0003 State change from NEW to NEW_SAVING on event = START
2019-01-08 21:01:37,938 INFO org.apache.hadoop.yarn.server.resourcemanager.recovery.RMStateStore: Storing info for app: application_1546970280036_0003
2019-01-08 21:01:37,938 INFO org.apache.hadoop.yarn.server.resourcemanager.rmapp.RMAppImpl: application_1546970280036_0003 State change from NEW_SAVING to SUBMITTED on event = APP_NEW_SAVED
2019-01-08 21:01:37,938 INFO org.apache.hadoop.yarn.server.resourcemanager.scheduler.capacity.ParentQueue: Application added - appId: application_1546970280036_0003 user: hadoop2 leaf-queue of parent: root #applications: 1
2019-01-08 21:01:37,938 INFO org.apache.hadoop.yarn.server.resourcemanager.scheduler.capacity.CapacityScheduler: Accepted application application_1546970280036_0003 from user: hadoop2, in queue: default
2019-01-08 21:01:37,938 INFO org.apache.hadoop.yarn.server.resourcemanager.rmapp.RMAppImpl: application_1546970280036_0003 State change from SUBMITTED to ACCEPTED on event = APP_ACCEPTED
2019-01-08 21:01:37,938 INFO org.apache.hadoop.yarn.server.resourcemanager.ApplicationMasterService: Registering app attempt : appattempt_1546970280036_0003_000001
2019-01-08 21:01:37,938 INFO org.apache.hadoop.yarn.server.resourcemanager.rmapp.attempt.RMAppAttemptImpl: appattempt_1546970280036_0003_000001 State change from NEW to SUBMITTED on event = START
2019-01-08 21:01:37,939 INFO org.apache.hadoop.yarn.server.resourcemanager.scheduler.capacity.LeafQueue: Application application_1546970280036_0003 from user: hadoop2 activated in queue: default
2019-01-08 21:01:37,939 INFO org.apache.hadoop.yarn.server.resourcemanager.scheduler.capacity.LeafQueue: Application added - appId: application_1546970280036_0003 user: hadoop2, leaf-queue: default #user-pending-applications: 0 #user-active-applications: 1 #queue-pending-applications: 0 #queue-active-applications: 1
2019-01-08 21:01:37,939 INFO org.apache.hadoop.yarn.server.resourcemanager.scheduler.capacity.CapacityScheduler: Added Application Attempt appattempt_1546970280036_0003_000001 to scheduler from user hadoop2 in queue default
2019-01-08 21:01:37,942 INFO org.apache.hadoop.yarn.server.resourcemanager.rmapp.attempt.RMAppAttemptImpl: appattempt_1546970280036_0003_000001 State change from SUBMITTED to SCHEDULED on event = ATTEMPT_ADDED
2019-01-08 21:01:37,956 INFO org.apache.hadoop.yarn.server.resourcemanager.scheduler.capacity.allocator.AbstractContainerAllocator: assignedContainer application attempt=appattempt_1546970280036_0003_000001 container=null queue=org.apache.hadoop.yarn.server.resourcemanager.scheduler.capacity.allocator.RegularContainerAllocator@6284c523 clusterResource=<memory:9072, vCores:4> type=OFF_SWITCH requestedPartition=
2019-01-08 21:01:37,956 INFO org.apache.hadoop.yarn.server.resourcemanager.scheduler.capacity.ParentQueue: assignedContainer queue=root usedCapacity=0.0 absoluteUsedCapacity=0.0 used=<memory:0, vCores:0> cluster=<memory:9072, vCores:4>
2019-01-08 21:01:37,956 INFO org.apache.hadoop.yarn.server.resourcemanager.rmcontainer.RMContainerImpl: container_1546970280036_0003_01_000001 Container Transitioned from NEW to ALLOCATED
2019-01-08 21:01:37,956 INFO org.apache.hadoop.yarn.server.resourcemanager.RMAuditLogger: USER=hadoop2	OPERATION=AM Allocated Container	TARGET=SchedulerApp	RESULT=SUCCESS	APPID=application_1546970280036_0003	CONTAINERID=container_1546970280036_0003_01_000001	RESOURCE=<memory:512, vCores:1>
2019-01-08 21:01:37,957 INFO org.apache.hadoop.yarn.server.resourcemanager.scheduler.capacity.ParentQueue: assignedContainer queue=root usedCapacity=0.056437388 absoluteUsedCapacity=0.056437388 used=<memory:512, vCores:1> cluster=<memory:9072, vCores:4>
2019-01-08 21:01:37,957 INFO org.apache.hadoop.yarn.server.resourcemanager.scheduler.capacity.CapacityScheduler: Allocation proposal accepted
2019-01-08 21:01:37,957 INFO org.apache.hadoop.yarn.server.resourcemanager.security.NMTokenSecretManagerInRM: Sending NMToken for nodeId : razoldslave2:40557 for container : container_1546970280036_0003_01_000001
2019-01-08 21:01:37,958 INFO org.apache.hadoop.yarn.server.resourcemanager.rmcontainer.RMContainerImpl: container_1546970280036_0003_01_000001 Container Transitioned from ALLOCATED to ACQUIRED
2019-01-08 21:01:37,958 INFO org.apache.hadoop.yarn.server.resourcemanager.security.NMTokenSecretManagerInRM: Clear node set for appattempt_1546970280036_0003_000001
2019-01-08 21:01:37,958 INFO org.apache.hadoop.yarn.server.resourcemanager.rmapp.attempt.RMAppAttemptImpl: Storing attempt: AppId: application_1546970280036_0003 AttemptId: appattempt_1546970280036_0003_000001 MasterContainer: Container: [ContainerId: container_1546970280036_0003_01_000001, AllocationRequestId: 0, Version: 0, NodeId: razoldslave2:40557, NodeHttpAddress: razoldslave2:8042, Resource: <memory:512, vCores:1>, Priority: 0, Token: Token { kind: ContainerToken, service: 132.72.109.41:40557 }, ExecutionType: GUARANTEED, ]
2019-01-08 21:01:37,958 INFO org.apache.hadoop.yarn.server.resourcemanager.rmapp.attempt.RMAppAttemptImpl: appattempt_1546970280036_0003_000001 State change from SCHEDULED to ALLOCATED_SAVING on event = CONTAINER_ALLOCATED
2019-01-08 21:01:37,959 INFO org.apache.hadoop.yarn.server.resourcemanager.rmapp.attempt.RMAppAttemptImpl: appattempt_1546970280036_0003_000001 State change from ALLOCATED_SAVING to ALLOCATED on event = ATTEMPT_NEW_SAVED
2019-01-08 21:01:37,972 INFO org.apache.hadoop.yarn.server.resourcemanager.amlauncher.AMLauncher: Launching masterappattempt_1546970280036_0003_000001
2019-01-08 21:01:37,975 INFO org.apache.hadoop.yarn.server.resourcemanager.amlauncher.AMLauncher: Setting up container Container: [ContainerId: container_1546970280036_0003_01_000001, AllocationRequestId: 0, Version: 0, NodeId: razoldslave2:40557, NodeHttpAddress: razoldslave2:8042, Resource: <memory:512, vCores:1>, Priority: 0, Token: Token { kind: ContainerToken, service: 132.72.109.41:40557 }, ExecutionType: GUARANTEED, ] for AM appattempt_1546970280036_0003_000001
2019-01-08 21:01:37,975 INFO org.apache.hadoop.yarn.server.resourcemanager.security.AMRMTokenSecretManager: Create AMRMToken for ApplicationAttempt: appattempt_1546970280036_0003_000001
2019-01-08 21:01:37,975 INFO org.apache.hadoop.yarn.server.resourcemanager.security.AMRMTokenSecretManager: Creating password for appattempt_1546970280036_0003_000001
2019-01-08 21:01:38,017 INFO org.apache.hadoop.yarn.server.resourcemanager.amlauncher.AMLauncher: Done launching container Container: [ContainerId: container_1546970280036_0003_01_000001, AllocationRequestId: 0, Version: 0, NodeId: razoldslave2:40557, NodeHttpAddress: razoldslave2:8042, Resource: <memory:512, vCores:1>, Priority: 0, Token: Token { kind: ContainerToken, service: 132.72.109.41:40557 }, ExecutionType: GUARANTEED, ] for AM appattempt_1546970280036_0003_000001
2019-01-08 21:01:38,017 INFO org.apache.hadoop.yarn.server.resourcemanager.rmapp.attempt.RMAppAttemptImpl: appattempt_1546970280036_0003_000001 State change from ALLOCATED to LAUNCHED on event = LAUNCHED
2019-01-08 21:01:38,957 INFO org.apache.hadoop.yarn.server.resourcemanager.rmcontainer.RMContainerImpl: container_1546970280036_0003_01_000001 Container Transitioned from ACQUIRED to RUNNING
2019-01-08 21:01:44,631 INFO SecurityLogger.org.apache.hadoop.ipc.Server: Auth successful for appattempt_1546970280036_0003_000001 (auth:SIMPLE)
2019-01-08 21:01:44,640 INFO org.apache.hadoop.yarn.server.resourcemanager.DefaultAMSProcessor: AM registration appattempt_1546970280036_0003_000001
2019-01-08 21:01:44,640 INFO org.apache.hadoop.yarn.server.resourcemanager.RMAuditLogger: USER=hadoop2	IP=132.72.109.41	OPERATION=Register App Master	TARGET=ApplicationMasterService	RESULT=SUCCESS	APPID=application_1546970280036_0003	APPATTEMPTID=appattempt_1546970280036_0003_000001
2019-01-08 21:01:44,640 INFO org.apache.hadoop.yarn.server.resourcemanager.rmapp.attempt.RMAppAttemptImpl: appattempt_1546970280036_0003_000001 State change from LAUNCHED to RUNNING on event = REGISTERED
2019-01-08 21:01:44,640 INFO org.apache.hadoop.yarn.server.resourcemanager.rmapp.RMAppImpl: application_1546970280036_0003 State change from ACCEPTED to RUNNING on event = ATTEMPT_REGISTERED
2019-01-08 21:01:45,968 INFO org.apache.hadoop.yarn.server.resourcemanager.scheduler.capacity.allocator.AbstractContainerAllocator: assignedContainer application attempt=appattempt_1546970280036_0003_000001 container=null queue=org.apache.hadoop.yarn.server.resourcemanager.scheduler.capacity.allocator.RegularContainerAllocator@6284c523 clusterResource=<memory:9072, vCores:4> type=NODE_LOCAL requestedPartition=
2019-01-08 21:01:45,969 INFO org.apache.hadoop.yarn.server.resourcemanager.scheduler.capacity.ParentQueue: assignedContainer queue=root usedCapacity=0.056437388 absoluteUsedCapacity=0.056437388 used=<memory:512, vCores:1> cluster=<memory:9072, vCores:4>
2019-01-08 21:01:45,970 INFO org.apache.hadoop.yarn.server.resourcemanager.rmcontainer.RMContainerImpl: container_1546970280036_0003_01_000002 Container Transitioned from NEW to ALLOCATED
2019-01-08 21:01:45,970 INFO org.apache.hadoop.yarn.server.resourcemanager.RMAuditLogger: USER=hadoop2	OPERATION=AM Allocated Container	TARGET=SchedulerApp	RESULT=SUCCESS	APPID=application_1546970280036_0003	CONTAINERID=container_1546970280036_0003_01_000002	RESOURCE=<memory:512, vCores:1>
2019-01-08 21:01:45,970 INFO org.apache.hadoop.yarn.server.resourcemanager.scheduler.capacity.ParentQueue: assignedContainer queue=root usedCapacity=0.112874776 absoluteUsedCapacity=0.112874776 used=<memory:1024, vCores:2> cluster=<memory:9072, vCores:4>
2019-01-08 21:01:45,970 INFO org.apache.hadoop.yarn.server.resourcemanager.scheduler.capacity.CapacityScheduler: Allocation proposal accepted
2019-01-08 21:01:46,717 INFO org.apache.hadoop.yarn.server.resourcemanager.security.NMTokenSecretManagerInRM: Sending NMToken for nodeId : razoldslave2:40557 for container : container_1546970280036_0003_01_000002
2019-01-08 21:01:46,718 INFO org.apache.hadoop.yarn.server.resourcemanager.rmcontainer.RMContainerImpl: container_1546970280036_0003_01_000002 Container Transitioned from ALLOCATED to ACQUIRED
2019-01-08 21:01:46,969 INFO org.apache.hadoop.yarn.server.resourcemanager.rmcontainer.RMContainerImpl: container_1546970280036_0003_01_000002 Container Transitioned from ACQUIRED to RUNNING
2019-01-08 21:01:46,970 INFO org.apache.hadoop.yarn.server.resourcemanager.scheduler.capacity.allocator.AbstractContainerAllocator: assignedContainer application attempt=appattempt_1546970280036_0003_000001 container=null queue=org.apache.hadoop.yarn.server.resourcemanager.scheduler.capacity.allocator.RegularContainerAllocator@6284c523 clusterResource=<memory:9072, vCores:4> type=OFF_SWITCH requestedPartition=
2019-01-08 21:01:46,970 INFO org.apache.hadoop.yarn.server.resourcemanager.scheduler.capacity.ParentQueue: assignedContainer queue=root usedCapacity=0.112874776 absoluteUsedCapacity=0.112874776 used=<memory:1024, vCores:2> cluster=<memory:9072, vCores:4>
2019-01-08 21:01:46,970 INFO org.apache.hadoop.yarn.server.resourcemanager.rmcontainer.RMContainerImpl: container_1546970280036_0003_01_000003 Container Transitioned from NEW to ALLOCATED
2019-01-08 21:01:46,970 INFO org.apache.hadoop.yarn.server.resourcemanager.RMAuditLogger: USER=hadoop2	OPERATION=AM Allocated Container	TARGET=SchedulerApp	RESULT=SUCCESS	APPID=application_1546970280036_0003	CONTAINERID=container_1546970280036_0003_01_000003	RESOURCE=<memory:512, vCores:1>
2019-01-08 21:01:46,970 INFO org.apache.hadoop.yarn.server.resourcemanager.scheduler.capacity.ParentQueue: assignedContainer queue=root usedCapacity=0.16931216 absoluteUsedCapacity=0.16931216 used=<memory:1536, vCores:3> cluster=<memory:9072, vCores:4>
2019-01-08 21:01:46,970 INFO org.apache.hadoop.yarn.server.resourcemanager.scheduler.capacity.CapacityScheduler: Allocation proposal accepted
2019-01-08 21:01:47,122 INFO org.apache.hadoop.yarn.server.resourcemanager.scheduler.capacity.allocator.AbstractContainerAllocator: assignedContainer application attempt=appattempt_1546970280036_0003_000001 container=null queue=org.apache.hadoop.yarn.server.resourcemanager.scheduler.capacity.allocator.RegularContainerAllocator@6284c523 clusterResource=<memory:9072, vCores:4> type=OFF_SWITCH requestedPartition=
2019-01-08 21:01:47,122 INFO org.apache.hadoop.yarn.server.resourcemanager.scheduler.capacity.ParentQueue: assignedContainer queue=root usedCapacity=0.16931216 absoluteUsedCapacity=0.16931216 used=<memory:1536, vCores:3> cluster=<memory:9072, vCores:4>
2019-01-08 21:01:47,122 INFO org.apache.hadoop.yarn.server.resourcemanager.rmcontainer.RMContainerImpl: container_1546970280036_0003_01_000004 Container Transitioned from NEW to ALLOCATED
2019-01-08 21:01:47,122 INFO org.apache.hadoop.yarn.server.resourcemanager.RMAuditLogger: USER=hadoop2	OPERATION=AM Allocated Container	TARGET=SchedulerApp	RESULT=SUCCESS	APPID=application_1546970280036_0003	CONTAINERID=container_1546970280036_0003_01_000004	RESOURCE=<memory:512, vCores:1>
2019-01-08 21:01:47,122 INFO org.apache.hadoop.yarn.server.resourcemanager.scheduler.capacity.ParentQueue: assignedContainer queue=root usedCapacity=0.22574955 absoluteUsedCapacity=0.22574955 used=<memory:2048, vCores:4> cluster=<memory:9072, vCores:4>
2019-01-08 21:01:47,123 INFO org.apache.hadoop.yarn.server.resourcemanager.scheduler.capacity.CapacityScheduler: Allocation proposal accepted
2019-01-08 21:01:47,734 INFO org.apache.hadoop.yarn.server.resourcemanager.scheduler.AppSchedulingInfo: checking for deactivate of application :application_1546970280036_0003
2019-01-08 21:01:47,736 INFO org.apache.hadoop.yarn.server.resourcemanager.rmcontainer.RMContainerImpl: container_1546970280036_0003_01_000003 Container Transitioned from ALLOCATED to ACQUIRED
2019-01-08 21:01:47,737 INFO org.apache.hadoop.yarn.server.resourcemanager.security.NMTokenSecretManagerInRM: Sending NMToken for nodeId : master:39349 for container : container_1546970280036_0003_01_000004
2019-01-08 21:01:47,739 INFO org.apache.hadoop.yarn.server.resourcemanager.rmcontainer.RMContainerImpl: container_1546970280036_0003_01_000004 Container Transitioned from ALLOCATED to ACQUIRED
2019-01-08 21:01:47,970 INFO org.apache.hadoop.yarn.server.resourcemanager.rmcontainer.RMContainerImpl: container_1546970280036_0003_01_000003 Container Transitioned from ACQUIRED to RUNNING
2019-01-08 21:01:47,971 INFO org.apache.hadoop.yarn.server.resourcemanager.scheduler.capacity.allocator.AbstractContainerAllocator: assignedContainer application attempt=appattempt_1546970280036_0003_000001 container=null queue=org.apache.hadoop.yarn.server.resourcemanager.scheduler.capacity.allocator.RegularContainerAllocator@6284c523 clusterResource=<memory:9072, vCores:4> type=OFF_SWITCH requestedPartition=
2019-01-08 21:01:47,971 INFO org.apache.hadoop.yarn.server.resourcemanager.scheduler.capacity.ParentQueue: assignedContainer queue=root usedCapacity=0.22574955 absoluteUsedCapacity=0.22574955 used=<memory:2048, vCores:4> cluster=<memory:9072, vCores:4>
2019-01-08 21:01:47,971 INFO org.apache.hadoop.yarn.server.resourcemanager.rmcontainer.RMContainerImpl: container_1546970280036_0003_01_000005 Container Transitioned from NEW to ALLOCATED
2019-01-08 21:01:47,971 INFO org.apache.hadoop.yarn.server.resourcemanager.RMAuditLogger: USER=hadoop2	OPERATION=AM Allocated Container	TARGET=SchedulerApp	RESULT=SUCCESS	APPID=application_1546970280036_0003	CONTAINERID=container_1546970280036_0003_01_000005	RESOURCE=<memory:512, vCores:1>
2019-01-08 21:01:47,971 INFO org.apache.hadoop.yarn.server.resourcemanager.scheduler.capacity.ParentQueue: assignedContainer queue=root usedCapacity=0.28218696 absoluteUsedCapacity=0.28218696 used=<memory:2560, vCores:5> cluster=<memory:9072, vCores:4>
2019-01-08 21:01:47,971 INFO org.apache.hadoop.yarn.server.resourcemanager.scheduler.capacity.CapacityScheduler: Allocation proposal accepted
2019-01-08 21:01:48,124 INFO org.apache.hadoop.yarn.server.resourcemanager.rmcontainer.RMContainerImpl: container_1546970280036_0003_01_000004 Container Transitioned from ACQUIRED to RUNNING
2019-01-08 21:01:48,124 INFO org.apache.hadoop.yarn.server.resourcemanager.scheduler.capacity.allocator.AbstractContainerAllocator: assignedContainer application attempt=appattempt_1546970280036_0003_000001 container=null queue=org.apache.hadoop.yarn.server.resourcemanager.scheduler.capacity.allocator.RegularContainerAllocator@6284c523 clusterResource=<memory:9072, vCores:4> type=OFF_SWITCH requestedPartition=
2019-01-08 21:01:48,124 INFO org.apache.hadoop.yarn.server.resourcemanager.scheduler.capacity.ParentQueue: assignedContainer queue=root usedCapacity=0.28218696 absoluteUsedCapacity=0.28218696 used=<memory:2560, vCores:5> cluster=<memory:9072, vCores:4>
2019-01-08 21:01:48,124 INFO org.apache.hadoop.yarn.server.resourcemanager.rmcontainer.RMContainerImpl: container_1546970280036_0003_01_000006 Container Transitioned from NEW to ALLOCATED
2019-01-08 21:01:48,124 INFO org.apache.hadoop.yarn.server.resourcemanager.RMAuditLogger: USER=hadoop2	OPERATION=AM Allocated Container	TARGET=SchedulerApp	RESULT=SUCCESS	APPID=application_1546970280036_0003	CONTAINERID=container_1546970280036_0003_01_000006	RESOURCE=<memory:512, vCores:1>
2019-01-08 21:01:48,124 INFO org.apache.hadoop.yarn.server.resourcemanager.scheduler.capacity.ParentQueue: assignedContainer queue=root usedCapacity=0.33862433 absoluteUsedCapacity=0.33862433 used=<memory:3072, vCores:6> cluster=<memory:9072, vCores:4>
2019-01-08 21:01:48,124 INFO org.apache.hadoop.yarn.server.resourcemanager.scheduler.capacity.CapacityScheduler: Allocation proposal accepted
2019-01-08 21:01:48,745 INFO org.apache.hadoop.yarn.server.resourcemanager.rmcontainer.RMContainerImpl: container_1546970280036_0003_01_000005 Container Transitioned from ALLOCATED to ACQUIRED
2019-01-08 21:01:48,747 INFO org.apache.hadoop.yarn.server.resourcemanager.rmcontainer.RMContainerImpl: container_1546970280036_0003_01_000006 Container Transitioned from ALLOCATED to ACQUIRED
2019-01-08 21:01:48,972 INFO org.apache.hadoop.yarn.server.resourcemanager.rmcontainer.RMContainerImpl: container_1546970280036_0003_01_000005 Container Transitioned from ACQUIRED to RUNNING
2019-01-08 21:01:48,973 INFO org.apache.hadoop.yarn.server.resourcemanager.scheduler.capacity.allocator.AbstractContainerAllocator: assignedContainer application attempt=appattempt_1546970280036_0003_000001 container=null queue=org.apache.hadoop.yarn.server.resourcemanager.scheduler.capacity.allocator.RegularContainerAllocator@6284c523 clusterResource=<memory:9072, vCores:4> type=OFF_SWITCH requestedPartition=
2019-01-08 21:01:48,973 INFO org.apache.hadoop.yarn.server.resourcemanager.scheduler.capacity.ParentQueue: assignedContainer queue=root usedCapacity=0.33862433 absoluteUsedCapacity=0.33862433 used=<memory:3072, vCores:6> cluster=<memory:9072, vCores:4>
2019-01-08 21:01:48,974 INFO org.apache.hadoop.yarn.server.resourcemanager.rmcontainer.RMContainerImpl: container_1546970280036_0003_01_000007 Container Transitioned from NEW to ALLOCATED
2019-01-08 21:01:48,974 INFO org.apache.hadoop.yarn.server.resourcemanager.RMAuditLogger: USER=hadoop2	OPERATION=AM Allocated Container	TARGET=SchedulerApp	RESULT=SUCCESS	APPID=application_1546970280036_0003	CONTAINERID=container_1546970280036_0003_01_000007	RESOURCE=<memory:512, vCores:1>
2019-01-08 21:01:48,974 INFO org.apache.hadoop.yarn.server.resourcemanager.scheduler.capacity.ParentQueue: assignedContainer queue=root usedCapacity=0.39506173 absoluteUsedCapacity=0.39506173 used=<memory:3584, vCores:7> cluster=<memory:9072, vCores:4>
2019-01-08 21:01:48,974 INFO org.apache.hadoop.yarn.server.resourcemanager.scheduler.capacity.CapacityScheduler: Allocation proposal accepted
2019-01-08 21:01:49,124 INFO org.apache.hadoop.yarn.server.resourcemanager.rmcontainer.RMContainerImpl: container_1546970280036_0003_01_000006 Container Transitioned from ACQUIRED to RUNNING
2019-01-08 21:01:49,125 INFO org.apache.hadoop.yarn.server.resourcemanager.scheduler.capacity.allocator.AbstractContainerAllocator: assignedContainer application attempt=appattempt_1546970280036_0003_000001 container=null queue=org.apache.hadoop.yarn.server.resourcemanager.scheduler.capacity.allocator.RegularContainerAllocator@6284c523 clusterResource=<memory:9072, vCores:4> type=OFF_SWITCH requestedPartition=
2019-01-08 21:01:49,125 INFO org.apache.hadoop.yarn.server.resourcemanager.scheduler.capacity.ParentQueue: assignedContainer queue=root usedCapacity=0.39506173 absoluteUsedCapacity=0.39506173 used=<memory:3584, vCores:7> cluster=<memory:9072, vCores:4>
2019-01-08 21:01:49,125 INFO org.apache.hadoop.yarn.server.resourcemanager.rmcontainer.RMContainerImpl: container_1546970280036_0003_01_000008 Container Transitioned from NEW to ALLOCATED
2019-01-08 21:01:49,125 INFO org.apache.hadoop.yarn.server.resourcemanager.RMAuditLogger: USER=hadoop2	OPERATION=AM Allocated Container	TARGET=SchedulerApp	RESULT=SUCCESS	APPID=application_1546970280036_0003	CONTAINERID=container_1546970280036_0003_01_000008	RESOURCE=<memory:512, vCores:1>
2019-01-08 21:01:49,126 INFO org.apache.hadoop.yarn.server.resourcemanager.scheduler.capacity.ParentQueue: assignedContainer queue=root usedCapacity=0.4514991 absoluteUsedCapacity=0.4514991 used=<memory:4096, vCores:8> cluster=<memory:9072, vCores:4>
2019-01-08 21:01:49,126 INFO org.apache.hadoop.yarn.server.resourcemanager.scheduler.capacity.CapacityScheduler: Allocation proposal accepted
2019-01-08 21:01:49,757 INFO org.apache.hadoop.yarn.server.resourcemanager.rmcontainer.RMContainerImpl: container_1546970280036_0003_01_000007 Container Transitioned from ALLOCATED to ACQUIRED
2019-01-08 21:01:49,758 INFO org.apache.hadoop.yarn.server.resourcemanager.rmcontainer.RMContainerImpl: container_1546970280036_0003_01_000008 Container Transitioned from ALLOCATED to ACQUIRED
2019-01-08 21:01:49,975 INFO org.apache.hadoop.yarn.server.resourcemanager.rmcontainer.RMContainerImpl: container_1546970280036_0003_01_000007 Container Transitioned from ACQUIRED to RUNNING
2019-01-08 21:01:49,975 INFO org.apache.hadoop.yarn.server.resourcemanager.scheduler.capacity.allocator.AbstractContainerAllocator: assignedContainer application attempt=appattempt_1546970280036_0003_000001 container=null queue=org.apache.hadoop.yarn.server.resourcemanager.scheduler.capacity.allocator.RegularContainerAllocator@6284c523 clusterResource=<memory:9072, vCores:4> type=OFF_SWITCH requestedPartition=
2019-01-08 21:01:49,976 INFO org.apache.hadoop.yarn.server.resourcemanager.scheduler.capacity.ParentQueue: assignedContainer queue=root usedCapacity=0.4514991 absoluteUsedCapacity=0.4514991 used=<memory:4096, vCores:8> cluster=<memory:9072, vCores:4>
2019-01-08 21:01:49,976 INFO org.apache.hadoop.yarn.server.resourcemanager.rmcontainer.RMContainerImpl: container_1546970280036_0003_01_000009 Container Transitioned from NEW to ALLOCATED
2019-01-08 21:01:49,976 INFO org.apache.hadoop.yarn.server.resourcemanager.RMAuditLogger: USER=hadoop2	OPERATION=AM Allocated Container	TARGET=SchedulerApp	RESULT=SUCCESS	APPID=application_1546970280036_0003	CONTAINERID=container_1546970280036_0003_01_000009	RESOURCE=<memory:512, vCores:1>
2019-01-08 21:01:49,976 INFO org.apache.hadoop.yarn.server.resourcemanager.scheduler.capacity.ParentQueue: assignedContainer queue=root usedCapacity=0.50793654 absoluteUsedCapacity=0.50793654 used=<memory:4608, vCores:9> cluster=<memory:9072, vCores:4>
2019-01-08 21:01:49,976 INFO org.apache.hadoop.yarn.server.resourcemanager.scheduler.capacity.CapacityScheduler: Allocation proposal accepted
2019-01-08 21:01:50,126 INFO org.apache.hadoop.yarn.server.resourcemanager.rmcontainer.RMContainerImpl: container_1546970280036_0003_01_000008 Container Transitioned from ACQUIRED to RUNNING
2019-01-08 21:01:50,126 INFO org.apache.hadoop.yarn.server.resourcemanager.scheduler.capacity.allocator.AbstractContainerAllocator: assignedContainer application attempt=appattempt_1546970280036_0003_000001 container=null queue=org.apache.hadoop.yarn.server.resourcemanager.scheduler.capacity.allocator.RegularContainerAllocator@6284c523 clusterResource=<memory:9072, vCores:4> type=OFF_SWITCH requestedPartition=
2019-01-08 21:01:50,126 INFO org.apache.hadoop.yarn.server.resourcemanager.scheduler.capacity.ParentQueue: assignedContainer queue=root usedCapacity=0.50793654 absoluteUsedCapacity=0.50793654 used=<memory:4608, vCores:9> cluster=<memory:9072, vCores:4>
2019-01-08 21:01:50,127 INFO org.apache.hadoop.yarn.server.resourcemanager.rmcontainer.RMContainerImpl: container_1546970280036_0003_01_000010 Container Transitioned from NEW to ALLOCATED
2019-01-08 21:01:50,127 INFO org.apache.hadoop.yarn.server.resourcemanager.RMAuditLogger: USER=hadoop2	OPERATION=AM Allocated Container	TARGET=SchedulerApp	RESULT=SUCCESS	APPID=application_1546970280036_0003	CONTAINERID=container_1546970280036_0003_01_000010	RESOURCE=<memory:512, vCores:1>
2019-01-08 21:01:50,127 INFO org.apache.hadoop.yarn.server.resourcemanager.scheduler.capacity.ParentQueue: assignedContainer queue=root usedCapacity=0.5643739 absoluteUsedCapacity=0.5643739 used=<memory:5120, vCores:10> cluster=<memory:9072, vCores:4>
2019-01-08 21:01:50,127 INFO org.apache.hadoop.yarn.server.resourcemanager.scheduler.capacity.CapacityScheduler: Allocation proposal accepted
2019-01-08 21:01:50,764 INFO org.apache.hadoop.yarn.server.resourcemanager.rmcontainer.RMContainerImpl: container_1546970280036_0003_01_000009 Container Transitioned from ALLOCATED to ACQUIRED
2019-01-08 21:01:50,765 INFO org.apache.hadoop.yarn.server.resourcemanager.rmcontainer.RMContainerImpl: container_1546970280036_0003_01_000010 Container Transitioned from ALLOCATED to ACQUIRED
2019-01-08 21:01:51,000 INFO org.apache.hadoop.yarn.server.resourcemanager.rmcontainer.RMContainerImpl: container_1546970280036_0003_01_000009 Container Transitioned from ACQUIRED to RUNNING
2019-01-08 21:01:51,001 INFO org.apache.hadoop.yarn.server.resourcemanager.scheduler.capacity.allocator.AbstractContainerAllocator: assignedContainer application attempt=appattempt_1546970280036_0003_000001 container=null queue=org.apache.hadoop.yarn.server.resourcemanager.scheduler.capacity.allocator.RegularContainerAllocator@6284c523 clusterResource=<memory:9072, vCores:4> type=OFF_SWITCH requestedPartition=
2019-01-08 21:01:51,001 INFO org.apache.hadoop.yarn.server.resourcemanager.scheduler.capacity.ParentQueue: assignedContainer queue=root usedCapacity=0.5643739 absoluteUsedCapacity=0.5643739 used=<memory:5120, vCores:10> cluster=<memory:9072, vCores:4>
2019-01-08 21:01:51,001 INFO org.apache.hadoop.yarn.server.resourcemanager.rmcontainer.RMContainerImpl: container_1546970280036_0003_01_000011 Container Transitioned from NEW to ALLOCATED
2019-01-08 21:01:51,001 INFO org.apache.hadoop.yarn.server.resourcemanager.RMAuditLogger: USER=hadoop2	OPERATION=AM Allocated Container	TARGET=SchedulerApp	RESULT=SUCCESS	APPID=application_1546970280036_0003	CONTAINERID=container_1546970280036_0003_01_000011	RESOURCE=<memory:512, vCores:1>
2019-01-08 21:01:51,001 INFO org.apache.hadoop.yarn.server.resourcemanager.scheduler.capacity.ParentQueue: assignedContainer queue=root usedCapacity=0.6208113 absoluteUsedCapacity=0.6208113 used=<memory:5632, vCores:11> cluster=<memory:9072, vCores:4>
2019-01-08 21:01:51,001 INFO org.apache.hadoop.yarn.server.resourcemanager.scheduler.capacity.CapacityScheduler: Allocation proposal accepted
2019-01-08 21:01:51,127 INFO org.apache.hadoop.yarn.server.resourcemanager.rmcontainer.RMContainerImpl: container_1546970280036_0003_01_000010 Container Transitioned from ACQUIRED to RUNNING
2019-01-08 21:01:51,128 INFO org.apache.hadoop.yarn.server.resourcemanager.scheduler.capacity.allocator.AbstractContainerAllocator: assignedContainer application attempt=appattempt_1546970280036_0003_000001 container=null queue=org.apache.hadoop.yarn.server.resourcemanager.scheduler.capacity.allocator.RegularContainerAllocator@6284c523 clusterResource=<memory:9072, vCores:4> type=OFF_SWITCH requestedPartition=
2019-01-08 21:01:51,128 INFO org.apache.hadoop.yarn.server.resourcemanager.scheduler.capacity.ParentQueue: assignedContainer queue=root usedCapacity=0.6208113 absoluteUsedCapacity=0.6208113 used=<memory:5632, vCores:11> cluster=<memory:9072, vCores:4>
2019-01-08 21:01:51,128 INFO org.apache.hadoop.yarn.server.resourcemanager.rmcontainer.RMContainerImpl: container_1546970280036_0003_01_000012 Container Transitioned from NEW to ALLOCATED
2019-01-08 21:01:51,128 INFO org.apache.hadoop.yarn.server.resourcemanager.RMAuditLogger: USER=hadoop2	OPERATION=AM Allocated Container	TARGET=SchedulerApp	RESULT=SUCCESS	APPID=application_1546970280036_0003	CONTAINERID=container_1546970280036_0003_01_000012	RESOURCE=<memory:512, vCores:1>
2019-01-08 21:01:51,128 INFO org.apache.hadoop.yarn.server.resourcemanager.scheduler.capacity.ParentQueue: assignedContainer queue=root usedCapacity=0.67724866 absoluteUsedCapacity=0.67724866 used=<memory:6144, vCores:12> cluster=<memory:9072, vCores:4>
2019-01-08 21:01:51,128 INFO org.apache.hadoop.yarn.server.resourcemanager.scheduler.capacity.CapacityScheduler: Allocation proposal accepted
2019-01-08 21:01:51,773 INFO org.apache.hadoop.yarn.server.resourcemanager.rmcontainer.RMContainerImpl: container_1546970280036_0003_01_000011 Container Transitioned from ALLOCATED to ACQUIRED
2019-01-08 21:01:51,775 INFO org.apache.hadoop.yarn.server.resourcemanager.rmcontainer.RMContainerImpl: container_1546970280036_0003_01_000012 Container Transitioned from ALLOCATED to ACQUIRED
2019-01-08 21:01:52,004 INFO org.apache.hadoop.yarn.server.resourcemanager.rmcontainer.RMContainerImpl: container_1546970280036_0003_01_000011 Container Transitioned from ACQUIRED to RUNNING
2019-01-08 21:01:52,005 INFO org.apache.hadoop.yarn.server.resourcemanager.scheduler.capacity.allocator.AbstractContainerAllocator: assignedContainer application attempt=appattempt_1546970280036_0003_000001 container=null queue=org.apache.hadoop.yarn.server.resourcemanager.scheduler.capacity.allocator.RegularContainerAllocator@6284c523 clusterResource=<memory:9072, vCores:4> type=OFF_SWITCH requestedPartition=
2019-01-08 21:01:52,005 INFO org.apache.hadoop.yarn.server.resourcemanager.scheduler.capacity.ParentQueue: assignedContainer queue=root usedCapacity=0.67724866 absoluteUsedCapacity=0.67724866 used=<memory:6144, vCores:12> cluster=<memory:9072, vCores:4>
2019-01-08 21:01:52,005 INFO org.apache.hadoop.yarn.server.resourcemanager.rmcontainer.RMContainerImpl: container_1546970280036_0003_01_000013 Container Transitioned from NEW to ALLOCATED
2019-01-08 21:01:52,005 INFO org.apache.hadoop.yarn.server.resourcemanager.RMAuditLogger: USER=hadoop2	OPERATION=AM Allocated Container	TARGET=SchedulerApp	RESULT=SUCCESS	APPID=application_1546970280036_0003	CONTAINERID=container_1546970280036_0003_01_000013	RESOURCE=<memory:512, vCores:1>
2019-01-08 21:01:52,005 INFO org.apache.hadoop.yarn.server.resourcemanager.scheduler.capacity.ParentQueue: assignedContainer queue=root usedCapacity=0.7336861 absoluteUsedCapacity=0.7336861 used=<memory:6656, vCores:13> cluster=<memory:9072, vCores:4>
2019-01-08 21:01:52,005 INFO org.apache.hadoop.yarn.server.resourcemanager.scheduler.capacity.CapacityScheduler: Allocation proposal accepted
2019-01-08 21:01:53,007 INFO org.apache.hadoop.yarn.server.resourcemanager.rmcontainer.RMContainerImpl: container_1546970280036_0003_01_000012 Container Transitioned from ACQUIRED to RELEASED
2019-01-08 21:01:53,008 INFO org.apache.hadoop.yarn.server.resourcemanager.RMAuditLogger: USER=hadoop2	IP=132.72.109.41	OPERATION=AM Released Container	TARGET=SchedulerApp	RESULT=SUCCESS	APPID=application_1546970280036_0003	CONTAINERID=container_1546970280036_0003_01_000012	RESOURCE=<memory:512, vCores:1>
2019-01-08 21:01:53,008 INFO org.apache.hadoop.yarn.server.resourcemanager.scheduler.AppSchedulingInfo: checking for deactivate of application :application_1546970280036_0003
2019-01-08 21:01:53,009 INFO org.apache.hadoop.yarn.server.resourcemanager.rmcontainer.RMContainerImpl: container_1546970280036_0003_01_000013 Container Transitioned from ALLOCATED to ACQUIRED
2019-01-08 21:01:54,020 INFO org.apache.hadoop.yarn.server.resourcemanager.rmcontainer.RMContainerImpl: container_1546970280036_0003_01_000013 Container Transitioned from ACQUIRED to RELEASED
2019-01-08 21:01:54,020 INFO org.apache.hadoop.yarn.server.resourcemanager.RMAuditLogger: USER=hadoop2	IP=132.72.109.41	OPERATION=AM Released Container	TARGET=SchedulerApp	RESULT=SUCCESS	APPID=application_1546970280036_0003	CONTAINERID=container_1546970280036_0003_01_000013	RESOURCE=<memory:512, vCores:1>
2019-01-08 21:02:09,370 INFO org.apache.hadoop.yarn.server.resourcemanager.rmcontainer.RMContainerImpl: container_1546970280036_0003_01_000002 Container Transitioned from RUNNING to COMPLETED
2019-01-08 21:02:09,453 INFO org.apache.hadoop.yarn.server.resourcemanager.RMAuditLogger: USER=hadoop2	OPERATION=AM Released Container	TARGET=SchedulerApp	RESULT=SUCCESS	APPID=application_1546970280036_0003	CONTAINERID=container_1546970280036_0003_01_000002	RESOURCE=<memory:512, vCores:1>
2019-01-08 21:02:12,241 INFO org.apache.hadoop.yarn.server.resourcemanager.rmcontainer.RMContainerImpl: container_1546970280036_0003_01_000005 Container Transitioned from RUNNING to COMPLETED
2019-01-08 21:02:12,241 INFO org.apache.hadoop.yarn.server.resourcemanager.RMAuditLogger: USER=hadoop2	OPERATION=AM Released Container	TARGET=SchedulerApp	RESULT=SUCCESS	APPID=application_1546970280036_0003	CONTAINERID=container_1546970280036_0003_01_000005	RESOURCE=<memory:512, vCores:1>
2019-01-08 21:02:12,785 INFO org.apache.hadoop.yarn.server.resourcemanager.rmcontainer.RMContainerImpl: container_1546970280036_0003_01_000007 Container Transitioned from RUNNING to COMPLETED
2019-01-08 21:02:12,785 INFO org.apache.hadoop.yarn.server.resourcemanager.RMAuditLogger: USER=hadoop2	OPERATION=AM Released Container	TARGET=SchedulerApp	RESULT=SUCCESS	APPID=application_1546970280036_0003	CONTAINERID=container_1546970280036_0003_01_000007	RESOURCE=<memory:512, vCores:1>
2019-01-08 21:02:12,891 INFO org.apache.hadoop.yarn.server.resourcemanager.rmcontainer.RMContainerImpl: container_1546970280036_0003_01_000011 Container Transitioned from RUNNING to COMPLETED
2019-01-08 21:02:12,891 INFO org.apache.hadoop.yarn.server.resourcemanager.RMAuditLogger: USER=hadoop2	OPERATION=AM Released Container	TARGET=SchedulerApp	RESULT=SUCCESS	APPID=application_1546970280036_0003	CONTAINERID=container_1546970280036_0003_01_000011	RESOURCE=<memory:512, vCores:1>
2019-01-08 21:02:12,923 INFO org.apache.hadoop.yarn.server.resourcemanager.rmcontainer.RMContainerImpl: container_1546970280036_0003_01_000009 Container Transitioned from RUNNING to COMPLETED
2019-01-08 21:02:12,923 INFO org.apache.hadoop.yarn.server.resourcemanager.RMAuditLogger: USER=hadoop2	OPERATION=AM Released Container	TARGET=SchedulerApp	RESULT=SUCCESS	APPID=application_1546970280036_0003	CONTAINERID=container_1546970280036_0003_01_000009	RESOURCE=<memory:512, vCores:1>
2019-01-08 21:02:13,368 INFO org.apache.hadoop.yarn.server.resourcemanager.rmcontainer.RMContainerImpl: container_1546970280036_0003_01_000003 Container Transitioned from RUNNING to COMPLETED
2019-01-08 21:02:13,368 INFO org.apache.hadoop.yarn.server.resourcemanager.RMAuditLogger: USER=hadoop2	OPERATION=AM Released Container	TARGET=SchedulerApp	RESULT=SUCCESS	APPID=application_1546970280036_0003	CONTAINERID=container_1546970280036_0003_01_000003	RESOURCE=<memory:512, vCores:1>
2019-01-08 21:02:14,159 INFO org.apache.hadoop.yarn.server.resourcemanager.scheduler.capacity.allocator.AbstractContainerAllocator: assignedContainer application attempt=appattempt_1546970280036_0003_000001 container=null queue=org.apache.hadoop.yarn.server.resourcemanager.scheduler.capacity.allocator.RegularContainerAllocator@6284c523 clusterResource=<memory:9072, vCores:4> type=OFF_SWITCH requestedPartition=
2019-01-08 21:02:14,159 INFO org.apache.hadoop.yarn.server.resourcemanager.scheduler.capacity.ParentQueue: assignedContainer queue=root usedCapacity=0.28218696 absoluteUsedCapacity=0.28218696 used=<memory:2560, vCores:5> cluster=<memory:9072, vCores:4>
2019-01-08 21:02:14,159 INFO org.apache.hadoop.yarn.server.resourcemanager.rmcontainer.RMContainerImpl: container_1546970280036_0003_01_000014 Container Transitioned from NEW to ALLOCATED
2019-01-08 21:02:14,159 INFO org.apache.hadoop.yarn.server.resourcemanager.RMAuditLogger: USER=hadoop2	OPERATION=AM Allocated Container	TARGET=SchedulerApp	RESULT=SUCCESS	APPID=application_1546970280036_0003	CONTAINERID=container_1546970280036_0003_01_000014	RESOURCE=<memory:512, vCores:1>
2019-01-08 21:02:14,159 INFO org.apache.hadoop.yarn.server.resourcemanager.scheduler.capacity.ParentQueue: assignedContainer queue=root usedCapacity=0.33862433 absoluteUsedCapacity=0.33862433 used=<memory:3072, vCores:6> cluster=<memory:9072, vCores:4>
2019-01-08 21:02:14,159 INFO org.apache.hadoop.yarn.server.resourcemanager.scheduler.capacity.CapacityScheduler: Allocation proposal accepted
2019-01-08 21:02:15,090 INFO org.apache.hadoop.yarn.server.resourcemanager.scheduler.AppSchedulingInfo: checking for deactivate of application :application_1546970280036_0003
2019-01-08 21:02:15,092 INFO org.apache.hadoop.yarn.server.resourcemanager.rmcontainer.RMContainerImpl: container_1546970280036_0003_01_000014 Container Transitioned from ALLOCATED to ACQUIRED
2019-01-08 21:02:16,094 INFO org.apache.hadoop.yarn.server.resourcemanager.rmcontainer.RMContainerImpl: container_1546970280036_0003_01_000014 Container Transitioned from ACQUIRED to RELEASED
2019-01-08 21:02:16,094 INFO org.apache.hadoop.yarn.server.resourcemanager.RMAuditLogger: USER=hadoop2	IP=132.72.109.41	OPERATION=AM Released Container	TARGET=SchedulerApp	RESULT=SUCCESS	APPID=application_1546970280036_0003	CONTAINERID=container_1546970280036_0003_01_000014	RESOURCE=<memory:512, vCores:1>
2019-01-08 21:02:16,481 INFO org.apache.hadoop.yarn.server.resourcemanager.rmcontainer.RMContainerImpl: container_1546970280036_0003_01_000008 Container Transitioned from RUNNING to COMPLETED
2019-01-08 21:02:16,481 INFO org.apache.hadoop.yarn.server.resourcemanager.RMAuditLogger: USER=hadoop2	OPERATION=AM Released Container	TARGET=SchedulerApp	RESULT=SUCCESS	APPID=application_1546970280036_0003	CONTAINERID=container_1546970280036_0003_01_000008	RESOURCE=<memory:512, vCores:1>
2019-01-08 21:02:16,514 INFO org.apache.hadoop.yarn.server.resourcemanager.rmcontainer.RMContainerImpl: container_1546970280036_0003_01_000010 Container Transitioned from RUNNING to COMPLETED
2019-01-08 21:02:16,514 INFO org.apache.hadoop.yarn.server.resourcemanager.RMAuditLogger: USER=hadoop2	OPERATION=AM Released Container	TARGET=SchedulerApp	RESULT=SUCCESS	APPID=application_1546970280036_0003	CONTAINERID=container_1546970280036_0003_01_000010	RESOURCE=<memory:512, vCores:1>
2019-01-08 21:02:16,590 INFO org.apache.hadoop.yarn.server.resourcemanager.rmcontainer.RMContainerImpl: container_1546970280036_0003_01_000006 Container Transitioned from RUNNING to COMPLETED
2019-01-08 21:02:16,590 INFO org.apache.hadoop.yarn.server.resourcemanager.RMAuditLogger: USER=hadoop2	OPERATION=AM Released Container	TARGET=SchedulerApp	RESULT=SUCCESS	APPID=application_1546970280036_0003	CONTAINERID=container_1546970280036_0003_01_000006	RESOURCE=<memory:512, vCores:1>
2019-01-08 21:02:16,591 INFO org.apache.hadoop.yarn.server.resourcemanager.rmcontainer.RMContainerImpl: container_1546970280036_0003_01_000004 Container Transitioned from RUNNING to COMPLETED
2019-01-08 21:02:16,591 INFO org.apache.hadoop.yarn.server.resourcemanager.RMAuditLogger: USER=hadoop2	OPERATION=AM Released Container	TARGET=SchedulerApp	RESULT=SUCCESS	APPID=application_1546970280036_0003	CONTAINERID=container_1546970280036_0003_01_000004	RESOURCE=<memory:512, vCores:1>
2019-01-08 21:02:16,691 INFO org.apache.hadoop.yarn.server.resourcemanager.rmapp.attempt.RMAppAttemptImpl: Updating application attempt appattempt_1546970280036_0003_000001 with final state: FINISHING, and exit status: -1000
2019-01-08 21:02:16,691 INFO org.apache.hadoop.yarn.server.resourcemanager.rmapp.attempt.RMAppAttemptImpl: appattempt_1546970280036_0003_000001 State change from RUNNING to FINAL_SAVING on event = UNREGISTERED
2019-01-08 21:02:16,691 INFO org.apache.hadoop.yarn.server.resourcemanager.rmapp.RMAppImpl: Updating application application_1546970280036_0003 with final state: FINISHING
2019-01-08 21:02:16,691 INFO org.apache.hadoop.yarn.server.resourcemanager.recovery.RMStateStore: Updating info for app: application_1546970280036_0003
2019-01-08 21:02:16,691 INFO org.apache.hadoop.yarn.server.resourcemanager.rmapp.RMAppImpl: application_1546970280036_0003 State change from RUNNING to FINAL_SAVING on event = ATTEMPT_UNREGISTERED
2019-01-08 21:02:16,692 INFO org.apache.hadoop.yarn.server.resourcemanager.rmapp.attempt.RMAppAttemptImpl: appattempt_1546970280036_0003_000001 State change from FINAL_SAVING to FINISHING on event = ATTEMPT_UPDATE_SAVED
2019-01-08 21:02:16,692 INFO org.apache.hadoop.yarn.server.resourcemanager.rmapp.RMAppImpl: application_1546970280036_0003 State change from FINAL_SAVING to FINISHING on event = APP_UPDATE_SAVED
2019-01-08 21:02:17,694 INFO org.apache.hadoop.yarn.server.resourcemanager.ApplicationMasterService: application_1546970280036_0003 unregistered successfully. 
2019-01-08 21:02:19,153 INFO org.apache.hadoop.yarn.server.resourcemanager.ClientRMService: Allocated new applicationId: 4
2019-01-08 21:02:23,225 INFO org.apache.hadoop.yarn.server.resourcemanager.ApplicationMasterService: Unregistering app attempt : appattempt_1546970280036_0003_000001
2019-01-08 21:02:23,225 INFO org.apache.hadoop.yarn.server.resourcemanager.rmcontainer.RMContainerImpl: container_1546970280036_0003_01_000001 Container Transitioned from RUNNING to COMPLETED
2019-01-08 21:02:23,225 INFO org.apache.hadoop.yarn.server.resourcemanager.security.AMRMTokenSecretManager: Application finished, removing password for appattempt_1546970280036_0003_000001
2019-01-08 21:02:23,225 INFO org.apache.hadoop.yarn.server.resourcemanager.RMAuditLogger: USER=hadoop2	OPERATION=AM Released Container	TARGET=SchedulerApp	RESULT=SUCCESS	APPID=application_1546970280036_0003	CONTAINERID=container_1546970280036_0003_01_000001	RESOURCE=<memory:512, vCores:1>
2019-01-08 21:02:23,225 INFO org.apache.hadoop.yarn.server.resourcemanager.rmapp.attempt.RMAppAttemptImpl: appattempt_1546970280036_0003_000001 State change from FINISHING to FINISHED on event = CONTAINER_FINISHED
2019-01-08 21:02:23,225 INFO org.apache.hadoop.yarn.server.resourcemanager.rmapp.RMAppImpl: application_1546970280036_0003 State change from FINISHING to FINISHED on event = ATTEMPT_FINISHED
2019-01-08 21:02:23,226 INFO org.apache.hadoop.yarn.server.resourcemanager.RMAuditLogger: USER=hadoop2	OPERATION=Application Finished - Succeeded	TARGET=RMAppManager	RESULT=SUCCESS	APPID=application_1546970280036_0003
2019-01-08 21:02:23,226 INFO org.apache.hadoop.yarn.server.resourcemanager.RMAppManager$ApplicationSummary: appId=application_1546970280036_0003,name=input_105_104-000,user=hadoop2,queue=default,state=FINISHED,trackingUrl=http://master:8088/proxy/application_1546970280036_0003/,appMasterHost=razoldslave2,submitTime=1546974097937,startTime=1546974097937,finishTime=1546974136691,finalStatus=SUCCEEDED,memorySeconds=156407,vcoreSeconds=298,preemptedMemorySeconds=0,preemptedVcoreSeconds=0,preemptedAMContainers=0,preemptedNonAMContainers=0,preemptedResources=<memory:0\, vCores:0>,applicationType=MAPREDUCE
2019-01-08 21:02:23,227 INFO org.apache.hadoop.yarn.server.resourcemanager.amlauncher.AMLauncher: Cleaning master appattempt_1546970280036_0003_000001
2019-01-08 21:02:23,229 INFO org.apache.hadoop.yarn.server.resourcemanager.scheduler.capacity.CapacityScheduler: Application Attempt appattempt_1546970280036_0003_000001 is done. finalState=FINISHED
2019-01-08 21:02:23,230 INFO org.apache.hadoop.yarn.server.resourcemanager.scheduler.AppSchedulingInfo: Application application_1546970280036_0003 requests cleared
2019-01-08 21:02:23,230 INFO org.apache.hadoop.yarn.server.resourcemanager.scheduler.capacity.LeafQueue: Application removed - appId: application_1546970280036_0003 user: hadoop2 queue: default #user-pending-applications: 0 #user-active-applications: 0 #queue-pending-applications: 0 #queue-active-applications: 0
2019-01-08 21:02:23,230 INFO org.apache.hadoop.yarn.server.resourcemanager.scheduler.capacity.ParentQueue: Application removed - appId: application_1546970280036_0003 user: hadoop2 leaf-queue of parent: root #applications: 0
2019-01-08 21:02:24,014 INFO org.apache.hadoop.yarn.server.resourcemanager.scheduler.capacity.CapacityScheduler: Application 'application_1546970280036_0004' is submitted without priority hence considering default queue/cluster priority: 0
2019-01-08 21:02:24,014 INFO org.apache.hadoop.yarn.server.resourcemanager.scheduler.capacity.CapacityScheduler: Priority '0' is acceptable in queue : default for application: application_1546970280036_0004
2019-01-08 21:02:24,014 INFO org.apache.hadoop.yarn.server.resourcemanager.ClientRMService: Application with id 4 submitted by user hadoop2
2019-01-08 21:02:24,014 INFO org.apache.hadoop.yarn.server.resourcemanager.RMAuditLogger: USER=hadoop2	IP=132.72.109.20	OPERATION=Submit Application Request	TARGET=ClientRMService	RESULT=SUCCESS	APPID=application_1546970280036_0004	CALLERCONTEXT=CLI
2019-01-08 21:02:24,014 INFO org.apache.hadoop.yarn.server.resourcemanager.rmapp.RMAppImpl: Storing application with id application_1546970280036_0004
2019-01-08 21:02:24,014 INFO org.apache.hadoop.yarn.server.resourcemanager.rmapp.RMAppImpl: application_1546970280036_0004 State change from NEW to NEW_SAVING on event = START
2019-01-08 21:02:24,015 INFO org.apache.hadoop.yarn.server.resourcemanager.recovery.RMStateStore: Storing info for app: application_1546970280036_0004
2019-01-08 21:02:24,015 INFO org.apache.hadoop.yarn.server.resourcemanager.rmapp.RMAppImpl: application_1546970280036_0004 State change from NEW_SAVING to SUBMITTED on event = APP_NEW_SAVED
2019-01-08 21:02:24,015 INFO org.apache.hadoop.yarn.server.resourcemanager.scheduler.capacity.ParentQueue: Application added - appId: application_1546970280036_0004 user: hadoop2 leaf-queue of parent: root #applications: 1
2019-01-08 21:02:24,015 INFO org.apache.hadoop.yarn.server.resourcemanager.scheduler.capacity.CapacityScheduler: Accepted application application_1546970280036_0004 from user: hadoop2, in queue: default
2019-01-08 21:02:24,015 INFO org.apache.hadoop.yarn.server.resourcemanager.rmapp.RMAppImpl: application_1546970280036_0004 State change from SUBMITTED to ACCEPTED on event = APP_ACCEPTED
2019-01-08 21:02:24,015 INFO org.apache.hadoop.yarn.server.resourcemanager.ApplicationMasterService: Registering app attempt : appattempt_1546970280036_0004_000001
2019-01-08 21:02:24,015 INFO org.apache.hadoop.yarn.server.resourcemanager.rmapp.attempt.RMAppAttemptImpl: appattempt_1546970280036_0004_000001 State change from NEW to SUBMITTED on event = START
2019-01-08 21:02:24,015 INFO org.apache.hadoop.yarn.server.resourcemanager.scheduler.capacity.LeafQueue: Application application_1546970280036_0004 from user: hadoop2 activated in queue: default
2019-01-08 21:02:24,016 INFO org.apache.hadoop.yarn.server.resourcemanager.scheduler.capacity.LeafQueue: Application added - appId: application_1546970280036_0004 user: hadoop2, leaf-queue: default #user-pending-applications: 0 #user-active-applications: 1 #queue-pending-applications: 0 #queue-active-applications: 1
2019-01-08 21:02:24,016 INFO org.apache.hadoop.yarn.server.resourcemanager.scheduler.capacity.CapacityScheduler: Added Application Attempt appattempt_1546970280036_0004_000001 to scheduler from user hadoop2 in queue default
2019-01-08 21:02:24,016 INFO org.apache.hadoop.yarn.server.resourcemanager.rmapp.attempt.RMAppAttemptImpl: appattempt_1546970280036_0004_000001 State change from SUBMITTED to SCHEDULED on event = ATTEMPT_ADDED
2019-01-08 21:02:24,234 INFO org.apache.hadoop.yarn.server.resourcemanager.scheduler.capacity.allocator.AbstractContainerAllocator: assignedContainer application attempt=appattempt_1546970280036_0004_000001 container=null queue=org.apache.hadoop.yarn.server.resourcemanager.scheduler.capacity.allocator.RegularContainerAllocator@51e8f7 clusterResource=<memory:9072, vCores:4> type=OFF_SWITCH requestedPartition=
2019-01-08 21:02:24,234 INFO org.apache.hadoop.yarn.server.resourcemanager.scheduler.capacity.ParentQueue: assignedContainer queue=root usedCapacity=0.0 absoluteUsedCapacity=0.0 used=<memory:0, vCores:0> cluster=<memory:9072, vCores:4>
2019-01-08 21:02:24,235 INFO org.apache.hadoop.yarn.server.resourcemanager.rmcontainer.RMContainerImpl: container_1546970280036_0004_01_000001 Container Transitioned from NEW to ALLOCATED
2019-01-08 21:02:24,235 INFO org.apache.hadoop.yarn.server.resourcemanager.RMAuditLogger: USER=hadoop2	OPERATION=AM Allocated Container	TARGET=SchedulerApp	RESULT=SUCCESS	APPID=application_1546970280036_0004	CONTAINERID=container_1546970280036_0004_01_000001	RESOURCE=<memory:512, vCores:1>
2019-01-08 21:02:24,235 INFO org.apache.hadoop.yarn.server.resourcemanager.scheduler.capacity.ParentQueue: assignedContainer queue=root usedCapacity=0.056437388 absoluteUsedCapacity=0.056437388 used=<memory:512, vCores:1> cluster=<memory:9072, vCores:4>
2019-01-08 21:02:24,235 INFO org.apache.hadoop.yarn.server.resourcemanager.scheduler.capacity.CapacityScheduler: Allocation proposal accepted
2019-01-08 21:02:24,236 INFO org.apache.hadoop.yarn.server.resourcemanager.security.NMTokenSecretManagerInRM: Sending NMToken for nodeId : razoldslave2:40557 for container : container_1546970280036_0004_01_000001
2019-01-08 21:02:24,238 INFO org.apache.hadoop.yarn.server.resourcemanager.rmcontainer.RMContainerImpl: container_1546970280036_0004_01_000001 Container Transitioned from ALLOCATED to ACQUIRED
2019-01-08 21:02:24,238 INFO org.apache.hadoop.yarn.server.resourcemanager.security.NMTokenSecretManagerInRM: Clear node set for appattempt_1546970280036_0004_000001
2019-01-08 21:02:24,238 INFO org.apache.hadoop.yarn.server.resourcemanager.rmapp.attempt.RMAppAttemptImpl: Storing attempt: AppId: application_1546970280036_0004 AttemptId: appattempt_1546970280036_0004_000001 MasterContainer: Container: [ContainerId: container_1546970280036_0004_01_000001, AllocationRequestId: 0, Version: 0, NodeId: razoldslave2:40557, NodeHttpAddress: razoldslave2:8042, Resource: <memory:512, vCores:1>, Priority: 0, Token: Token { kind: ContainerToken, service: 132.72.109.41:40557 }, ExecutionType: GUARANTEED, ]
2019-01-08 21:02:24,239 INFO org.apache.hadoop.yarn.server.resourcemanager.rmapp.attempt.RMAppAttemptImpl: appattempt_1546970280036_0004_000001 State change from SCHEDULED to ALLOCATED_SAVING on event = CONTAINER_ALLOCATED
2019-01-08 21:02:24,239 INFO org.apache.hadoop.yarn.server.resourcemanager.rmapp.attempt.RMAppAttemptImpl: appattempt_1546970280036_0004_000001 State change from ALLOCATED_SAVING to ALLOCATED on event = ATTEMPT_NEW_SAVED
2019-01-08 21:02:24,243 INFO org.apache.hadoop.yarn.server.resourcemanager.amlauncher.AMLauncher: Launching masterappattempt_1546970280036_0004_000001
2019-01-08 21:02:24,249 INFO org.apache.hadoop.yarn.server.resourcemanager.amlauncher.AMLauncher: Setting up container Container: [ContainerId: container_1546970280036_0004_01_000001, AllocationRequestId: 0, Version: 0, NodeId: razoldslave2:40557, NodeHttpAddress: razoldslave2:8042, Resource: <memory:512, vCores:1>, Priority: 0, Token: Token { kind: ContainerToken, service: 132.72.109.41:40557 }, ExecutionType: GUARANTEED, ] for AM appattempt_1546970280036_0004_000001
2019-01-08 21:02:24,249 INFO org.apache.hadoop.yarn.server.resourcemanager.security.AMRMTokenSecretManager: Create AMRMToken for ApplicationAttempt: appattempt_1546970280036_0004_000001
2019-01-08 21:02:24,249 INFO org.apache.hadoop.yarn.server.resourcemanager.security.AMRMTokenSecretManager: Creating password for appattempt_1546970280036_0004_000001
2019-01-08 21:02:24,286 INFO org.apache.hadoop.yarn.server.resourcemanager.amlauncher.AMLauncher: Done launching container Container: [ContainerId: container_1546970280036_0004_01_000001, AllocationRequestId: 0, Version: 0, NodeId: razoldslave2:40557, NodeHttpAddress: razoldslave2:8042, Resource: <memory:512, vCores:1>, Priority: 0, Token: Token { kind: ContainerToken, service: 132.72.109.41:40557 }, ExecutionType: GUARANTEED, ] for AM appattempt_1546970280036_0004_000001
2019-01-08 21:02:24,287 INFO org.apache.hadoop.yarn.server.resourcemanager.rmapp.attempt.RMAppAttemptImpl: appattempt_1546970280036_0004_000001 State change from ALLOCATED to LAUNCHED on event = LAUNCHED
2019-01-08 21:02:25,235 INFO org.apache.hadoop.yarn.server.resourcemanager.rmcontainer.RMContainerImpl: container_1546970280036_0004_01_000001 Container Transitioned from ACQUIRED to RUNNING
2019-01-08 21:02:31,095 INFO SecurityLogger.org.apache.hadoop.ipc.Server: Auth successful for appattempt_1546970280036_0004_000001 (auth:SIMPLE)
2019-01-08 21:02:31,106 INFO org.apache.hadoop.yarn.server.resourcemanager.DefaultAMSProcessor: AM registration appattempt_1546970280036_0004_000001
2019-01-08 21:02:31,106 INFO org.apache.hadoop.yarn.server.resourcemanager.RMAuditLogger: USER=hadoop2	IP=132.72.109.41	OPERATION=Register App Master	TARGET=ApplicationMasterService	RESULT=SUCCESS	APPID=application_1546970280036_0004	APPATTEMPTID=appattempt_1546970280036_0004_000001
2019-01-08 21:02:31,106 INFO org.apache.hadoop.yarn.server.resourcemanager.rmapp.attempt.RMAppAttemptImpl: appattempt_1546970280036_0004_000001 State change from LAUNCHED to RUNNING on event = REGISTERED
2019-01-08 21:02:31,106 INFO org.apache.hadoop.yarn.server.resourcemanager.rmapp.RMAppImpl: application_1546970280036_0004 State change from ACCEPTED to RUNNING on event = ATTEMPT_REGISTERED
2019-01-08 21:02:32,246 INFO org.apache.hadoop.yarn.server.resourcemanager.scheduler.capacity.allocator.AbstractContainerAllocator: assignedContainer application attempt=appattempt_1546970280036_0004_000001 container=null queue=org.apache.hadoop.yarn.server.resourcemanager.scheduler.capacity.allocator.RegularContainerAllocator@51e8f7 clusterResource=<memory:9072, vCores:4> type=NODE_LOCAL requestedPartition=
2019-01-08 21:02:32,246 INFO org.apache.hadoop.yarn.server.resourcemanager.scheduler.capacity.ParentQueue: assignedContainer queue=root usedCapacity=0.056437388 absoluteUsedCapacity=0.056437388 used=<memory:512, vCores:1> cluster=<memory:9072, vCores:4>
2019-01-08 21:02:32,246 INFO org.apache.hadoop.yarn.server.resourcemanager.rmcontainer.RMContainerImpl: container_1546970280036_0004_01_000002 Container Transitioned from NEW to ALLOCATED
2019-01-08 21:02:32,247 INFO org.apache.hadoop.yarn.server.resourcemanager.RMAuditLogger: USER=hadoop2	OPERATION=AM Allocated Container	TARGET=SchedulerApp	RESULT=SUCCESS	APPID=application_1546970280036_0004	CONTAINERID=container_1546970280036_0004_01_000002	RESOURCE=<memory:512, vCores:1>
2019-01-08 21:02:32,247 INFO org.apache.hadoop.yarn.server.resourcemanager.scheduler.capacity.ParentQueue: assignedContainer queue=root usedCapacity=0.112874776 absoluteUsedCapacity=0.112874776 used=<memory:1024, vCores:2> cluster=<memory:9072, vCores:4>
2019-01-08 21:02:32,247 INFO org.apache.hadoop.yarn.server.resourcemanager.scheduler.capacity.CapacityScheduler: Allocation proposal accepted
2019-01-08 21:02:33,213 INFO org.apache.hadoop.yarn.server.resourcemanager.security.NMTokenSecretManagerInRM: Sending NMToken for nodeId : razoldslave2:40557 for container : container_1546970280036_0004_01_000002
2019-01-08 21:02:33,214 INFO org.apache.hadoop.yarn.server.resourcemanager.rmcontainer.RMContainerImpl: container_1546970280036_0004_01_000002 Container Transitioned from ALLOCATED to ACQUIRED
2019-01-08 21:02:33,247 INFO org.apache.hadoop.yarn.server.resourcemanager.scheduler.capacity.allocator.AbstractContainerAllocator: assignedContainer application attempt=appattempt_1546970280036_0004_000001 container=null queue=org.apache.hadoop.yarn.server.resourcemanager.scheduler.capacity.allocator.RegularContainerAllocator@51e8f7 clusterResource=<memory:9072, vCores:4> type=OFF_SWITCH requestedPartition=
2019-01-08 21:02:33,247 INFO org.apache.hadoop.yarn.server.resourcemanager.scheduler.capacity.ParentQueue: assignedContainer queue=root usedCapacity=0.112874776 absoluteUsedCapacity=0.112874776 used=<memory:1024, vCores:2> cluster=<memory:9072, vCores:4>
2019-01-08 21:02:33,248 INFO org.apache.hadoop.yarn.server.resourcemanager.rmcontainer.RMContainerImpl: container_1546970280036_0004_01_000003 Container Transitioned from NEW to ALLOCATED
2019-01-08 21:02:33,248 INFO org.apache.hadoop.yarn.server.resourcemanager.RMAuditLogger: USER=hadoop2	OPERATION=AM Allocated Container	TARGET=SchedulerApp	RESULT=SUCCESS	APPID=application_1546970280036_0004	CONTAINERID=container_1546970280036_0004_01_000003	RESOURCE=<memory:512, vCores:1>
2019-01-08 21:02:33,248 INFO org.apache.hadoop.yarn.server.resourcemanager.scheduler.capacity.ParentQueue: assignedContainer queue=root usedCapacity=0.16931216 absoluteUsedCapacity=0.16931216 used=<memory:1536, vCores:3> cluster=<memory:9072, vCores:4>
2019-01-08 21:02:33,248 INFO org.apache.hadoop.yarn.server.resourcemanager.scheduler.capacity.CapacityScheduler: Allocation proposal accepted
2019-01-08 21:02:33,611 INFO org.apache.hadoop.yarn.server.resourcemanager.scheduler.capacity.allocator.AbstractContainerAllocator: assignedContainer application attempt=appattempt_1546970280036_0004_000001 container=null queue=org.apache.hadoop.yarn.server.resourcemanager.scheduler.capacity.allocator.RegularContainerAllocator@51e8f7 clusterResource=<memory:9072, vCores:4> type=OFF_SWITCH requestedPartition=
2019-01-08 21:02:33,611 INFO org.apache.hadoop.yarn.server.resourcemanager.scheduler.capacity.ParentQueue: assignedContainer queue=root usedCapacity=0.16931216 absoluteUsedCapacity=0.16931216 used=<memory:1536, vCores:3> cluster=<memory:9072, vCores:4>
2019-01-08 21:02:33,611 INFO org.apache.hadoop.yarn.server.resourcemanager.rmcontainer.RMContainerImpl: container_1546970280036_0004_01_000004 Container Transitioned from NEW to ALLOCATED
2019-01-08 21:02:33,611 INFO org.apache.hadoop.yarn.server.resourcemanager.RMAuditLogger: USER=hadoop2	OPERATION=AM Allocated Container	TARGET=SchedulerApp	RESULT=SUCCESS	APPID=application_1546970280036_0004	CONTAINERID=container_1546970280036_0004_01_000004	RESOURCE=<memory:512, vCores:1>
2019-01-08 21:02:33,611 INFO org.apache.hadoop.yarn.server.resourcemanager.scheduler.capacity.ParentQueue: assignedContainer queue=root usedCapacity=0.22574955 absoluteUsedCapacity=0.22574955 used=<memory:2048, vCores:4> cluster=<memory:9072, vCores:4>
2019-01-08 21:02:33,611 INFO org.apache.hadoop.yarn.server.resourcemanager.scheduler.capacity.CapacityScheduler: Allocation proposal accepted
2019-01-08 21:02:34,239 INFO org.apache.hadoop.yarn.server.resourcemanager.scheduler.AppSchedulingInfo: checking for deactivate of application :application_1546970280036_0004
2019-01-08 21:02:34,241 INFO org.apache.hadoop.yarn.server.resourcemanager.rmcontainer.RMContainerImpl: container_1546970280036_0004_01_000003 Container Transitioned from ALLOCATED to ACQUIRED
2019-01-08 21:02:34,241 INFO org.apache.hadoop.yarn.server.resourcemanager.security.NMTokenSecretManagerInRM: Sending NMToken for nodeId : master:39349 for container : container_1546970280036_0004_01_000004
2019-01-08 21:02:34,242 INFO org.apache.hadoop.yarn.server.resourcemanager.rmcontainer.RMContainerImpl: container_1546970280036_0004_01_000004 Container Transitioned from ALLOCATED to ACQUIRED
2019-01-08 21:02:34,248 INFO org.apache.hadoop.yarn.server.resourcemanager.rmcontainer.RMContainerImpl: container_1546970280036_0004_01_000002 Container Transitioned from ACQUIRED to RUNNING
2019-01-08 21:02:34,249 INFO org.apache.hadoop.yarn.server.resourcemanager.scheduler.capacity.allocator.AbstractContainerAllocator: assignedContainer application attempt=appattempt_1546970280036_0004_000001 container=null queue=org.apache.hadoop.yarn.server.resourcemanager.scheduler.capacity.allocator.RegularContainerAllocator@51e8f7 clusterResource=<memory:9072, vCores:4> type=OFF_SWITCH requestedPartition=
2019-01-08 21:02:34,249 INFO org.apache.hadoop.yarn.server.resourcemanager.scheduler.capacity.ParentQueue: assignedContainer queue=root usedCapacity=0.22574955 absoluteUsedCapacity=0.22574955 used=<memory:2048, vCores:4> cluster=<memory:9072, vCores:4>
2019-01-08 21:02:34,249 INFO org.apache.hadoop.yarn.server.resourcemanager.rmcontainer.RMContainerImpl: container_1546970280036_0004_01_000005 Container Transitioned from NEW to ALLOCATED
2019-01-08 21:02:34,249 INFO org.apache.hadoop.yarn.server.resourcemanager.RMAuditLogger: USER=hadoop2	OPERATION=AM Allocated Container	TARGET=SchedulerApp	RESULT=SUCCESS	APPID=application_1546970280036_0004	CONTAINERID=container_1546970280036_0004_01_000005	RESOURCE=<memory:512, vCores:1>
2019-01-08 21:02:34,249 INFO org.apache.hadoop.yarn.server.resourcemanager.scheduler.capacity.ParentQueue: assignedContainer queue=root usedCapacity=0.28218696 absoluteUsedCapacity=0.28218696 used=<memory:2560, vCores:5> cluster=<memory:9072, vCores:4>
2019-01-08 21:02:34,249 INFO org.apache.hadoop.yarn.server.resourcemanager.scheduler.capacity.CapacityScheduler: Allocation proposal accepted
2019-01-08 21:02:34,612 INFO org.apache.hadoop.yarn.server.resourcemanager.rmcontainer.RMContainerImpl: container_1546970280036_0004_01_000004 Container Transitioned from ACQUIRED to RUNNING
2019-01-08 21:02:34,613 INFO org.apache.hadoop.yarn.server.resourcemanager.scheduler.capacity.allocator.AbstractContainerAllocator: assignedContainer application attempt=appattempt_1546970280036_0004_000001 container=null queue=org.apache.hadoop.yarn.server.resourcemanager.scheduler.capacity.allocator.RegularContainerAllocator@51e8f7 clusterResource=<memory:9072, vCores:4> type=OFF_SWITCH requestedPartition=
2019-01-08 21:02:34,613 INFO org.apache.hadoop.yarn.server.resourcemanager.scheduler.capacity.ParentQueue: assignedContainer queue=root usedCapacity=0.28218696 absoluteUsedCapacity=0.28218696 used=<memory:2560, vCores:5> cluster=<memory:9072, vCores:4>
2019-01-08 21:02:34,613 INFO org.apache.hadoop.yarn.server.resourcemanager.rmcontainer.RMContainerImpl: container_1546970280036_0004_01_000006 Container Transitioned from NEW to ALLOCATED
2019-01-08 21:02:34,613 INFO org.apache.hadoop.yarn.server.resourcemanager.RMAuditLogger: USER=hadoop2	OPERATION=AM Allocated Container	TARGET=SchedulerApp	RESULT=SUCCESS	APPID=application_1546970280036_0004	CONTAINERID=container_1546970280036_0004_01_000006	RESOURCE=<memory:512, vCores:1>
2019-01-08 21:02:34,613 INFO org.apache.hadoop.yarn.server.resourcemanager.scheduler.capacity.ParentQueue: assignedContainer queue=root usedCapacity=0.33862433 absoluteUsedCapacity=0.33862433 used=<memory:3072, vCores:6> cluster=<memory:9072, vCores:4>
2019-01-08 21:02:34,613 INFO org.apache.hadoop.yarn.server.resourcemanager.scheduler.capacity.CapacityScheduler: Allocation proposal accepted
2019-01-08 21:02:35,247 INFO org.apache.hadoop.yarn.server.resourcemanager.rmcontainer.RMContainerImpl: container_1546970280036_0004_01_000005 Container Transitioned from ALLOCATED to ACQUIRED
2019-01-08 21:02:35,248 INFO org.apache.hadoop.yarn.server.resourcemanager.rmcontainer.RMContainerImpl: container_1546970280036_0004_01_000006 Container Transitioned from ALLOCATED to ACQUIRED
2019-01-08 21:02:35,252 INFO org.apache.hadoop.yarn.server.resourcemanager.rmcontainer.RMContainerImpl: container_1546970280036_0004_01_000003 Container Transitioned from ACQUIRED to RUNNING
2019-01-08 21:02:35,256 INFO org.apache.hadoop.yarn.server.resourcemanager.scheduler.capacity.allocator.AbstractContainerAllocator: assignedContainer application attempt=appattempt_1546970280036_0004_000001 container=null queue=org.apache.hadoop.yarn.server.resourcemanager.scheduler.capacity.allocator.RegularContainerAllocator@51e8f7 clusterResource=<memory:9072, vCores:4> type=OFF_SWITCH requestedPartition=
2019-01-08 21:02:35,256 INFO org.apache.hadoop.yarn.server.resourcemanager.scheduler.capacity.ParentQueue: assignedContainer queue=root usedCapacity=0.33862433 absoluteUsedCapacity=0.33862433 used=<memory:3072, vCores:6> cluster=<memory:9072, vCores:4>
2019-01-08 21:02:35,256 INFO org.apache.hadoop.yarn.server.resourcemanager.rmcontainer.RMContainerImpl: container_1546970280036_0004_01_000007 Container Transitioned from NEW to ALLOCATED
2019-01-08 21:02:35,256 INFO org.apache.hadoop.yarn.server.resourcemanager.RMAuditLogger: USER=hadoop2	OPERATION=AM Allocated Container	TARGET=SchedulerApp	RESULT=SUCCESS	APPID=application_1546970280036_0004	CONTAINERID=container_1546970280036_0004_01_000007	RESOURCE=<memory:512, vCores:1>
2019-01-08 21:02:35,256 INFO org.apache.hadoop.yarn.server.resourcemanager.scheduler.capacity.ParentQueue: assignedContainer queue=root usedCapacity=0.39506173 absoluteUsedCapacity=0.39506173 used=<memory:3584, vCores:7> cluster=<memory:9072, vCores:4>
2019-01-08 21:02:35,256 INFO org.apache.hadoop.yarn.server.resourcemanager.scheduler.capacity.CapacityScheduler: Allocation proposal accepted
2019-01-08 21:02:35,613 INFO org.apache.hadoop.yarn.server.resourcemanager.rmcontainer.RMContainerImpl: container_1546970280036_0004_01_000006 Container Transitioned from ACQUIRED to RUNNING
2019-01-08 21:02:35,613 INFO org.apache.hadoop.yarn.server.resourcemanager.scheduler.capacity.allocator.AbstractContainerAllocator: assignedContainer application attempt=appattempt_1546970280036_0004_000001 container=null queue=org.apache.hadoop.yarn.server.resourcemanager.scheduler.capacity.allocator.RegularContainerAllocator@51e8f7 clusterResource=<memory:9072, vCores:4> type=OFF_SWITCH requestedPartition=
2019-01-08 21:02:35,614 INFO org.apache.hadoop.yarn.server.resourcemanager.scheduler.capacity.ParentQueue: assignedContainer queue=root usedCapacity=0.39506173 absoluteUsedCapacity=0.39506173 used=<memory:3584, vCores:7> cluster=<memory:9072, vCores:4>
2019-01-08 21:02:35,614 INFO org.apache.hadoop.yarn.server.resourcemanager.rmcontainer.RMContainerImpl: container_1546970280036_0004_01_000008 Container Transitioned from NEW to ALLOCATED
2019-01-08 21:02:35,614 INFO org.apache.hadoop.yarn.server.resourcemanager.RMAuditLogger: USER=hadoop2	OPERATION=AM Allocated Container	TARGET=SchedulerApp	RESULT=SUCCESS	APPID=application_1546970280036_0004	CONTAINERID=container_1546970280036_0004_01_000008	RESOURCE=<memory:512, vCores:1>
2019-01-08 21:02:35,614 INFO org.apache.hadoop.yarn.server.resourcemanager.scheduler.capacity.ParentQueue: assignedContainer queue=root usedCapacity=0.4514991 absoluteUsedCapacity=0.4514991 used=<memory:4096, vCores:8> cluster=<memory:9072, vCores:4>
2019-01-08 21:02:35,614 INFO org.apache.hadoop.yarn.server.resourcemanager.scheduler.capacity.CapacityScheduler: Allocation proposal accepted
2019-01-08 21:02:36,256 INFO org.apache.hadoop.yarn.server.resourcemanager.rmcontainer.RMContainerImpl: container_1546970280036_0004_01_000007 Container Transitioned from ALLOCATED to ACQUIRED
2019-01-08 21:02:36,257 INFO org.apache.hadoop.yarn.server.resourcemanager.rmcontainer.RMContainerImpl: container_1546970280036_0004_01_000008 Container Transitioned from ALLOCATED to ACQUIRED
2019-01-08 21:02:36,257 INFO org.apache.hadoop.yarn.server.resourcemanager.rmcontainer.RMContainerImpl: container_1546970280036_0004_01_000005 Container Transitioned from ACQUIRED to RUNNING
2019-01-08 21:02:36,258 INFO org.apache.hadoop.yarn.server.resourcemanager.scheduler.capacity.allocator.AbstractContainerAllocator: assignedContainer application attempt=appattempt_1546970280036_0004_000001 container=null queue=org.apache.hadoop.yarn.server.resourcemanager.scheduler.capacity.allocator.RegularContainerAllocator@51e8f7 clusterResource=<memory:9072, vCores:4> type=OFF_SWITCH requestedPartition=
2019-01-08 21:02:36,258 INFO org.apache.hadoop.yarn.server.resourcemanager.scheduler.capacity.ParentQueue: assignedContainer queue=root usedCapacity=0.4514991 absoluteUsedCapacity=0.4514991 used=<memory:4096, vCores:8> cluster=<memory:9072, vCores:4>
2019-01-08 21:02:36,258 INFO org.apache.hadoop.yarn.server.resourcemanager.rmcontainer.RMContainerImpl: container_1546970280036_0004_01_000009 Container Transitioned from NEW to ALLOCATED
2019-01-08 21:02:36,258 INFO org.apache.hadoop.yarn.server.resourcemanager.RMAuditLogger: USER=hadoop2	OPERATION=AM Allocated Container	TARGET=SchedulerApp	RESULT=SUCCESS	APPID=application_1546970280036_0004	CONTAINERID=container_1546970280036_0004_01_000009	RESOURCE=<memory:512, vCores:1>
2019-01-08 21:02:36,258 INFO org.apache.hadoop.yarn.server.resourcemanager.scheduler.capacity.ParentQueue: assignedContainer queue=root usedCapacity=0.50793654 absoluteUsedCapacity=0.50793654 used=<memory:4608, vCores:9> cluster=<memory:9072, vCores:4>
2019-01-08 21:02:36,258 INFO org.apache.hadoop.yarn.server.resourcemanager.scheduler.capacity.CapacityScheduler: Allocation proposal accepted
2019-01-08 21:02:36,614 INFO org.apache.hadoop.yarn.server.resourcemanager.rmcontainer.RMContainerImpl: container_1546970280036_0004_01_000008 Container Transitioned from ACQUIRED to RUNNING
2019-01-08 21:02:36,615 INFO org.apache.hadoop.yarn.server.resourcemanager.scheduler.capacity.allocator.AbstractContainerAllocator: assignedContainer application attempt=appattempt_1546970280036_0004_000001 container=null queue=org.apache.hadoop.yarn.server.resourcemanager.scheduler.capacity.allocator.RegularContainerAllocator@51e8f7 clusterResource=<memory:9072, vCores:4> type=OFF_SWITCH requestedPartition=
2019-01-08 21:02:36,615 INFO org.apache.hadoop.yarn.server.resourcemanager.scheduler.capacity.ParentQueue: assignedContainer queue=root usedCapacity=0.50793654 absoluteUsedCapacity=0.50793654 used=<memory:4608, vCores:9> cluster=<memory:9072, vCores:4>
2019-01-08 21:02:36,615 INFO org.apache.hadoop.yarn.server.resourcemanager.rmcontainer.RMContainerImpl: container_1546970280036_0004_01_000010 Container Transitioned from NEW to ALLOCATED
2019-01-08 21:02:36,615 INFO org.apache.hadoop.yarn.server.resourcemanager.RMAuditLogger: USER=hadoop2	OPERATION=AM Allocated Container	TARGET=SchedulerApp	RESULT=SUCCESS	APPID=application_1546970280036_0004	CONTAINERID=container_1546970280036_0004_01_000010	RESOURCE=<memory:512, vCores:1>
2019-01-08 21:02:36,615 INFO org.apache.hadoop.yarn.server.resourcemanager.scheduler.capacity.ParentQueue: assignedContainer queue=root usedCapacity=0.5643739 absoluteUsedCapacity=0.5643739 used=<memory:5120, vCores:10> cluster=<memory:9072, vCores:4>
2019-01-08 21:02:36,615 INFO org.apache.hadoop.yarn.server.resourcemanager.scheduler.capacity.CapacityScheduler: Allocation proposal accepted
2019-01-08 21:02:37,259 INFO org.apache.hadoop.yarn.server.resourcemanager.rmcontainer.RMContainerImpl: container_1546970280036_0004_01_000007 Container Transitioned from ACQUIRED to RUNNING
2019-01-08 21:02:37,259 INFO org.apache.hadoop.yarn.server.resourcemanager.scheduler.capacity.allocator.AbstractContainerAllocator: assignedContainer application attempt=appattempt_1546970280036_0004_000001 container=null queue=org.apache.hadoop.yarn.server.resourcemanager.scheduler.capacity.allocator.RegularContainerAllocator@51e8f7 clusterResource=<memory:9072, vCores:4> type=OFF_SWITCH requestedPartition=
2019-01-08 21:02:37,259 INFO org.apache.hadoop.yarn.server.resourcemanager.scheduler.capacity.ParentQueue: assignedContainer queue=root usedCapacity=0.5643739 absoluteUsedCapacity=0.5643739 used=<memory:5120, vCores:10> cluster=<memory:9072, vCores:4>
2019-01-08 21:02:37,259 INFO org.apache.hadoop.yarn.server.resourcemanager.rmcontainer.RMContainerImpl: container_1546970280036_0004_01_000011 Container Transitioned from NEW to ALLOCATED
2019-01-08 21:02:37,259 INFO org.apache.hadoop.yarn.server.resourcemanager.RMAuditLogger: USER=hadoop2	OPERATION=AM Allocated Container	TARGET=SchedulerApp	RESULT=SUCCESS	APPID=application_1546970280036_0004	CONTAINERID=container_1546970280036_0004_01_000011	RESOURCE=<memory:512, vCores:1>
2019-01-08 21:02:37,259 INFO org.apache.hadoop.yarn.server.resourcemanager.scheduler.capacity.ParentQueue: assignedContainer queue=root usedCapacity=0.6208113 absoluteUsedCapacity=0.6208113 used=<memory:5632, vCores:11> cluster=<memory:9072, vCores:4>
2019-01-08 21:02:37,259 INFO org.apache.hadoop.yarn.server.resourcemanager.scheduler.capacity.CapacityScheduler: Allocation proposal accepted
2019-01-08 21:02:37,262 INFO org.apache.hadoop.yarn.server.resourcemanager.rmcontainer.RMContainerImpl: container_1546970280036_0004_01_000009 Container Transitioned from ALLOCATED to ACQUIRED
2019-01-08 21:02:37,262 INFO org.apache.hadoop.yarn.server.resourcemanager.rmcontainer.RMContainerImpl: container_1546970280036_0004_01_000010 Container Transitioned from ALLOCATED to ACQUIRED
2019-01-08 21:02:37,263 INFO org.apache.hadoop.yarn.server.resourcemanager.rmcontainer.RMContainerImpl: container_1546970280036_0004_01_000011 Container Transitioned from ALLOCATED to ACQUIRED
2019-01-08 21:02:37,618 INFO org.apache.hadoop.yarn.server.resourcemanager.rmcontainer.RMContainerImpl: container_1546970280036_0004_01_000010 Container Transitioned from ACQUIRED to RUNNING
2019-01-08 21:02:37,618 INFO org.apache.hadoop.yarn.server.resourcemanager.scheduler.capacity.allocator.AbstractContainerAllocator: assignedContainer application attempt=appattempt_1546970280036_0004_000001 container=null queue=org.apache.hadoop.yarn.server.resourcemanager.scheduler.capacity.allocator.RegularContainerAllocator@51e8f7 clusterResource=<memory:9072, vCores:4> type=OFF_SWITCH requestedPartition=
2019-01-08 21:02:37,619 INFO org.apache.hadoop.yarn.server.resourcemanager.scheduler.capacity.ParentQueue: assignedContainer queue=root usedCapacity=0.6208113 absoluteUsedCapacity=0.6208113 used=<memory:5632, vCores:11> cluster=<memory:9072, vCores:4>
2019-01-08 21:02:37,619 INFO org.apache.hadoop.yarn.server.resourcemanager.rmcontainer.RMContainerImpl: container_1546970280036_0004_01_000012 Container Transitioned from NEW to ALLOCATED
2019-01-08 21:02:37,619 INFO org.apache.hadoop.yarn.server.resourcemanager.RMAuditLogger: USER=hadoop2	OPERATION=AM Allocated Container	TARGET=SchedulerApp	RESULT=SUCCESS	APPID=application_1546970280036_0004	CONTAINERID=container_1546970280036_0004_01_000012	RESOURCE=<memory:512, vCores:1>
2019-01-08 21:02:37,619 INFO org.apache.hadoop.yarn.server.resourcemanager.scheduler.capacity.ParentQueue: assignedContainer queue=root usedCapacity=0.67724866 absoluteUsedCapacity=0.67724866 used=<memory:6144, vCores:12> cluster=<memory:9072, vCores:4>
2019-01-08 21:02:37,619 INFO org.apache.hadoop.yarn.server.resourcemanager.scheduler.capacity.CapacityScheduler: Allocation proposal accepted
2019-01-08 21:02:38,262 INFO org.apache.hadoop.yarn.server.resourcemanager.rmcontainer.RMContainerImpl: container_1546970280036_0004_01_000009 Container Transitioned from ACQUIRED to RUNNING
2019-01-08 21:02:38,262 INFO org.apache.hadoop.yarn.server.resourcemanager.rmcontainer.RMContainerImpl: container_1546970280036_0004_01_000011 Container Transitioned from ACQUIRED to RUNNING
2019-01-08 21:02:38,262 INFO org.apache.hadoop.yarn.server.resourcemanager.scheduler.capacity.allocator.AbstractContainerAllocator: assignedContainer application attempt=appattempt_1546970280036_0004_000001 container=null queue=org.apache.hadoop.yarn.server.resourcemanager.scheduler.capacity.allocator.RegularContainerAllocator@51e8f7 clusterResource=<memory:9072, vCores:4> type=OFF_SWITCH requestedPartition=
2019-01-08 21:02:38,263 INFO org.apache.hadoop.yarn.server.resourcemanager.scheduler.capacity.ParentQueue: assignedContainer queue=root usedCapacity=0.67724866 absoluteUsedCapacity=0.67724866 used=<memory:6144, vCores:12> cluster=<memory:9072, vCores:4>
2019-01-08 21:02:38,263 INFO org.apache.hadoop.yarn.server.resourcemanager.rmcontainer.RMContainerImpl: container_1546970280036_0004_01_000013 Container Transitioned from NEW to ALLOCATED
2019-01-08 21:02:38,263 INFO org.apache.hadoop.yarn.server.resourcemanager.RMAuditLogger: USER=hadoop2	OPERATION=AM Allocated Container	TARGET=SchedulerApp	RESULT=SUCCESS	APPID=application_1546970280036_0004	CONTAINERID=container_1546970280036_0004_01_000013	RESOURCE=<memory:512, vCores:1>
2019-01-08 21:02:38,263 INFO org.apache.hadoop.yarn.server.resourcemanager.scheduler.capacity.ParentQueue: assignedContainer queue=root usedCapacity=0.7336861 absoluteUsedCapacity=0.7336861 used=<memory:6656, vCores:13> cluster=<memory:9072, vCores:4>
2019-01-08 21:02:38,263 INFO org.apache.hadoop.yarn.server.resourcemanager.scheduler.capacity.CapacityScheduler: Allocation proposal accepted
2019-01-08 21:02:38,621 INFO org.apache.hadoop.yarn.server.resourcemanager.scheduler.capacity.allocator.AbstractContainerAllocator: assignedContainer application attempt=appattempt_1546970280036_0004_000001 container=null queue=org.apache.hadoop.yarn.server.resourcemanager.scheduler.capacity.allocator.RegularContainerAllocator@51e8f7 clusterResource=<memory:9072, vCores:4> type=OFF_SWITCH requestedPartition=
2019-01-08 21:02:38,621 INFO org.apache.hadoop.yarn.server.resourcemanager.scheduler.capacity.ParentQueue: assignedContainer queue=root usedCapacity=0.7336861 absoluteUsedCapacity=0.7336861 used=<memory:6656, vCores:13> cluster=<memory:9072, vCores:4>
2019-01-08 21:02:38,621 INFO org.apache.hadoop.yarn.server.resourcemanager.rmcontainer.RMContainerImpl: container_1546970280036_0004_01_000014 Container Transitioned from NEW to ALLOCATED
2019-01-08 21:02:38,621 INFO org.apache.hadoop.yarn.server.resourcemanager.RMAuditLogger: USER=hadoop2	OPERATION=AM Allocated Container	TARGET=SchedulerApp	RESULT=SUCCESS	APPID=application_1546970280036_0004	CONTAINERID=container_1546970280036_0004_01_000014	RESOURCE=<memory:512, vCores:1>
2019-01-08 21:02:38,622 INFO org.apache.hadoop.yarn.server.resourcemanager.scheduler.capacity.ParentQueue: assignedContainer queue=root usedCapacity=0.79012346 absoluteUsedCapacity=0.79012346 used=<memory:7168, vCores:14> cluster=<memory:9072, vCores:4>
2019-01-08 21:02:38,622 INFO org.apache.hadoop.yarn.server.resourcemanager.scheduler.capacity.CapacityScheduler: Allocation proposal accepted
2019-01-08 21:02:38,741 INFO org.apache.hadoop.yarn.server.resourcemanager.scheduler.AppSchedulingInfo: checking for deactivate of application :application_1546970280036_0004
2019-01-08 21:02:38,742 INFO org.apache.hadoop.yarn.server.resourcemanager.rmcontainer.RMContainerImpl: container_1546970280036_0004_01_000012 Container Transitioned from ALLOCATED to ACQUIRED
2019-01-08 21:02:38,743 INFO org.apache.hadoop.yarn.server.resourcemanager.rmcontainer.RMContainerImpl: container_1546970280036_0004_01_000013 Container Transitioned from ALLOCATED to ACQUIRED
2019-01-08 21:02:38,744 INFO org.apache.hadoop.yarn.server.resourcemanager.rmcontainer.RMContainerImpl: container_1546970280036_0004_01_000014 Container Transitioned from ALLOCATED to ACQUIRED
2019-01-08 21:02:39,749 INFO org.apache.hadoop.yarn.server.resourcemanager.rmcontainer.RMContainerImpl: container_1546970280036_0004_01_000012 Container Transitioned from ACQUIRED to RELEASED
2019-01-08 21:02:39,749 INFO org.apache.hadoop.yarn.server.resourcemanager.RMAuditLogger: USER=hadoop2	IP=132.72.109.41	OPERATION=AM Released Container	TARGET=SchedulerApp	RESULT=SUCCESS	APPID=application_1546970280036_0004	CONTAINERID=container_1546970280036_0004_01_000012	RESOURCE=<memory:512, vCores:1>
2019-01-08 21:02:39,749 INFO org.apache.hadoop.yarn.server.resourcemanager.rmcontainer.RMContainerImpl: container_1546970280036_0004_01_000013 Container Transitioned from ACQUIRED to RELEASED
2019-01-08 21:02:39,749 INFO org.apache.hadoop.yarn.server.resourcemanager.RMAuditLogger: USER=hadoop2	IP=132.72.109.41	OPERATION=AM Released Container	TARGET=SchedulerApp	RESULT=SUCCESS	APPID=application_1546970280036_0004	CONTAINERID=container_1546970280036_0004_01_000013	RESOURCE=<memory:512, vCores:1>
2019-01-08 21:02:39,749 INFO org.apache.hadoop.yarn.server.resourcemanager.rmcontainer.RMContainerImpl: container_1546970280036_0004_01_000014 Container Transitioned from ACQUIRED to RELEASED
2019-01-08 21:02:39,749 INFO org.apache.hadoop.yarn.server.resourcemanager.RMAuditLogger: USER=hadoop2	IP=132.72.109.41	OPERATION=AM Released Container	TARGET=SchedulerApp	RESULT=SUCCESS	APPID=application_1546970280036_0004	CONTAINERID=container_1546970280036_0004_01_000014	RESOURCE=<memory:512, vCores:1>
2019-01-08 21:02:54,870 INFO org.apache.hadoop.yarn.server.resourcemanager.rmcontainer.RMContainerImpl: container_1546970280036_0004_01_000002 Container Transitioned from RUNNING to COMPLETED
2019-01-08 21:02:54,870 INFO org.apache.hadoop.yarn.server.resourcemanager.RMAuditLogger: USER=hadoop2	OPERATION=AM Released Container	TARGET=SchedulerApp	RESULT=SUCCESS	APPID=application_1546970280036_0004	CONTAINERID=container_1546970280036_0004_01_000002	RESOURCE=<memory:512, vCores:1>
2019-01-08 21:02:58,307 INFO org.apache.hadoop.yarn.server.resourcemanager.rmcontainer.RMContainerImpl: container_1546970280036_0004_01_000003 Container Transitioned from RUNNING to COMPLETED
2019-01-08 21:02:58,307 INFO org.apache.hadoop.yarn.server.resourcemanager.RMAuditLogger: USER=hadoop2	OPERATION=AM Released Container	TARGET=SchedulerApp	RESULT=SUCCESS	APPID=application_1546970280036_0004	CONTAINERID=container_1546970280036_0004_01_000003	RESOURCE=<memory:512, vCores:1>
2019-01-08 21:02:58,590 INFO org.apache.hadoop.yarn.server.resourcemanager.rmcontainer.RMContainerImpl: container_1546970280036_0004_01_000007 Container Transitioned from RUNNING to COMPLETED
2019-01-08 21:02:58,590 INFO org.apache.hadoop.yarn.server.resourcemanager.RMAuditLogger: USER=hadoop2	OPERATION=AM Released Container	TARGET=SchedulerApp	RESULT=SUCCESS	APPID=application_1546970280036_0004	CONTAINERID=container_1546970280036_0004_01_000007	RESOURCE=<memory:512, vCores:1>
2019-01-08 21:02:58,861 INFO org.apache.hadoop.yarn.server.resourcemanager.rmcontainer.RMContainerImpl: container_1546970280036_0004_01_000008 Container Transitioned from RUNNING to COMPLETED
2019-01-08 21:02:58,861 INFO org.apache.hadoop.yarn.server.resourcemanager.RMAuditLogger: USER=hadoop2	OPERATION=AM Released Container	TARGET=SchedulerApp	RESULT=SUCCESS	APPID=application_1546970280036_0004	CONTAINERID=container_1546970280036_0004_01_000008	RESOURCE=<memory:512, vCores:1>
2019-01-08 21:02:58,875 INFO org.apache.hadoop.yarn.server.resourcemanager.rmcontainer.RMContainerImpl: container_1546970280036_0004_01_000009 Container Transitioned from RUNNING to COMPLETED
2019-01-08 21:02:58,875 INFO org.apache.hadoop.yarn.server.resourcemanager.RMAuditLogger: USER=hadoop2	OPERATION=AM Released Container	TARGET=SchedulerApp	RESULT=SUCCESS	APPID=application_1546970280036_0004	CONTAINERID=container_1546970280036_0004_01_000009	RESOURCE=<memory:512, vCores:1>
2019-01-08 21:02:58,931 INFO org.apache.hadoop.yarn.server.resourcemanager.rmcontainer.RMContainerImpl: container_1546970280036_0004_01_000010 Container Transitioned from RUNNING to COMPLETED
2019-01-08 21:02:58,931 INFO org.apache.hadoop.yarn.server.resourcemanager.RMAuditLogger: USER=hadoop2	OPERATION=AM Released Container	TARGET=SchedulerApp	RESULT=SUCCESS	APPID=application_1546970280036_0004	CONTAINERID=container_1546970280036_0004_01_000010	RESOURCE=<memory:512, vCores:1>
2019-01-08 21:02:58,937 INFO org.apache.hadoop.yarn.server.resourcemanager.rmcontainer.RMContainerImpl: container_1546970280036_0004_01_000005 Container Transitioned from RUNNING to COMPLETED
2019-01-08 21:02:58,937 INFO org.apache.hadoop.yarn.server.resourcemanager.RMAuditLogger: USER=hadoop2	OPERATION=AM Released Container	TARGET=SchedulerApp	RESULT=SUCCESS	APPID=application_1546970280036_0004	CONTAINERID=container_1546970280036_0004_01_000005	RESOURCE=<memory:512, vCores:1>
2019-01-08 21:02:59,022 INFO org.apache.hadoop.yarn.server.resourcemanager.rmcontainer.RMContainerImpl: container_1546970280036_0004_01_000004 Container Transitioned from RUNNING to COMPLETED
2019-01-08 21:02:59,023 INFO org.apache.hadoop.yarn.server.resourcemanager.RMAuditLogger: USER=hadoop2	OPERATION=AM Released Container	TARGET=SchedulerApp	RESULT=SUCCESS	APPID=application_1546970280036_0004	CONTAINERID=container_1546970280036_0004_01_000004	RESOURCE=<memory:512, vCores:1>
2019-01-08 21:02:59,153 INFO org.apache.hadoop.yarn.server.resourcemanager.rmcontainer.RMContainerImpl: container_1546970280036_0004_01_000006 Container Transitioned from RUNNING to COMPLETED
2019-01-08 21:02:59,153 INFO org.apache.hadoop.yarn.server.resourcemanager.RMAuditLogger: USER=hadoop2	OPERATION=AM Released Container	TARGET=SchedulerApp	RESULT=SUCCESS	APPID=application_1546970280036_0004	CONTAINERID=container_1546970280036_0004_01_000006	RESOURCE=<memory:512, vCores:1>
2019-01-08 21:02:59,274 INFO org.apache.hadoop.yarn.server.resourcemanager.rmcontainer.RMContainerImpl: container_1546970280036_0004_01_000011 Container Transitioned from RUNNING to COMPLETED
2019-01-08 21:02:59,274 INFO org.apache.hadoop.yarn.server.resourcemanager.RMAuditLogger: USER=hadoop2	OPERATION=AM Released Container	TARGET=SchedulerApp	RESULT=SUCCESS	APPID=application_1546970280036_0004	CONTAINERID=container_1546970280036_0004_01_000011	RESOURCE=<memory:512, vCores:1>
2019-01-08 21:02:59,460 INFO org.apache.hadoop.yarn.server.resourcemanager.rmapp.attempt.RMAppAttemptImpl: Updating application attempt appattempt_1546970280036_0004_000001 with final state: FINISHING, and exit status: -1000
2019-01-08 21:02:59,461 INFO org.apache.hadoop.yarn.server.resourcemanager.rmapp.attempt.RMAppAttemptImpl: appattempt_1546970280036_0004_000001 State change from RUNNING to FINAL_SAVING on event = UNREGISTERED
2019-01-08 21:02:59,461 INFO org.apache.hadoop.yarn.server.resourcemanager.rmapp.RMAppImpl: Updating application application_1546970280036_0004 with final state: FINISHING
2019-01-08 21:02:59,461 INFO org.apache.hadoop.yarn.server.resourcemanager.recovery.RMStateStore: Updating info for app: application_1546970280036_0004
2019-01-08 21:02:59,461 INFO org.apache.hadoop.yarn.server.resourcemanager.rmapp.RMAppImpl: application_1546970280036_0004 State change from RUNNING to FINAL_SAVING on event = ATTEMPT_UNREGISTERED
2019-01-08 21:02:59,461 INFO org.apache.hadoop.yarn.server.resourcemanager.rmapp.attempt.RMAppAttemptImpl: appattempt_1546970280036_0004_000001 State change from FINAL_SAVING to FINISHING on event = ATTEMPT_UPDATE_SAVED
2019-01-08 21:02:59,461 INFO org.apache.hadoop.yarn.server.resourcemanager.rmapp.RMAppImpl: application_1546970280036_0004 State change from FINAL_SAVING to FINISHING on event = APP_UPDATE_SAVED
2019-01-08 21:03:00,469 INFO org.apache.hadoop.yarn.server.resourcemanager.ApplicationMasterService: application_1546970280036_0004 unregistered successfully. 
2019-01-08 21:03:05,973 INFO org.apache.hadoop.yarn.server.resourcemanager.rmcontainer.RMContainerImpl: container_1546970280036_0004_01_000001 Container Transitioned from RUNNING to COMPLETED
2019-01-08 21:03:05,973 INFO org.apache.hadoop.yarn.server.resourcemanager.ApplicationMasterService: Unregistering app attempt : appattempt_1546970280036_0004_000001
2019-01-08 21:03:05,973 INFO org.apache.hadoop.yarn.server.resourcemanager.RMAuditLogger: USER=hadoop2	OPERATION=AM Released Container	TARGET=SchedulerApp	RESULT=SUCCESS	APPID=application_1546970280036_0004	CONTAINERID=container_1546970280036_0004_01_000001	RESOURCE=<memory:512, vCores:1>
2019-01-08 21:03:05,974 INFO org.apache.hadoop.yarn.server.resourcemanager.security.AMRMTokenSecretManager: Application finished, removing password for appattempt_1546970280036_0004_000001
2019-01-08 21:03:05,974 INFO org.apache.hadoop.yarn.server.resourcemanager.rmapp.attempt.RMAppAttemptImpl: appattempt_1546970280036_0004_000001 State change from FINISHING to FINISHED on event = CONTAINER_FINISHED
2019-01-08 21:03:05,974 INFO org.apache.hadoop.yarn.server.resourcemanager.rmapp.RMAppImpl: application_1546970280036_0004 State change from FINISHING to FINISHED on event = ATTEMPT_FINISHED
2019-01-08 21:03:05,974 INFO org.apache.hadoop.yarn.server.resourcemanager.RMAuditLogger: USER=hadoop2	OPERATION=Application Finished - Succeeded	TARGET=RMAppManager	RESULT=SUCCESS	APPID=application_1546970280036_0004
2019-01-08 21:03:05,974 INFO org.apache.hadoop.yarn.server.resourcemanager.RMAppManager$ApplicationSummary: appId=application_1546970280036_0004,name=input_105_104-000,user=hadoop2,queue=default,state=FINISHED,trackingUrl=http://master:8088/proxy/application_1546970280036_0004/,appMasterHost=razoldslave2,submitTime=1546974144011,startTime=1546974144014,finishTime=1546974179461,finalStatus=SUCCEEDED,memorySeconds=144549,vcoreSeconds=277,preemptedMemorySeconds=0,preemptedVcoreSeconds=0,preemptedAMContainers=0,preemptedNonAMContainers=0,preemptedResources=<memory:0\, vCores:0>,applicationType=MAPREDUCE
2019-01-08 21:03:05,975 INFO org.apache.hadoop.yarn.server.resourcemanager.scheduler.capacity.CapacityScheduler: Application Attempt appattempt_1546970280036_0004_000001 is done. finalState=FINISHED
2019-01-08 21:03:05,975 INFO org.apache.hadoop.yarn.server.resourcemanager.scheduler.AppSchedulingInfo: Application application_1546970280036_0004 requests cleared
2019-01-08 21:03:05,975 INFO org.apache.hadoop.yarn.server.resourcemanager.scheduler.capacity.LeafQueue: Application removed - appId: application_1546970280036_0004 user: hadoop2 queue: default #user-pending-applications: 0 #user-active-applications: 0 #queue-pending-applications: 0 #queue-active-applications: 0
2019-01-08 21:03:05,975 INFO org.apache.hadoop.yarn.server.resourcemanager.scheduler.capacity.ParentQueue: Application removed - appId: application_1546970280036_0004 user: hadoop2 leaf-queue of parent: root #applications: 0
2019-01-08 21:03:05,976 INFO org.apache.hadoop.yarn.server.resourcemanager.amlauncher.AMLauncher: Cleaning master appattempt_1546970280036_0004_000001
2019-01-08 22:33:06,539 INFO org.apache.hadoop.util.JvmPauseMonitor: Detected pause in JVM or host machine (eg GC): pause of approximately 1877ms
GC pool 'PS Scavenge' had collection(s): count=1 time=1733ms
2019-01-08 23:22:06,465 ERROR org.apache.hadoop.yarn.server.resourcemanager.ResourceManager: RECEIVED SIGNAL 15: SIGTERM
2019-01-08 23:22:06,508 ERROR org.apache.hadoop.security.token.delegation.AbstractDelegationTokenSecretManager: ExpiredTokenRemover received java.lang.InterruptedException: sleep interrupted
2019-01-08 23:22:06,541 INFO org.mortbay.log: Stopped HttpServer2$SelectChannelConnectorWithSafeStartup@master:8088
2019-01-08 23:22:06,645 INFO org.apache.hadoop.ipc.Server: Stopping server on 8032
2019-01-08 23:22:06,658 INFO org.apache.hadoop.ipc.Server: Stopping IPC Server listener on 8032
2019-01-08 23:22:06,659 INFO org.apache.hadoop.ipc.Server: Stopping server on 8033
2019-01-08 23:22:06,659 INFO org.apache.hadoop.ipc.Server: Stopping IPC Server Responder
2019-01-08 23:22:06,660 INFO org.apache.hadoop.ipc.Server: Stopping IPC Server listener on 8033
2019-01-08 23:22:06,661 INFO org.apache.hadoop.yarn.server.resourcemanager.ResourceManager: Transitioning to standby state
2019-01-08 23:22:06,661 INFO org.apache.hadoop.ipc.Server: Stopping IPC Server Responder
2019-01-08 23:22:06,661 WARN org.apache.hadoop.yarn.server.resourcemanager.amlauncher.ApplicationMasterLauncher: org.apache.hadoop.yarn.server.resourcemanager.amlauncher.ApplicationMasterLauncher$LauncherThread interrupted. Returning.
2019-01-08 23:22:06,663 INFO org.apache.hadoop.ipc.Server: Stopping server on 8030
2019-01-08 23:22:06,666 INFO org.apache.hadoop.ipc.Server: Stopping IPC Server listener on 8030
2019-01-08 23:22:06,669 INFO org.apache.hadoop.ipc.Server: Stopping IPC Server Responder
2019-01-08 23:22:06,670 INFO org.apache.hadoop.ipc.Server: Stopping server on 8031
2019-01-08 23:22:06,674 INFO org.apache.hadoop.ipc.Server: Stopping IPC Server Responder
2019-01-08 23:22:06,674 INFO org.apache.hadoop.ipc.Server: Stopping IPC Server listener on 8031
2019-01-08 23:22:06,675 INFO org.apache.hadoop.yarn.util.AbstractLivelinessMonitor: NMLivelinessMonitor thread interrupted
2019-01-08 23:22:06,675 ERROR org.apache.hadoop.yarn.event.EventDispatcher: Returning, interrupted : java.lang.InterruptedException
2019-01-08 23:22:06,696 INFO org.apache.hadoop.yarn.event.AsyncDispatcher: AsyncDispatcher is draining to stop, ignoring any new events.
2019-01-08 23:22:06,696 INFO org.apache.hadoop.yarn.util.AbstractLivelinessMonitor: org.apache.hadoop.yarn.server.resourcemanager.rmapp.monitor.RMAppLifetimeMonitor thread interrupted
2019-01-08 23:22:06,696 INFO org.apache.hadoop.yarn.util.AbstractLivelinessMonitor: AMLivelinessMonitor thread interrupted
2019-01-08 23:22:06,696 INFO org.apache.hadoop.yarn.util.AbstractLivelinessMonitor: AMLivelinessMonitor thread interrupted
2019-01-08 23:22:06,696 INFO org.apache.hadoop.yarn.util.AbstractLivelinessMonitor: org.apache.hadoop.yarn.server.resourcemanager.rmcontainer.ContainerAllocationExpirer thread interrupted
2019-01-08 23:22:06,696 ERROR org.apache.hadoop.security.token.delegation.AbstractDelegationTokenSecretManager: ExpiredTokenRemover received java.lang.InterruptedException: sleep interrupted
2019-01-08 23:22:06,697 INFO org.apache.hadoop.metrics2.impl.MetricsSystemImpl: Stopping ResourceManager metrics system...
2019-01-08 23:22:06,698 INFO org.apache.hadoop.metrics2.impl.MetricsSystemImpl: ResourceManager metrics system stopped.
2019-01-08 23:22:06,699 INFO org.apache.hadoop.metrics2.impl.MetricsSystemImpl: ResourceManager metrics system shutdown complete.
2019-01-08 23:22:06,699 INFO org.apache.hadoop.yarn.event.AsyncDispatcher: AsyncDispatcher is draining to stop, ignoring any new events.
2019-01-08 23:22:06,699 INFO org.apache.hadoop.yarn.server.resourcemanager.ResourceManager: Transitioned to standby state
2019-01-08 23:22:06,699 INFO org.apache.hadoop.yarn.server.resourcemanager.ResourceManager: SHUTDOWN_MSG: 
/************************************************************
SHUTDOWN_MSG: Shutting down ResourceManager at master/132.72.109.20
************************************************************/
